Workbook
Name Countries: OFFSET(lists!$B$2,0,0,COUNTA(lists!$B$2:$B$20),1)
Name length_measures: OFFSET(lists!$D$2,0,0,COUNTA(lists!$D$2:$D$20),1)
Name Species: OFFSET(lists!$C$2,0,0,COUNTA(lists!$C$2:$C$20),1)
Name Units: OFFSET(lists!$A$2,0,0,COUNTA(lists!$A$2:$A$20),1)

Sheet START HERE
A1: South Pacific Regional Fisheries Management Organisation
B3: Data Submission Work Book (v3.2, Aug. 2021) | J3: Year: | K3: 2007
B5: SPECIES: | F5: Jack mackerel
B6: MEMBER | F6: EU
B7: PERSON RESPONSIBLE FOR DATA:
B8: DATE SUBMITTED: | F8: 13/6/2022
B9: EMAIL:
B10: TEL
B11: ADDRESS:
B12: If this workbook is an alteration to a previous submission, enter the date of the previous submission
B13: LENGTH MEASURE | F13: fork length
B14: These data can be used as presented and there are no known problematic issues which require
B15: discussion and agreement within the Scientific Committee meeting
B17: If NO, please describe the problem in the text field on the next page

Sheet Comments
A1: South Pacific Regional Fisheries Management Organisation
B3: Member: | C3: ='START HERE'!F6 -> EU
B4: Species: | C4: ='START HERE'!F5 -> Jack mackerel
B5: Year: | C5: ='START HERE'!K3 -> 2007
B8: Please specify any problem to be discussed within the SC HERE:
B42: Fleet data: please provide a very brief fleet description for your member state in the input fields below
D45: Comments
B46: Number of vessels
B47: Fishing Gear
B48: Length range vessels (m)
B49: Mean vessel length (m)
B50: Type of vessel
B51: Horse power range (HP)
B52: Mean horse power (HP)
B53: Average crew size
B54: Target species
B55: Human consumption or fish meal
B56: Length measurements in total length (TL) or fork length (FL). Supply conversion factor
B57: Value / kg (national currency)
B59: General comments

Sheet catch data
A1: =Comments!$A$1 -> South Pacific Regional Fisheries Management Organisation
A2: CATCH DATA | B2: Only fill in yellow cells!
A4: Member : | B4: ='START HERE'!F6 -> EU
A5: Species : | B5: ='START HERE'!F5 -> Jack mackerel
A6: Year : | B6: ='START HERE'!K3 -> 2007
A7: Revised (date) : | B7: 42585
B12: 1st Quarter | E12: 2nd Quarter | H12: 3rd Quarter | K12: 4th Quarter | N12: all quarters
B13: ='START HERE'!$K$3 -> 2007 | E13: ='START HERE'!$K$3 -> 2007 | H13: ='START HERE'!$K$3 -> 2007 | K13: ='START HERE'!$K$3 -> 2007
Q14: TOTAL CATCH | R14: REMARKS
B15: OFFICIAL LANDINGS | C15: RETAINED | D15: DISCARDS | E15: OFFICIAL LANDINGS | F15: RETAINED | G15: DISCARDS | H15: OFFICIAL LANDINGS | I15: RETAINED | J15: DISCARDS | K15: OFFICIAL LANDINGS | L15: RETAINED | M15: DISCARDS | N15: OFFICIAL LANDINGS | O15: RETAINED | P15: DISCARDS | Q15: WG estimate | S15: FLEET
A16: Fleet | B16: (tonnes) | C16: (tonnes) | D16: (tonnes) | E16: (tonnes) | F16: (tonnes) | G16: (tonnes) | H16: (tonnes) | I16: (tonnes) | J16: (tonnes) | K16: (tonnes) | L16: (tonnes) | M16: (tonnes) | N16: (tonnes) | O16: (tonnes) | P16: (tonnes) | Q16: (tonnes)
A17: Fleet 1: Northern Chile (inside EEZ) | N17: =SUM(B17+E17+H17+K17) -> 0 | O17: =SUM(C17+F17+I17+L17) -> 0 | P17: =SUM(D17+G17+J17+M17) -> 0 | Q17: =IF(SUM(O17:P17)>0,SUM(O17:P17),N17) -> 0 | S17: Fleet 1
A18: Fleet 2: South-Central Chile (EEZ/HS) | N18: =SUM(B18+E18+H18+K18) -> 0 | O18: =SUM(C18+F18+I18+L18) -> 0 | P18: =SUM(D18+G18+J18+M18) -> 0 | Q18: =IF(SUM(O18:P18)>0,SUM(O18:P18),N18) -> 0 | S18: Fleet 2
A19: Fleet 3: Peru & Equador (inside EEZ) | N19: =SUM(B19+E19+H19+K19) -> 0 | O19: =SUM(C19+F19+I19+L19) -> 0 | P19: =SUM(D19+G19+J19+M19) -> 0 | Q19: =IF(SUM(O19:P19)>0,SUM(O19:P19),N19) -> 0 | S19: Fleet 3
A20: Fleet 4: Offshore (outside EEZ) | E20: 123523 | N20: =SUM(B20+E20+H20+K20) -> 123523 | O20: =SUM(C20+F20+I20+L20) -> 0 | P20: =SUM(D20+G20+J20+M20) -> 0 | Q20: =IF(SUM(O20:P20)>0,SUM(O20:P20),N20) -> 123523 | S20: Fleet 4
A21: Total | B21: =SUM(B17:B20) -> 0 | C21: =SUM(C17:C20) -> 0 | D21: =SUM(D17:D20) -> 0 | E21: =SUM(E17:E20) -> 123523 | F21: =SUM(F17:F20) -> 0 | G21: =SUM(G17:G20) -> 0 | H21: =SUM(H17:H20) -> 0 | I21: =SUM(I17:I20) -> 0 | ... M21: =SUM(M17:M20) -> 0 | N21: =SUM(B21+E21+H21+K21) -> 123523 | O21: =SUM(C21+F21+I21+L21) -> 0 | P21: =SUM(D21+G21+J21+M21) -> 0 | Q21: =SUM(Q17:Q20) -> 123523 | S21: TOTAL
A22: PLEASE CHECK:
A23: ="Final total catch (WG estimate = "& Q21 &") should be the same as the sum of the catch totals of all CANUM (CN) sheets (= "& SUM('CN F1:CN F4'!P27) &")!" -> Final total catch (WG estimate = 123523) should be the same as the sum of the catch totals of all CANUM (CN) sheets (= 0)!

Sheet sampling
A1: SUMMARY OF SAMPLING FROM COMMERCIAL FISHERY
A3: Member: | B3: ='START HERE'!F6 -> EU | F3: ONLY SAMPLES FROM COMMERCIAL FISHERY! NO SAMPLES FROM RESEARCH VESSEL SURVEYS,
A4: Species : | B4: ='START HERE'!F5 -> Jack mackerel | F4: EXCEPT WHEN THESE ARE USED TO CALCULATE CATCH IN NUMBERS AT AGE!
A5: Year : | B5: ='START HERE'!K3 -> 2007
A6: Revised (date) : | B6: ='START HERE'!F8 -> 13/6/2022
B8: Quarter 1 | E8: ='START HERE'!K3 -> 2007 | F8: Quarter 2 | I8: ='START HERE'!K3 -> 2007 | J8: Quarter 3 | M8: ='START HERE'!K3 -> 2007 | N8: Quarter 4 | Q8: ='START HERE'!K3 -> 2007 | R8: ALL YEAR | U8: ='START HERE'!K3 -> 2007
B9: total of sample | C9: samples | D9: measured | E9: aged | F9: total of sample | G9: samples | H9: measured | I9: aged | J9: total of sample | K9: samples | L9: measured | M9: aged | N9: total of sample | O9: samples | P9: measured | Q9: aged | R9: total of sample | S9: samples | T9: measured | U9: aged
A10: Fleet | B10: (tonnes) | C10: (n) | D10: (n) | E10: (n) | F10: (tonnes) | G10: (n) | H10: (n) | I10: (n) | J10: (tonnes) | K10: (n) | L10: (n) | M10: (n) | N10: (tonnes) | O10: (n) | P10: (n) | Q10: (n) | R10: (tonnes) | S10: (n) | T10: (n) | U10: (n)
A11: Fleet 1: Northern Chile (inside EEZ) | R11: =SUM(N11,J11,F11,B11) -> 0 | S11: =SUM(O11,K11,G11,C11) -> 0 | T11: =SUM(P11,L11,H11,D11) -> 0 | U11: =SUM(Q11,M11,I11,E11) -> 0
A12: Fleet 2: South-Central Chile (EEZ/HS) | B12: 0 | R12: =SUM(N12,J12,F12,B12) -> 0 | S12: =SUM(O12,K12,G12,C12) -> 0 | T12: =SUM(P12,L12,H12,D12) -> 0 | U12: =SUM(Q12,M12,I12,E12) -> 0
A13: Fleet 3: Peru & Equador (inside EEZ) | R13: =SUM(N13,J13,F13,B13) -> 0 | S13: =SUM(O13,K13,G13,C13) -> 0 | T13: =SUM(P13,L13,H13,D13) -> 0 | U13: =SUM(Q13,M13,I13,E13) -> 0
A14: Fleet 4: Offshore (outside EEZ) | R14: =SUM(N14,J14,F14,B14) -> 0 | S14: =SUM(O14,K14,G14,C14) -> 0 | T14: =SUM(P14,L14,H14,D14) -> 0 | U14: =SUM(Q14,M14,I14,E14) -> 0
A15: Total | B15: =SUM(B11:B14) -> 0 | C15: =SUM(C11:C14) -> 0 | D15: =SUM(D11:D14) -> 0 | E15: =SUM(E11:E14) -> 0 | F15: =SUM(F11:F14) -> 0 | G15: =SUM(G11:G14) -> 0 | H15: =SUM(H11:H14) -> 0 | I15: =SUM(I11:I14) -> 0 | ... Q15: =SUM(Q11:Q14) -> 0 | R15: =SUM(N15,J15,F15,B15) -> 0 | S15: =SUM(S11:S14) -> 0 | T15: =SUM(T11:T14) -> 0 | U15: =SUM(U11:U14) -> 0

Sheet LEN F1
A1: LENGTH DISTRIBUTIONS BY FLEET AND QUARTER
A2: Raised to the total catch by quarter
A3: Member: | B3: ='START HERE'!F6 -> EU | E3: Fleet : | F3: Fleet 1 Northern Chile
A4: Species : | B4: ='START HERE'!F5 -> Jack mackerel
A5: Year : | B5: ='START HERE'!$K$3 -> 2007 | E5: Unit : | F5: thousands
E6: Revised (date) : | F6: ='START HERE'!$F8 -> 13/6/2022
A8: ='START HERE'!$F$13 -> fork length | B8: Quarter1 | C8: Quarter 2 | D8: Quarter 3 | E8: Quarter 4 | F8: All year
A9: (cm) | B9: ='START HERE'!$K$3 -> 2007 | C9: ='START HERE'!$K$3 -> 2007 | D9: ='START HERE'!$K$3 -> 2007 | E9: ='START HERE'!$K$3 -> 2007 | F9: ='START HERE'!$K$3 -> 2007
A10: 1 | F10: =SUM(B10:E10) -> 0
A11: 2 | F11: =SUM(B11:E11) -> 0
A12: 3 | F12: =SUM(B12:E12) -> 0
A13: 4 | F13: =SUM(B13:E13) -> 0
A14: 5 | F14: =SUM(B14:E14) -> 0
A15: 6 | F15: =SUM(B15:E15) -> 0
A16: 7 | F16: =SUM(B16:E16) -> 0
A17: 8 | F17: =SUM(B17:E17) -> 0
A18: 9 | F18: =SUM(B18:E18) -> 0
A19: 10 | F19: =SUM(B19:E19) -> 0
A20: 11 | F20: =SUM(B20:E20) -> 0
A21: 12 | F21: =SUM(B21:E21) -> 0
... A109: 100 | F109: =SUM(B109:E109) -> 0
A110: TOTAL numbers | B110: =SUM(B10:B109) -> 0 | C110: =SUM(C10:C109) -> 0 | D110: =SUM(D10:D109) -> 0 | E110: =SUM(E10:E109) -> 0 | F110: =SUM(F10:F109) -> 0

Sheet LEN F2
A1: LENGTH DISTRIBUTIONS BY FLEET AND QUARTER
A2: Raised to the total catch by quarter
A3: Member: | B3: ='START HERE'!F6 -> EU | E3: Fleet : | F3: Fleet 2 South-Central Chile
A4: Species : | B4: ='START HERE'!F5 -> Jack mackerel
A5: Year : | B5: ='START HERE'!$K$3 -> 2007 | E5: Unit : | F5: thousands
E6: Revised (date) : | F6: ='START HERE'!$F8 -> 13/6/2022
A8: ='START HERE'!$F$13 -> fork length | B8: Quarter1 | C8: Quarter 2 | D8: Quarter 3 | E8: Quarter 4 | F8: All year
A9: (cm) | B9: ='START HERE'!$K$3 -> 2007 | C9: ='START HERE'!$K$3 -> 2007 | D9: ='START HERE'!$K$3 -> 2007 | E9: ='START HERE'!$K$3 -> 2007 | F9: ='START HERE'!$K$3 -> 2007
A10: 1 | F10: =SUM(B10:E10) -> 0
A11: 2 | F11: =SUM(B11:E11) -> 0
A12: 3 | F12: =SUM(B12:E12) -> 0
A13: 4 | F13: =SUM(B13:E13) -> 0
A14: 5 | F14: =SUM(B14:E14) -> 0
A15: 6 | F15: =SUM(B15:E15) -> 0
A16: 7 | F16: =SUM(B16:E16) -> 0
A17: 8 | F17: =SUM(B17:E17) -> 0
A18: 9 | F18: =SUM(B18:E18) -> 0
A19: 10 | F19: =SUM(B19:E19) -> 0
A20: 11 | F20: =SUM(B20:E20) -> 0
A21: 12 | F21: =SUM(B21:E21) -> 0
... A109: 100 | F109: =SUM(B109:E109) -> 0
A110: TOTAL numbers | B110: =SUM(B10:B109) -> 0 | C110: =SUM(C10:C109) -> 0 | D110: =SUM(D10:D109) -> 0 | E110: =SUM(E10:E109) -> 0 | F110: =SUM(F10:F109) -> 0

Sheet LEN F3
A1: LENGTH DISTRIBUTIONS BY FLEET AND QUARTER
A2: Raised to the total catch by quarter
A3: Member: | B3: ='START HERE'!F6 -> EU | E3: Fleet : | F3: Fleet 3 Peru & Equador
A4: Species : | B4: ='START HERE'!F5 -> Jack mackerel
A5: Year : | B5: ='START HERE'!$K$3 -> 2007 | E5: Unit : | F5: thousands
E6: Revised (date) : | F6: ='START HERE'!$F8 -> 13/6/2022
A8: ='START HERE'!$F$13 -> fork length | B8: Quarter1 | C8: Quarter 2 | D8: Quarter 3 | E8: Quarter 4 | F8: All year
A9: (cm) | B9: ='START HERE'!$K$3 -> 2007 | C9: ='START HERE'!$K$3 -> 2007 | D9: ='START HERE'!$K$3 -> 2007 | E9: ='START HERE'!$K$3 -> 2007 | F9: ='START HERE'!$K$3 -> 2007
A10: 1 | F10: =SUM(B10:E10) -> 0
A11: 2 | F11: =SUM(B11:E11) -> 0
A12: 3 | F12: =SUM(B12:E12) -> 0
A13: 4 | F13: =SUM(B13:E13) -> 0
A14: 5 | F14: =SUM(B14:E14) -> 0
A15: 6 | F15: =SUM(B15:E15) -> 0
A16: 7 | F16: =SUM(B16:E16) -> 0
A17: 8 | F17: =SUM(B17:E17) -> 0
A18: 9 | F18: =SUM(B18:E18) -> 0
A19: 10 | F19: =SUM(B19:E19) -> 0
A20: 11 | F20: =SUM(B20:E20) -> 0
A21: 12 | F21: =SUM(B21:E21) -> 0
... A109: 100 | F109: =SUM(B109:E109) -> 0
A110: TOTAL numbers | B110: =SUM(B10:B109) -> 0 | C110: =SUM(C10:C109) -> 0 | D110: =SUM(D10:D109) -> 0 | E110: =SUM(E10:E109) -> 0 | F110: =SUM(F10:F109) -> 0

Sheet LEN F4
A1: LENGTH DISTRIBUTIONS BY FLEET AND QUARTER
A2: Raised to the total catch by quarter
A3: Member: | B3: ='START HERE'!F6 -> EU | E3: Fleet : | F3: Fleet 4 Offshore
A4: Species : | B4: ='START HERE'!F5 -> Jack mackerel
A5: Year : | B5: ='START HERE'!$K$3 -> 2007 | E5: Unit : | F5: thousands
E6: Revised (date) : | F6: ='START HERE'!$F8 -> 13/6/2022
A8: ='START HERE'!$F$13 -> fork length | B8: Quarter1 | C8: Quarter 2 | D8: Quarter 3 | E8: Quarter 4 | F8: All year
A9: (cm) | B9: ='START HERE'!$K$3 -> 2007 | C9: ='START HERE'!$K$3 -> 2007 | D9: ='START HERE'!$K$3 -> 2007 | E9: ='START HERE'!$K$3 -> 2007 | F9: ='START HERE'!$K$3 -> 2007
A10: 1 | F10: =SUM(B10:E10) -> 0
A11: 2 | F11: =SUM(B11:E11) -> 0
A12: 3 | F12: =SUM(B12:E12) -> 0
A13: 4 | F13: =SUM(B13:E13) -> 0
A14: 5 | F14: =SUM(B14:E14) -> 0
A15: 6 | F15: =SUM(B15:E15) -> 0
A16: 7 | F16: =SUM(B16:E16) -> 0
A17: 8 | F17: =SUM(B17:E17) -> 0
A18: 9 | F18: =SUM(B18:E18) -> 0
A19: 10 | F19: =SUM(B19:E19) -> 0
A20: 11 | F20: =SUM(B20:E20) -> 0
A21: 12 | F21: =SUM(B21:E21) -> 0
... A23: 14 | F23: =SUM(B23:E23) -> 0
A24: 15 | C24: 0
A25: 16 | C25: 0
A26: 17
A27: 18
A28: 19
A29: 20
A30: 21
A31: 22
A32: 23
A33: 24
A34: 25 | C34: 0
A35: 26 | C35: 170.1611
A36: 27 | C36: 4254.0274
A37: 28 | C37: 21440.298
A38: 29 | C38: 47730.188
A39: 30 | C39: 100990.61
A40: 31 | C40: 140723.23
A41: 32 | C41: 138851.46
A42: 33 | C42: 118432.12
...

Sheet ALK F1
A1: AGE-LENGTH DISTRIBUTIONS BY FLEET AND QUARTER
A2: Raised to the total catch by quarter
A3: Member: | B3: ='START HERE'!F6 -> EU | F3: Fleet : | G3: ='LEN F1'!F3 -> Fleet 1 Northern Chile
A4: Species : | B4: ='START HERE'!F5 -> Jack mackerel
A5: Year : | B5: ='START HERE'!K3 -> 2007 | F5: Unit : | G5: Thousands
F6: Revised (date) : | G6: ='START HERE'!$F8 -> 13/6/2022
B9: Quarter 1 | Q9: Quarter 2 | AF9: Quarter 3 | AU9: Quarter 4
A10: ='START HERE'!$F$13 -> fork length | B10: Age | P10: =A10 -> fork length | Q10: Age | AE10: =A10 -> fork length | AF10: Age | AT10: =A10 -> fork length | AU10: Age
A11: (cm) | B11: 0 | C11: 1 | D11: 2 | E11: 3 | F11: 4 | G11: 5 | H11: 6 | I11: 7 | J11: 8 | K11: 9 | L11: 10 | M11: 11 | N11: 12 | P11: (cm) | Q11: 0 | R11: 1 | S11: 2 | T11: 3 | U11: 4 | V11: 5 | W11: 6 | X11: 7 | Y11: 8 | Z11: 9 | AA11: 10 | AB11: 11 | AC11: 12 | AE11: (cm) | AF11: 0 | AG11: 1 | AH11: 2 | AI11: 3 | AJ11: 4 | AK11: 5 | AL11: 6 | AM11: 7 | AN11: 8 | AO11: 9 | AP11: 10 | AQ11: 11 | AR11: 12 | AT11: (cm) | AU11: 0 | AV11: 1 | AW11: 2 | AX11: 3 | AY11: 4 | AZ11: 5 | BA11: 6 | BB11: 7 | BC11: 8 | BD11: 9 | BE11: 10 | BF11: 11 | BG11: 12
A12: 1 | P12: 1 | AE12: 1 | AT12: 1
A13: 2 | P13: 2 | AE13: 2 | AT13: 2
A14: 3 | P14: 3 | AE14: 3 | AT14: 3
A15: 4 | P15: 4 | AE15: 4 | AT15: 4
A16: 5 | P16: 5 | AE16: 5 | AT16: 5
A17: 6 | P17: 6 | AE17: 6 | AT17: 6
A18: 7 | P18: 7 | AE18: 7 | AT18: 7
A19: 8 | P19: 8 | AE19: 8 | AT19: 8
A20: 9 | P20: 9 | AE20: 9 | AT20: 9
A21: 10 | P21: 10 | AE21: 10 | AT21: 10
A22: 11 | P22: 11 | AE22: 11 | AT22: 11
A23: 12 | P23: 12 | AE23: 12 | AT23: 12
... A111: 100 | P111: 100 | AE111: 100 | AT111: 100
A112: TOTAL | B112: =SUM(B12:B111) -> 0 | C112: =SUM(C12:C111) -> 0 | D112: =SUM(D12:D111) -> 0 | E112: =SUM(E12:E111) -> 0 | F112: =SUM(F12:F111) -> 0 | G112: =SUM(G12:G111) -> 0 | H112: =SUM(H12:H111) -> 0 | I112: =SUM(I12:I111) -> 0 | ... N112: =SUM(N12:N111) -> 0 | P112: TOTAL | Q112: =SUM(Q12:Q111) -> 0 | R112: =SUM(R12:R111) -> 0 | S112: =SUM(S12:S111) -> 0 | T112: =SUM(T12:T111) -> 0 | U112: =SUM(U12:U111) -> 0 | V112: =SUM(V12:V111) -> 0 | W112: =SUM(W12:W111) -> 0 | X112: =SUM(X12:X111) -> 0 | ... AC112: =SUM(AC12:AC111) -> 0 | AE112: TOTAL | AF112: =SUM(AF12:AF111) -> 0 | AG112: =SUM(AG12:AG111) -> 0 | AH112: =SUM(AH12:AH111) -> 0 | AI112: =SUM(AI12:AI111) -> 0 | AJ112: =SUM(AJ12:AJ111) -> 0 | AK112: =SUM(AK12:AK111) -> 0 | AL112: =SUM(AL12:AL111) -> 0 | AM112: =SUM(AM12:AM111) -> 0 | ... AR112: =SUM(AR12:AR111) -> 0 | AT112: TOTAL | AU112: =SUM(AU12:AU111) -> 0 | AV112: =SUM(AV12:AV111) -> 0 | AW112: =SUM(AW12:AW111) -> 0 | AX112: =SUM(AX12:AX111) -> 0 | AY112: =SUM(AY12:AY111) -> 0 | AZ112: =SUM(AZ12:AZ111) -> 0 | BA112: =SUM(BA12:BA111) -> 0 | BB112: =SUM(BB12:BB111) -> 0 | ... BG112: =SUM(BG12:BG111) -> 0

Sheet ALK F2
A1: AGE-LENGTH DISTRIBUTIONS BY FLEET AND QUARTER
A2: Raised to the total catch by quarter
A3: Member: | B3: ='START HERE'!F6 -> EU | F3: Fleet : | G3: ='LEN F2'!F3 -> Fleet 2 South-Central Chile
A4: Species : | B4: ='START HERE'!F5 -> Jack mackerel
A5: Year : | B5: ='START HERE'!K3 -> 2007 | F5: Unit : | G5: Thousands
F6: Revised (date) : | G6: ='START HERE'!$F8 -> 13/6/2022
B9: Quarter 1 | Q9: Quarter 2 | AF9: Quarter 3 | AU9: Quarter 4
A10: ='START HERE'!$F$13 -> fork length | B10: Age | P10: =A10 -> fork length | Q10: Age | AE10: =A10 -> fork length | AF10: Age | AT10: =A10 -> fork length | AU10: Age
A11: (cm) | B11: 0 | C11: 1 | D11: 2 | E11: 3 | F11: 4 | G11: 5 | H11: 6 | I11: 7 | J11: 8 | K11: 9 | L11: 10 | M11: 11 | N11: 12 | P11: (cm) | Q11: 0 | R11: 1 | S11: 2 | T11: 3 | U11: 4 | V11: 5 | W11: 6 | X11: 7 | Y11: 8 | Z11: 9 | AA11: 10 | AB11: 11 | AC11: 12 | AE11: (cm) | AF11: 0 | AG11: 1 | AH11: 2 | AI11: 3 | AJ11: 4 | AK11: 5 | AL11: 6 | AM11: 7 | AN11: 8 | AO11: 9 | AP11: 10 | AQ11: 11 | AR11: 12 | AT11: (cm) | AU11: 0 | AV11: 1 | AW11: 2 | AX11: 3 | AY11: 4 | AZ11: 5 | BA11: 6 | BB11: 7 | BC11: 8 | BD11: 9 | BE11: 10 | BF11: 11 | BG11: 12
A12: 1 | P12: 1 | AE12: 1 | AT12: 1
A13: 2 | P13: 2 | AE13: 2 | AT13: 2
A14: 3 | P14: 3 | AE14: 3 | AT14: 3
A15: 4 | P15: 4 | AE15: 4 | AT15: 4
A16: 5 | P16: 5 | AE16: 5 | AT16: 5
A17: 6 | P17: 6 | AE17: 6 | AT17: 6
A18: 7 | P18: 7 | AE18: 7 | AT18: 7
A19: 8 | P19: 8 | AE19: 8 | AT19: 8
A20: 9 | P20: 9 | AE20: 9 | AT20: 9
A21: 10 | P21: 10 | AE21: 10 | AT21: 10
A22: 11 | P22: 11 | AE22: 11 | AT22: 11
A23: 12 | P23: 12 | AE23: 12 | AT23: 12
... A111: 100 | P111: 100 | AE111: 100 | AT111: 100
A112: TOTAL | B112: =SUM(B12:B111) -> 0 | C112: =SUM(C12:C111) -> 0 | D112: =SUM(D12:D111) -> 0 | E112: =SUM(E12:E111) -> 0 | F112: =SUM(F12:F111) -> 0 | G112: =SUM(G12:G111) -> 0 | H112: =SUM(H12:H111) -> 0 | I112: =SUM(I12:I111) -> 0 | ... N112: =SUM(N12:N111) -> 0 | P112: TOTAL | Q112: =SUM(Q12:Q111) -> 0 | R112: =SUM(R12:R111) -> 0 | S112: =SUM(S12:S111) -> 0 | T112: =SUM(T12:T111) -> 0 | U112: =SUM(U12:U111) -> 0 | V112: =SUM(V12:V111) -> 0 | W112: =SUM(W12:W111) -> 0 | X112: =SUM(X12:X111) -> 0 | ... AC112: =SUM(AC12:AC111) -> 0 | AE112: TOTAL | AF112: =SUM(AF12:AF111) -> 0 | AG112: =SUM(AG12:AG111) -> 0 | AH112: =SUM(AH12:AH111) -> 0 | AI112: =SUM(AI12:AI111) -> 0 | AJ112: =SUM(AJ12:AJ111) -> 0 | AK112: =SUM(AK12:AK111) -> 0 | AL112: =SUM(AL12:AL111) -> 0 | AM112: =SUM(AM12:AM111) -> 0 | ... AR112: =SUM(AR12:AR111) -> 0 | AT112: TOTAL | AU112: =SUM(AU12:AU111) -> 0 | AV112: =SUM(AV12:AV111) -> 0 | AW112: =SUM(AW12:AW111) -> 0 | AX112: =SUM(AX12:AX111) -> 0 | AY112: =SUM(AY12:AY111) -> 0 | AZ112: =SUM(AZ12:AZ111) -> 0 | BA112: =SUM(BA12:BA111) -> 0 | BB112: =SUM(BB12:BB111) -> 0 | ... BG112: =SUM(BG12:BG111) -> 0

Sheet ALK F3
A1: AGE-LENGTH DISTRIBUTIONS BY FLEET AND QUARTER
A2: Raised to the total catch by quarter
A3: Member: | B3: ='START HERE'!F6 -> EU | F3: Fleet : | G3: ='LEN F3'!F3 -> Fleet 3 Peru & Equador
A4: Species : | B4: ='START HERE'!F5 -> Jack mackerel
A5: Year : | B5: ='START HERE'!K3 -> 2007 | F5: Unit : | G5: Thousands
F6: Revised (date) : | G6: ='START HERE'!$F8 -> 13/6/2022
B9: Quarter 1 | Q9: Quarter 2 | AF9: Quarter 3 | AU9: Quarter 4
A10: ='START HERE'!$F$13 -> fork length | B10: Age | P10: =A10 -> fork length | Q10: Age | AE10: =A10 -> fork length | AF10: Age | AT10: =A10 -> fork length | AU10: Age
A11: (cm) | B11: 0 | C11: 1 | D11: 2 | E11: 3 | F11: 4 | G11: 5 | H11: 6 | I11: 7 | J11: 8 | K11: 9 | L11: 10 | M11: 11 | N11: 12 | P11: (cm) | Q11: 0 | R11: 1 | S11: 2 | T11: 3 | U11: 4 | V11: 5 | W11: 6 | X11: 7 | Y11: 8 | Z11: 9 | AA11: 10 | AB11: 11 | AC11: 12 | AE11: (cm) | AF11: 0 | AG11: 1 | AH11: 2 | AI11: 3 | AJ11: 4 | AK11: 5 | AL11: 6 | AM11: 7 | AN11: 8 | AO11: 9 | AP11: 10 | AQ11: 11 | AR11: 12 | AT11: (cm) | AU11: 0 | AV11: 1 | AW11: 2 | AX11: 3 | AY11: 4 | AZ11: 5 | BA11: 6 | BB11: 7 | BC11: 8 | BD11: 9 | BE11: 10 | BF11: 11 | BG11: 12
A12: 1 | P12: 1 | AE12: 1 | AT12: 1
A13: 2 | P13: 2 | AE13: 2 | AT13: 2
A14: 3 | P14: 3 | AE14: 3 | AT14: 3
A15: 4 | P15: 4 | AE15: 4 | AT15: 4
A16: 5 | P16: 5 | AE16: 5 | AT16: 5
A17: 6 | P17: 6 | AE17: 6 | AT17: 6
A18: 7 | P18: 7 | AE18: 7 | AT18: 7
A19: 8 | P19: 8 | AE19: 8 | AT19: 8
A20: 9 | P20: 9 | AE20: 9 | AT20: 9
A21: 10 | P21: 10 | AE21: 10 | AT21: 10
A22: 11 | P22: 11 | AE22: 11 | AT22: 11
A23: 12 | P23: 12 | AE23: 12 | AT23: 12
... A111: 100 | P111: 100 | AE111: 100 | AT111: 100
A112: TOTAL | B112: =SUM(B12:B111) -> 0 | C112: =SUM(C12:C111) -> 0 | D112: =SUM(D12:D111) -> 0 | E112: =SUM(E12:E111) -> 0 | F112: =SUM(F12:F111) -> 0 | G112: =SUM(G12:G111) -> 0 | H112: =SUM(H12:H111) -> 0 | I112: =SUM(I12:I111) -> 0 | ... N112: =SUM(N12:N111) -> 0 | P112: TOTAL | Q112: =SUM(Q12:Q111) -> 0 | R112: =SUM(R12:R111) -> 0 | S112: =SUM(S12:S111) -> 0 | T112: =SUM(T12:T111) -> 0 | U112: =SUM(U12:U111) -> 0 | V112: =SUM(V12:V111) -> 0 | W112: =SUM(W12:W111) -> 0 | X112: =SUM(X12:X111) -> 0 | ... AC112: =SUM(AC12:AC111) -> 0 | AE112: TOTAL | AF112: =SUM(AF12:AF111) -> 0 | AG112: =SUM(AG12:AG111) -> 0 | AH112: =SUM(AH12:AH111) -> 0 | AI112: =SUM(AI12:AI111) -> 0 | AJ112: =SUM(AJ12:AJ111) -> 0 | AK112: =SUM(AK12:AK111) -> 0 | AL112: =SUM(AL12:AL111) -> 0 | AM112: =SUM(AM12:AM111) -> 0 | ... AR112: =SUM(AR12:AR111) -> 0 | AT112: TOTAL | AU112: =SUM(AU12:AU111) -> 0 | AV112: =SUM(AV12:AV111) -> 0 | AW112: =SUM(AW12:AW111) -> 0 | AX112: =SUM(AX12:AX111) -> 0 | AY112: =SUM(AY12:AY111) -> 0 | AZ112: =SUM(AZ12:AZ111) -> 0 | BA112: =SUM(BA12:BA111) -> 0 | BB112: =SUM(BB12:BB111) -> 0 | ... BG112: =SUM(BG12:BG111) -> 0

Sheet ALK F4
A1: AGE-LENGTH DISTRIBUTIONS BY FLEET AND QUARTER
A2: Raised to the total catch by quarter
A3: Member: | B3: ='START HERE'!F6 -> EU | F3: Fleet : | G3: ='LEN F4'!F3 -> Fleet 4 Offshore
A4: Species : | B4: ='START HERE'!F5 -> Jack mackerel
A5: Year : | B5: ='START HERE'!K3 -> 2007 | F5: Unit : | G5: individuals
F6: Revised (date) : | G6: ='START HERE'!$F8 -> 13/6/2022
B9: Quarter 1 | Q9: Quarter 2 | AF9: Quarter 3 | AU9: Quarter 4
A10: ='START HERE'!$F$13 -> fork length | B10: Age | P10: =A10 -> fork length | Q10: Age | AE10: =A10 -> fork length | AF10: Age | AT10: =A10 -> fork length | AU10: Age
A11: (cm) | B11: 0 | C11: 1 | D11: 2 | E11: 3 | F11: 4 | G11: 5 | H11: 6 | I11: 7 | J11: 8 | K11: 9 | L11: 10 | M11: 11 | N11: 12 | P11: (cm) | Q11: 0 | R11: 1 | S11: 2 | T11: 3 | U11: 4 | V11: 5 | W11: 6 | X11: 7 | Y11: 8 | Z11: 9 | AA11: 10 | AB11: 11 | AC11: 12 | AE11: (cm) | AF11: 0 | AG11: 1 | AH11: 2 | AI11: 3 | AJ11: 4 | AK11: 5 | AL11: 6 | AM11: 7 | AN11: 8 | AO11: 9 | AP11: 10 | AQ11: 11 | AR11: 12 | AT11: (cm) | AU11: 0 | AV11: 1 | AW11: 2 | AX11: 3 | AY11: 4 | AZ11: 5 | BA11: 6 | BB11: 7 | BC11: 8 | BD11: 9 | BE11: 10 | BF11: 11 | BG11: 12
A12: 1 | P12: 1 | AE12: 1 | AT12: 1
A13: 2 | P13: 2 | AE13: 2 | AT13: 2
A14: 3 | P14: 3 | AE14: 3 | AT14: 3
A15: 4 | P15: 4 | AE15: 4 | AT15: 4
A16: 5 | P16: 5 | AE16: 5 | AT16: 5
A17: 6 | P17: 6 | AE17: 6 | AT17: 6
A18: 7 | P18: 7 | AE18: 7 | AT18: 7
A19: 8 | P19: 8 | AE19: 8 | AT19: 8
A20: 9 | P20: 9 | AE20: 9 | AT20: 9
A21: 10 | P21: 10 | AE21: 10 | AT21: 10
A22: 11 | P22: 11 | AE22: 11 | AT22: 11
A23: 12 | P23: 12 | AE23: 12 | AT23: 12
... A111: 100 | P111: 100 | AE111: 100 | AT111: 100
A112: TOTAL | B112: =SUM(B12:B111) -> 0 | C112: =SUM(C12:C111) -> 0 | D112: =SUM(D12:D111) -> 0 | E112: =SUM(E12:E111) -> 0 | F112: =SUM(F12:F111) -> 0 | G112: =SUM(G12:G111) -> 0 | H112: =SUM(H12:H111) -> 0 | I112: =SUM(I12:I111) -> 0 | ... N112: =SUM(N12:N111) -> 0 | P112: TOTAL | Q112: =SUM(Q12:Q111) -> 0 | R112: =SUM(R12:R111) -> 0 | S112: =SUM(S12:S111) -> 0 | T112: =SUM(T12:T111) -> 0 | U112: =SUM(U12:U111) -> 0 | V112: =SUM(V12:V111) -> 0 | W112: =SUM(W12:W111) -> 0 | X112: =SUM(X12:X111) -> 0 | ... AC112: =SUM(AC12:AC111) -> 0 | AE112: TOTAL | AF112: =SUM(AF12:AF111) -> 0 | AG112: =SUM(AG12:AG111) -> 0 | AH112: =SUM(AH12:AH111) -> 0 | AI112: =SUM(AI12:AI111) -> 0 | AJ112: =SUM(AJ12:AJ111) -> 0 | AK112: =SUM(AK12:AK111) -> 0 | AL112: =SUM(AL12:AL111) -> 0 | AM112: =SUM(AM12:AM111) -> 0 | ... AR112: =SUM(AR12:AR111) -> 0 | AT112: TOTAL | AU112: =SUM(AU12:AU111) -> 0 | AV112: =SUM(AV12:AV111) -> 0 | AW112: =SUM(AW12:AW111) -> 0 | AX112: =SUM(AX12:AX111) -> 0 | AY112: =SUM(AY12:AY111) -> 0 | AZ112: =SUM(AZ12:AZ111) -> 0 | BA112: =SUM(BA12:BA111) -> 0 | BB112: =SUM(BB12:BB111) -> 0 | ... BG112: =SUM(BG12:BG111) -> 0

Sheet CN F1
A1: CATCH NUMBERS, LENGTH AND WEIGHT AT AGE | H1: Numbers at age should include discards
A2: Of the sample(s) taken, raised to the total catch of the sample(s)
B4: Member: | C4: ='START HERE'!F6 -> EU | H4: Fleet : | I4: ='LEN F1'!F3 -> Fleet 1 Northern Chile
B5: Species: | C5: ='START HERE'!F5 -> Jack mackerel
B6: Year: | C6: ='START HERE'!$K$3 -> 2007 | H6: Revised (date) : | I6: ='START HERE'!$F8 -> 13/6/2022
C8: Quarter 1 | F8: Quarter 2 | I8: Quarter 3 | L8: Quarter 4 | O8: All year
C9: Numbers | D9: Mean | E9: Mean | F9: Numbers | G9: Mean | H9: Mean | I9: Numbers | J9: Mean | K9: Mean | L9: Numbers | M9: Mean | N9: Mean | O9: Numbers | P9: Mean | Q9: Mean
B10: Age | C10: at age | D10: Length | E10: Weight | F10: at age | G10: Length | H10: Weight | I10: at age | J10: Length | K10: Weight | L10: at age | M10: Length | N10: Weight | O10: at age | P10: Length | Q10: Weight
C11: (thousands) | D11: (cm) | E11: (kg) | F11: (thousands) | G11: (cm) | H11: (kg) | I11: (thousands) | J11: (cm) | K11: (kg) | L11: (thousands) | M11: (cm) | N11: (kg) | O11: (thousands) | P11: (cm) | Q11: (g)
B12: 0 | O12: =SUM(C12+F12+I12+L12) -> 0 | P12: =IF(SUM(D12+G12+J12+M12)>0,(C12*D12+F12*G12+I12*J12+L12*M12)/SUM(C12+F12+I12+L12),"") | Q12: =IF(SUM(E12,H12,K12,N12)>0,SUM(C12*E12+F12*H12+I12*K12+L12*N12)/SUM(C12+F12+I12+L12),"")
B13: 1 | O13: =SUM(C13+F13+I13+L13) -> 0 | P13: =IF(SUM(D13+G13+J13+M13)>0,(C13*D13+F13*G13+I13*J13+L13*M13)/SUM(C13+F13+I13+L13),"") | Q13: =IF(SUM(E13,H13,K13,N13)>0,SUM(C13*E13+F13*H13+I13*K13+L13*N13)/SUM(C13+F13+I13+L13),"")
B14: 2 | O14: =SUM(C14+F14+I14+L14) -> 0 | P14: =IF(SUM(D14+G14+J14+M14)>0,(C14*D14+F14*G14+I14*J14+L14*M14)/SUM(C14+F14+I14+L14),"") | Q14: =IF(SUM(E14,H14,K14,N14)>0,SUM(C14*E14+F14*H14+I14*K14+L14*N14)/SUM(C14+F14+I14+L14),"")
B15: 3 | O15: =SUM(C15+F15+I15+L15) -> 0 | P15: =IF(SUM(D15+G15+J15+M15)>0,(C15*D15+F15*G15+I15*J15+L15*M15)/SUM(C15+F15+I15+L15),"") | Q15: =IF(SUM(E15,H15,K15,N15)>0,SUM(C15*E15+F15*H15+I15*K15+L15*N15)/SUM(C15+F15+I15+L15),"")
B16: 4 | O16: =SUM(C16+F16+I16+L16) -> 0 | P16: =IF(SUM(D16+G16+J16+M16)>0,(C16*D16+F16*G16+I16*J16+L16*M16)/SUM(C16+F16+I16+L16),"") | Q16: =IF(SUM(E16,H16,K16,N16)>0,SUM(C16*E16+F16*H16+I16*K16+L16*N16)/SUM(C16+F16+I16+L16),"")
B17: 5 | O17: =SUM(C17+F17+I17+L17) -> 0 | P17: =IF(SUM(D17+G17+J17+M17)>0,(C17*D17+F17*G17+I17*J17+L17*M17)/SUM(C17+F17+I17+L17),"") | Q17: =IF(SUM(E17,H17,K17,N17)>0,SUM(C17*E17+F17*H17+I17*K17+L17*N17)/SUM(C17+F17+I17+L17),"")
B18: 6 | O18: =SUM(C18+F18+I18+L18) -> 0 | P18: =IF(SUM(D18+G18+J18+M18)>0,(C18*D18+F18*G18+I18*J18+L18*M18)/SUM(C18+F18+I18+L18),"") | Q18: =IF(SUM(E18,H18,K18,N18)>0,SUM(C18*E18+F18*H18+I18*K18+L18*N18)/SUM(C18+F18+I18+L18),"")
B19: 7 | O19: =SUM(C19+F19+I19+L19) -> 0 | P19: =IF(SUM(D19+G19+J19+M19)>0,(C19*D19+F19*G19+I19*J19+L19*M19)/SUM(C19+F19+I19+L19),"") | Q19: =IF(SUM(E19,H19,K19,N19)>0,SUM(C19*E19+F19*H19+I19*K19+L19*N19)/SUM(C19+F19+I19+L19),"")
B20: 8 | O20: =SUM(C20+F20+I20+L20) -> 0 | P20: =IF(SUM(D20+G20+J20+M20)>0,(C20*D20+F20*G20+I20*J20+L20*M20)/SUM(C20+F20+I20+L20),"") | Q20: =IF(SUM(E20,H20,K20,N20)>0,SUM(C20*E20+F20*H20+I20*K20+L20*N20)/SUM(C20+F20+I20+L20),"")
B21: 9
B22: 10
B23: 11
A24: Plus-group | B24: 12+ | O24: =SUM(C24+F24+I24+L24) -> 0 | P24: =IF(SUM(D24+G24+J24+M24)>0,(C24*D24+F24*G24+I24*J24+L24*M24)/SUM(C24+F24+I24+L24),"") | Q24: =IF(SUM(E24,H24,K24,N24)>0,SUM(C24*E24+F24*H24+I24*K24+L24*N24)/SUM(C24+F24+I24+L24),"")
B25: Total/Mean --> | C25: =IF(SUM(C12:C24)>0,SUM(C12:C24),"na") -> na | D25: =IF(SUM(D12:D24)>0,SUMPRODUCT(C12:C24,D12:D24)/C25,"na") -> na | E25: =IF(SUM(E12:E24)>0,SUMPRODUCT(C12:C24,E12:E24)/C25,"na") -> na | F25: =IF(SUM(F12:F24)>0,SUM(F12:F24),"na") -> na | G25: =IF(SUM(G12:G24)>0,SUMPRODUCT(F12:F24,G12:G24)/F25,"na") -> na | H25: =IF(SUM(H12:H24)>0,SUMPRODUCT(F12:F24,H12:H24)/F25,"na") -> na | I25: =IF(SUM(I12:I24)>0,SUM(I12:I24),"na") -> na | J25: =IF(SUM(J12:J24)>0,SUMPRODUCT(I12:I24,J12:J24)/I25,"na") -> na | K25: =IF(SUM(K12:K24)>0,SUMPRODUCT(I12:I24,K12:K24)/I25,"na") -> na | L25: =IF(SUM(L12:L24)>0,SUM(L12:L24),"na") -> na | M25: =IF(SUM(M12:M24)>0,SUMPRODUCT(L12:L24,M12:M24)/L25,"na") -> na | N25: =IF(SUM(N12:N24)>0,SUMPRODUCT(L12:L24,N12:N24)/L25,"na") -> na | O25: =IF(SUM(O12:O24)>0,SUM(O12:O24),"na") -> na | P25: =IF(SUM(P12:P24)>0,SUMPRODUCT(O12:O24,P12:P24)/O25,"na") -> na | Q25: =IF(SUM(Q12:Q24)>0,SUMPRODUCT(O12:O24,Q12:Q24)/O25,"na") -> na
C27: Total catch | E27: (t) | F27: Total catch | H27: (t) | I27: Total catch | K27: (t) | L27: Total catch | N27: (t) | O27: Total catch | P27: =SUM(M27,J27,G27,D27) -> 0 | Q27: (t)
C28: SoP | D28: =IF(SUM(E12:E24)>0,(C25*E25),"na") -> na | E28: (t) | F28: SoP | G28: =IF(SUM(H12:H24)>0,(F25*H25),"na") -> na | H28: (t) | I28: SoP | J28: =IF(SUM(K12:K24)>0,(I25*K25),"na") -> na | K28: (t) | L28: SoP | M28: =IF(SUM(N12:N24)>0,(L25*N25),"na") -> na | N28: (t) | O28: SoP | P28: =IF(SUM(Q12:Q24)>0,(O25*Q25),"na") -> na | Q28: (t)
C29: SoP | D29: =IF(SUM(E12:E24)>0,D28/D27,"na") -> na | E29: (%) | F29: SoP | G29: =IF(SUM(H12:H24)>0,G28/G27,"na") -> na | H29: (%) | I29: SoP | J29: =IF(SUM(K12:K24)>0,J28/J27,"na") -> na | K29: (%) | L29: SoP | M29: =IF(SUM(N12:N24)>0,M28/M27,"na") -> na | N29: (%) | O29: SoP | P29: =IF(SUM(Q12:Q24)>0,P28/P27,"na") -> na | Q29: (%)
C31: No. aged | E31: (n) | F31: No. aged | H31: (n) | I31: No. aged | K31: (n) | L31: No. aged | N31: (n) | O31: No. aged | Q31: (n)

Sheet CN F2
A1: CATCH NUMBERS, LENGTH AND WEIGHT AT AGE | H1: Numbers at age should include discards
A2: Of the sample(s) taken, raised to the total catch of the sample(s)
B4: Member: | C4: ='START HERE'!F6 -> EU | H4: Fleet : | I4: ='LEN F2'!F3 -> Fleet 2 South-Central Chile
B5: Species: | C5: ='START HERE'!F5 -> Jack mackerel
B6: Year: | C6: ='START HERE'!$K$3 -> 2007 | H6: Revised (date) : | I6: ='START HERE'!$F8 -> 13/6/2022
C8: Quarter 1 | F8: Quarter 2 | I8: Quarter 3 | L8: Quarter 4 | O8: All year
C9: Numbers | D9: Mean | E9: Mean | F9: Numbers | G9: Mean | H9: Mean | I9: Numbers | J9: Mean | K9: Mean | L9: Numbers | M9: Mean | N9: Mean | O9: Numbers | P9: Mean | Q9: Mean
B10: Age | C10: at age | D10: Length | E10: Weight | F10: at age | G10: Length | H10: Weight | I10: at age | J10: Length | K10: Weight | L10: at age | M10: Length | N10: Weight | O10: at age | P10: Length | Q10: Weight
C11: (thousands) | D11: (cm) | E11: (kg) | F11: (thousands) | G11: (cm) | H11: (kg) | I11: (thousands) | J11: (cm) | K11: (kg) | L11: (thousands) | M11: (cm) | N11: (kg) | O11: (thousands) | P11: (cm) | Q11: (g)
B12: 0 | O12: =SUM(C12+F12+I12+L12) -> 0 | P12: =IF(SUM(D12+G12+J12+M12)>0,(C12*D12+F12*G12+I12*J12+L12*M12)/SUM(C12+F12+I12+L12),"") | Q12: =IF(SUM(E12,H12,K12,N12)>0,SUM(C12*E12+F12*H12+I12*K12+L12*N12)/SUM(C12+F12+I12+L12),"")
B13: 1 | O13: =SUM(C13+F13+I13+L13) -> 0 | P13: =IF(SUM(D13+G13+J13+M13)>0,(C13*D13+F13*G13+I13*J13+L13*M13)/SUM(C13+F13+I13+L13),"") | Q13: =IF(SUM(E13,H13,K13,N13)>0,SUM(C13*E13+F13*H13+I13*K13+L13*N13)/SUM(C13+F13+I13+L13),"")
B14: 2 | O14: =SUM(C14+F14+I14+L14) -> 0 | P14: =IF(SUM(D14+G14+J14+M14)>0,(C14*D14+F14*G14+I14*J14+L14*M14)/SUM(C14+F14+I14+L14),"") | Q14: =IF(SUM(E14,H14,K14,N14)>0,SUM(C14*E14+F14*H14+I14*K14+L14*N14)/SUM(C14+F14+I14+L14),"")
B15: 3 | O15: =SUM(C15+F15+I15+L15) -> 0 | P15: =IF(SUM(D15+G15+J15+M15)>0,(C15*D15+F15*G15+I15*J15+L15*M15)/SUM(C15+F15+I15+L15),"") | Q15: =IF(SUM(E15,H15,K15,N15)>0,SUM(C15*E15+F15*H15+I15*K15+L15*N15)/SUM(C15+F15+I15+L15),"")
B16: 4 | O16: =SUM(C16+F16+I16+L16) -> 0 | P16: =IF(SUM(D16+G16+J16+M16)>0,(C16*D16+F16*G16+I16*J16+L16*M16)/SUM(C16+F16+I16+L16),"") | Q16: =IF(SUM(E16,H16,K16,N16)>0,SUM(C16*E16+F16*H16+I16*K16+L16*N16)/SUM(C16+F16+I16+L16),"")
B17: 5 | O17: =SUM(C17+F17+I17+L17) -> 0 | P17: =IF(SUM(D17+G17+J17+M17)>0,(C17*D17+F17*G17+I17*J17+L17*M17)/SUM(C17+F17+I17+L17),"") | Q17: =IF(SUM(E17,H17,K17,N17)>0,SUM(C17*E17+F17*H17+I17*K17+L17*N17)/SUM(C17+F17+I17+L17),"")
B18: 6 | O18: =SUM(C18+F18+I18+L18) -> 0 | P18: =IF(SUM(D18+G18+J18+M18)>0,(C18*D18+F18*G18+I18*J18+L18*M18)/SUM(C18+F18+I18+L18),"") | Q18: =IF(SUM(E18,H18,K18,N18)>0,SUM(C18*E18+F18*H18+I18*K18+L18*N18)/SUM(C18+F18+I18+L18),"")
B19: 7 | O19: =SUM(C19+F19+I19+L19) -> 0 | P19: =IF(SUM(D19+G19+J19+M19)>0,(C19*D19+F19*G19+I19*J19+L19*M19)/SUM(C19+F19+I19+L19),"") | Q19: =IF(SUM(E19,H19,K19,N19)>0,SUM(C19*E19+F19*H19+I19*K19+L19*N19)/SUM(C19+F19+I19+L19),"")
B20: 8 | O20: =SUM(C20+F20+I20+L20) -> 0 | P20: =IF(SUM(D20+G20+J20+M20)>0,(C20*D20+F20*G20+I20*J20+L20*M20)/SUM(C20+F20+I20+L20),"") | Q20: =IF(SUM(E20,H20,K20,N20)>0,SUM(C20*E20+F20*H20+I20*K20+L20*N20)/SUM(C20+F20+I20+L20),"")
B21: 9
B22: 10
B23: 11
A24: Plus-group | B24: 12+ | O24: =SUM(C24+F24+I24+L24) -> 0 | P24: =IF(SUM(D24+G24+J24+M24)>0,(C24*D24+F24*G24+I24*J24+L24*M24)/SUM(C24+F24+I24+L24),"") | Q24: =IF(SUM(E24,H24,K24,N24)>0,SUM(C24*E24+F24*H24+I24*K24+L24*N24)/SUM(C24+F24+I24+L24),"")
B25: Total/Mean --> | C25: =IF(SUM(C12:C24)>0,SUM(C12:C24),"na") -> na | D25: =IF(SUM(D12:D24)>0,SUMPRODUCT(C12:C24,D12:D24)/C25,"na") -> na | E25: =IF(SUM(E12:E24)>0,SUMPRODUCT(C12:C24,E12:E24)/C25,"na") -> na | F25: =IF(SUM(F12:F24)>0,SUM(F12:F24),"na") -> na | G25: =IF(SUM(G12:G24)>0,SUMPRODUCT(F12:F24,G12:G24)/F25,"na") -> na | H25: =IF(SUM(H12:H24)>0,SUMPRODUCT(F12:F24,H12:H24)/F25,"na") -> na | I25: =IF(SUM(I12:I24)>0,SUM(I12:I24),"na") -> na | J25: =IF(SUM(J12:J24)>0,SUMPRODUCT(I12:I24,J12:J24)/I25,"na") -> na | K25: =IF(SUM(K12:K24)>0,SUMPRODUCT(I12:I24,K12:K24)/I25,"na") -> na | L25: =IF(SUM(L12:L24)>0,SUM(L12:L24),"na") -> na | M25: =IF(SUM(M12:M24)>0,SUMPRODUCT(L12:L24,M12:M24)/L25,"na") -> na | N25: =IF(SUM(N12:N24)>0,SUMPRODUCT(L12:L24,N12:N24)/L25,"na") -> na | O25: =IF(SUM(O12:O24)>0,SUM(O12:O24),"na") -> na | P25: =IF(SUM(P12:P24)>0,SUMPRODUCT(O12:O24,P12:P24)/O25,"na") -> na | Q25: =IF(SUM(Q12:Q24)>0,SUMPRODUCT(O12:O24,Q12:Q24)/O25,"na") -> na
C27: Total catch | E27: (t) | F27: Total catch | H27: (t) | I27: Total catch | K27: (t) | L27: Total catch | N27: (t) | O27: Total catch | P27: =SUM(M27,J27,G27,D27) -> 0 | Q27: (t)
C28: SoP | D28: =IF(SUM(E12:E24)>0,(C25*E25),"na") -> na | E28: (t) | F28: SoP | G28: =IF(SUM(H12:H24)>0,(F25*H25),"na") -> na | H28: (t) | I28: SoP | J28: =IF(SUM(K12:K24)>0,(I25*K25),"na") -> na | K28: (t) | L28: SoP | M28: =IF(SUM(N12:N24)>0,(L25*N25),"na") -> na | N28: (t) | O28: SoP | P28: =IF(SUM(Q12:Q24)>0,(O25*Q25),"na") -> na | Q28: (t)
C29: SoP | D29: =IF(SUM(E12:E24)>0,D28/D27,"na") -> na | E29: (%) | F29: SoP | G29: =IF(SUM(H12:H24)>0,G28/G27,"na") -> na | H29: (%) | I29: SoP | J29: =IF(SUM(K12:K24)>0,J28/J27,"na") -> na | K29: (%) | L29: SoP | M29: =IF(SUM(N12:N24)>0,M28/M27,"na") -> na | N29: (%) | O29: SoP | P29: =IF(SUM(Q12:Q24)>0,P28/P27,"na") -> na | Q29: (%)
C31: No. aged | E31: (n) | F31: No. aged | H31: (n) | I31: No. aged | K31: (n) | L31: No. aged | N31: (n) | O31: No. aged | Q31: (n)

Sheet CN F3
A1: CATCH NUMBERS, LENGTH AND WEIGHT AT AGE | H1: Numbers at age should include discards
A2: Of the sample(s) taken, raised to the total catch of the sample(s)
B4: Member: | C4: ='START HERE'!F6 -> EU | H4: Fleet : | I4: ='LEN F3'!F3 -> Fleet 3 Peru & Equador
B5: Species: | C5: ='START HERE'!F5 -> Jack mackerel
B6: Year: | C6: ='START HERE'!$K$3 -> 2007 | H6: Revised (date) : | I6: ='START HERE'!$F8 -> 13/6/2022
C8: Quarter 1 | F8: Quarter 2 | I8: Quarter 3 | L8: Quarter 4 | O8: All year
C9: Numbers | D9: Mean | E9: Mean | F9: Numbers | G9: Mean | H9: Mean | I9: Numbers | J9: Mean | K9: Mean | L9: Numbers | M9: Mean | N9: Mean | O9: Numbers | P9: Mean | Q9: Mean
B10: Age | C10: at age | D10: Length | E10: Weight | F10: at age | G10: Length | H10: Weight | I10: at age | J10: Length | K10: Weight | L10: at age | M10: Length | N10: Weight | O10: at age | P10: Length | Q10: Weight
C11: (thousands) | D11: (cm) | E11: (kg) | F11: (thousands) | G11: (cm) | H11: (kg) | I11: (thousands) | J11: (cm) | K11: (kg) | L11: (thousands) | M11: (cm) | N11: (kg) | O11: (thousands) | P11: (cm) | Q11: (g)
B12: 0 | O12: =SUM(C12+F12+I12+L12) -> 0 | P12: =IF(SUM(D12+G12+J12+M12)>0,(C12*D12+F12*G12+I12*J12+L12*M12)/SUM(C12+F12+I12+L12),"") | Q12: =IF(SUM(E12,H12,K12,N12)>0,SUM(C12*E12+F12*H12+I12*K12+L12*N12)/SUM(C12+F12+I12+L12),"")
B13: 1 | O13: =SUM(C13+F13+I13+L13) -> 0 | P13: =IF(SUM(D13+G13+J13+M13)>0,(C13*D13+F13*G13+I13*J13+L13*M13)/SUM(C13+F13+I13+L13),"") | Q13: =IF(SUM(E13,H13,K13,N13)>0,SUM(C13*E13+F13*H13+I13*K13+L13*N13)/SUM(C13+F13+I13+L13),"")
B14: 2 | O14: =SUM(C14+F14+I14+L14) -> 0 | P14: =IF(SUM(D14+G14+J14+M14)>0,(C14*D14+F14*G14+I14*J14+L14*M14)/SUM(C14+F14+I14+L14),"") | Q14: =IF(SUM(E14,H14,K14,N14)>0,SUM(C14*E14+F14*H14+I14*K14+L14*N14)/SUM(C14+F14+I14+L14),"")
B15: 3 | O15: =SUM(C15+F15+I15+L15) -> 0 | P15: =IF(SUM(D15+G15+J15+M15)>0,(C15*D15+F15*G15+I15*J15+L15*M15)/SUM(C15+F15+I15+L15),"") | Q15: =IF(SUM(E15,H15,K15,N15)>0,SUM(C15*E15+F15*H15+I15*K15+L15*N15)/SUM(C15+F15+I15+L15),"")
B16: 4 | O16: =SUM(C16+F16+I16+L16) -> 0 | P16: =IF(SUM(D16+G16+J16+M16)>0,(C16*D16+F16*G16+I16*J16+L16*M16)/SUM(C16+F16+I16+L16),"") | Q16: =IF(SUM(E16,H16,K16,N16)>0,SUM(C16*E16+F16*H16+I16*K16+L16*N16)/SUM(C16+F16+I16+L16),"")
B17: 5 | O17: =SUM(C17+F17+I17+L17) -> 0 | P17: =IF(SUM(D17+G17+J17+M17)>0,(C17*D17+F17*G17+I17*J17+L17*M17)/SUM(C17+F17+I17+L17),"") | Q17: =IF(SUM(E17,H17,K17,N17)>0,SUM(C17*E17+F17*H17+I17*K17+L17*N17)/SUM(C17+F17+I17+L17),"")
B18: 6 | O18: =SUM(C18+F18+I18+L18) -> 0 | P18: =IF(SUM(D18+G18+J18+M18)>0,(C18*D18+F18*G18+I18*J18+L18*M18)/SUM(C18+F18+I18+L18),"") | Q18: =IF(SUM(E18,H18,K18,N18)>0,SUM(C18*E18+F18*H18+I18*K18+L18*N18)/SUM(C18+F18+I18+L18),"")
B19: 7 | O19: =SUM(C19+F19+I19+L19) -> 0 | P19: =IF(SUM(D19+G19+J19+M19)>0,(C19*D19+F19*G19+I19*J19+L19*M19)/SUM(C19+F19+I19+L19),"") | Q19: =IF(SUM(E19,H19,K19,N19)>0,SUM(C19*E19+F19*H19+I19*K19+L19*N19)/SUM(C19+F19+I19+L19),"")
B20: 8 | O20: =SUM(C20+F20+I20+L20) -> 0 | P20: =IF(SUM(D20+G20+J20+M20)>0,(C20*D20+F20*G20+I20*J20+L20*M20)/SUM(C20+F20+I20+L20),"") | Q20: =IF(SUM(E20,H20,K20,N20)>0,SUM(C20*E20+F20*H20+I20*K20+L20*N20)/SUM(C20+F20+I20+L20),"")
B21: 9
B22: 10
B23: 11
A24: Plus-group | B24: 12+ | O24: =SUM(C24+F24+I24+L24) -> 0 | P24: =IF(SUM(D24+G24+J24+M24)>0,(C24*D24+F24*G24+I24*J24+L24*M24)/SUM(C24+F24+I24+L24),"") | Q24: =IF(SUM(E24,H24,K24,N24)>0,SUM(C24*E24+F24*H24+I24*K24+L24*N24)/SUM(C24+F24+I24+L24),"")
B25: Total/Mean --> | C25: =IF(SUM(C12:C24)>0,SUM(C12:C24),"na") -> na | D25: =IF(SUM(D12:D24)>0,SUMPRODUCT(C12:C24,D12:D24)/C25,"na") -> na | E25: =IF(SUM(E12:E24)>0,SUMPRODUCT(C12:C24,E12:E24)/C25,"na") -> na | F25: =IF(SUM(F12:F24)>0,SUM(F12:F24),"na") -> na | G25: =IF(SUM(G12:G24)>0,SUMPRODUCT(F12:F24,G12:G24)/F25,"na") -> na | H25: =IF(SUM(H12:H24)>0,SUMPRODUCT(F12:F24,H12:H24)/F25,"na") -> na | I25: =IF(SUM(I12:I24)>0,SUM(I12:I24),"na") -> na | J25: =IF(SUM(J12:J24)>0,SUMPRODUCT(I12:I24,J12:J24)/I25,"na") -> na | K25: =IF(SUM(K12:K24)>0,SUMPRODUCT(I12:I24,K12:K24)/I25,"na") -> na | L25: =IF(SUM(L12:L24)>0,SUM(L12:L24),"na") -> na | M25: =IF(SUM(M12:M24)>0,SUMPRODUCT(L12:L24,M12:M24)/L25,"na") -> na | N25: =IF(SUM(N12:N24)>0,SUMPRODUCT(L12:L24,N12:N24)/L25,"na") -> na | O25: =IF(SUM(O12:O24)>0,SUM(O12:O24),"na") -> na | P25: =IF(SUM(P12:P24)>0,SUMPRODUCT(O12:O24,P12:P24)/O25,"na") -> na | Q25: =IF(SUM(Q12:Q24)>0,SUMPRODUCT(O12:O24,Q12:Q24)/O25,"na") -> na
C27: Total catch | E27: (t) | F27: Total catch | H27: (t) | I27: Total catch | K27: (t) | L27: Total catch | N27: (t) | O27: Total catch | P27: =SUM(M27,J27,G27,D27) -> 0 | Q27: (t)
C28: SoP | D28: =IF(SUM(E12:E24)>0,(C25*E25),"na") -> na | E28: (t) | F28: SoP | G28: =IF(SUM(H12:H24)>0,(F25*H25),"na") -> na | H28: (t) | I28: SoP | J28: =IF(SUM(K12:K24)>0,(I25*K25),"na") -> na | K28: (t) | L28: SoP | M28: =IF(SUM(N12:N24)>0,(L25*N25),"na") -> na | N28: (t) | O28: SoP | P28: =IF(SUM(Q12:Q24)>0,(O25*Q25),"na") -> na | Q28: (t)
C29: SoP | D29: =IF(SUM(E12:E24)>0,D28/D27,"na") -> na | E29: (%) | F29: SoP | G29: =IF(SUM(H12:H24)>0,G28/G27,"na") -> na | H29: (%) | I29: SoP | J29: =IF(SUM(K12:K24)>0,J28/J27,"na") -> na | K29: (%) | L29: SoP | M29: =IF(SUM(N12:N24)>0,M28/M27,"na") -> na | N29: (%) | O29: SoP | P29: =IF(SUM(Q12:Q24)>0,P28/P27,"na") -> na | Q29: (%)
C31: No. aged | E31: (n) | F31: No. aged | H31: (n) | I31: No. aged | K31: (n) | L31: No. aged | N31: (n) | O31: No. aged | Q31: (n)

Sheet CN F4
A1: CATCH NUMBERS, LENGTH AND WEIGHT AT AGE | H1: Numbers at age should include discards
A2: Of the sample(s) taken, raised to the total catch of the sample(s)
B4: Member: | C4: ='START HERE'!F6 -> EU | H4: Fleet : | I4: ='LEN F4'!F3 -> Fleet 4 Offshore
B5: Species: | C5: ='START HERE'!F5 -> Jack mackerel
B6: Year: | C6: ='START HERE'!$K$3 -> 2007 | H6: Revised (date) : | I6: ='START HERE'!$F8 -> 13/6/2022
C8: Quarter 1 | F8: Quarter 2 | I8: Quarter 3 | L8: Quarter 4 | O8: All year
C9: Numbers | D9: Mean | E9: Mean | F9: Numbers | G9: Mean | H9: Mean | I9: Numbers | J9: Mean | K9: Mean | L9: Numbers | M9: Mean | N9: Mean | O9: Numbers | P9: Mean | Q9: Mean
B10: Age | C10: at age | D10: Length | E10: Weight | F10: at age | G10: Length | H10: Weight | I10: at age | J10: Length | K10: Weight | L10: at age | M10: Length | N10: Weight | O10: at age | P10: Length | Q10: Weight
C11: (thousands) | D11: (cm) | E11: (kg) | F11: (thousands) | G11: (cm) | H11: (kg) | I11: (thousands) | J11: (cm) | K11: (kg) | L11: (thousands) | M11: (cm) | N11: (kg) | O11: (thousands) | P11: (cm) | Q11: (g)
B12: 0 | O12: =SUM(C12+F12+I12+L12) -> 0 | P12: =IF(SUM(D12+G12+J12+M12)>0,(C12*D12+F12*G12+I12*J12+L12*M12)/SUM(C12+F12+I12+L12),"") | Q12: =IF(SUM(E12,H12,K12,N12)>0,SUM(C12*E12+F12*H12+I12*K12+L12*N12)/SUM(C12+F12+I12+L12),"")
B13: 1 | O13: =SUM(C13+F13+I13+L13) -> 0 | P13: =IF(SUM(D13+G13+J13+M13)>0,(C13*D13+F13*G13+I13*J13+L13*M13)/SUM(C13+F13+I13+L13),"") | Q13: =IF(SUM(E13,H13,K13,N13)>0,SUM(C13*E13+F13*H13+I13*K13+L13*N13)/SUM(C13+F13+I13+L13),"")
B14: 2 | O14: =SUM(C14+F14+I14+L14) -> 0 | P14: =IF(SUM(D14+G14+J14+M14)>0,(C14*D14+F14*G14+I14*J14+L14*M14)/SUM(C14+F14+I14+L14),"") | Q14: =IF(SUM(E14,H14,K14,N14)>0,SUM(C14*E14+F14*H14+I14*K14+L14*N14)/SUM(C14+F14+I14+L14),"")
B15: 3 | O15: =SUM(C15+F15+I15+L15) -> 0 | P15: =IF(SUM(D15+G15+J15+M15)>0,(C15*D15+F15*G15+I15*J15+L15*M15)/SUM(C15+F15+I15+L15),"") | Q15: =IF(SUM(E15,H15,K15,N15)>0,SUM(C15*E15+F15*H15+I15*K15+L15*N15)/SUM(C15+F15+I15+L15),"")
B16: 4 | O16: =SUM(C16+F16+I16+L16) -> 0 | P16: =IF(SUM(D16+G16+J16+M16)>0,(C16*D16+F16*G16+I16*J16+L16*M16)/SUM(C16+F16+I16+L16),"") | Q16: =IF(SUM(E16,H16,K16,N16)>0,SUM(C16*E16+F16*H16+I16*K16+L16*N16)/SUM(C16+F16+I16+L16),"")
B17: 5 | O17: =SUM(C17+F17+I17+L17) -> 0 | P17: =IF(SUM(D17+G17+J17+M17)>0,(C17*D17+F17*G17+I17*J17+L17*M17)/SUM(C17+F17+I17+L17),"") | Q17: =IF(SUM(E17,H17,K17,N17)>0,SUM(C17*E17+F17*H17+I17*K17+L17*N17)/SUM(C17+F17+I17+L17),"")
B18: 6 | O18: =SUM(C18+F18+I18+L18) -> 0 | P18: =IF(SUM(D18+G18+J18+M18)>0,(C18*D18+F18*G18+I18*J18+L18*M18)/SUM(C18+F18+I18+L18),"") | Q18: =IF(SUM(E18,H18,K18,N18)>0,SUM(C18*E18+F18*H18+I18*K18+L18*N18)/SUM(C18+F18+I18+L18),"")
B19: 7 | O19: =SUM(C19+F19+I19+L19) -> 0 | P19: =IF(SUM(D19+G19+J19+M19)>0,(C19*D19+F19*G19+I19*J19+L19*M19)/SUM(C19+F19+I19+L19),"") | Q19: =IF(SUM(E19,H19,K19,N19)>0,SUM(C19*E19+F19*H19+I19*K19+L19*N19)/SUM(C19+F19+I19+L19),"")
B20: 8 | O20: =SUM(C20+F20+I20+L20) -> 0 | P20: =IF(SUM(D20+G20+J20+M20)>0,(C20*D20+F20*G20+I20*J20+L20*M20)/SUM(C20+F20+I20+L20),"") | Q20: =IF(SUM(E20,H20,K20,N20)>0,SUM(C20*E20+F20*H20+I20*K20+L20*N20)/SUM(C20+F20+I20+L20),"")
B21: 9
B22: 10
B23: 11
A24: Plus-group | B24: 12+ | O24: =SUM(C24+F24+I24+L24) -> 0 | P24: =IF(SUM(D24+G24+J24+M24)>0,(C24*D24+F24*G24+I24*J24+L24*M24)/SUM(C24+F24+I24+L24),"") | Q24: =IF(SUM(E24,H24,K24,N24)>0,SUM(C24*E24+F24*H24+I24*K24+L24*N24)/SUM(C24+F24+I24+L24),"")
B25: Total/Mean --> | C25: =IF(SUM(C12:C24)>0,SUM(C12:C24),"na") -> na | D25: =IF(SUM(D12:D24)>0,SUMPRODUCT(C12:C24,D12:D24)/C25,"na") -> na | E25: =IF(SUM(E12:E24)>0,SUMPRODUCT(C12:C24,E12:E24)/C25,"na") -> na | F25: =IF(SUM(F12:F24)>0,SUM(F12:F24),"na") -> na | G25: =IF(SUM(G12:G24)>0,SUMPRODUCT(F12:F24,G12:G24)/F25,"na") -> na | H25: =IF(SUM(H12:H24)>0,SUMPRODUCT(F12:F24,H12:H24)/F25,"na") -> na | I25: =IF(SUM(I12:I24)>0,SUM(I12:I24),"na") -> na | J25: =IF(SUM(J12:J24)>0,SUMPRODUCT(I12:I24,J12:J24)/I25,"na") -> na | K25: =IF(SUM(K12:K24)>0,SUMPRODUCT(I12:I24,K12:K24)/I25,"na") -> na | L25: =IF(SUM(L12:L24)>0,SUM(L12:L24),"na") -> na | M25: =IF(SUM(M12:M24)>0,SUMPRODUCT(L12:L24,M12:M24)/L25,"na") -> na | N25: =IF(SUM(N12:N24)>0,SUMPRODUCT(L12:L24,N12:N24)/L25,"na") -> na | O25: =IF(SUM(O12:O24)>0,SUM(O12:O24),"na") -> na | P25: =IF(SUM(P12:P24)>0,SUMPRODUCT(O12:O24,P12:P24)/O25,"na") -> na | Q25: =IF(SUM(Q12:Q24)>0,SUMPRODUCT(O12:O24,Q12:Q24)/O25,"na") -> na
C27: Total catch | E27: (t) | F27: Total catch | H27: (t) | I27: Total catch | K27: (t) | L27: Total catch | N27: (t) | O27: Total catch | P27: =SUM(M27,J27,G27,D27) -> 0 | Q27: (t)
C28: SoP | D28: =IF(SUM(E12:E24)>0,(C25*E25),"na") -> na | E28: (t) | F28: SoP | G28: =IF(SUM(H12:H24)>0,(F25*H25),"na") -> na | H28: (t) | I28: SoP | J28: =IF(SUM(K12:K24)>0,(I25*K25),"na") -> na | K28: (t) | L28: SoP | M28: =IF(SUM(N12:N24)>0,(L25*N25),"na") -> na | N28: (t) | O28: SoP | P28: =IF(SUM(Q12:Q24)>0,(O25*Q25),"na") -> na | Q28: (t)
C29: SoP | D29: =IF(SUM(E12:E24)>0,D28/D27,"na") -> na | E29: (%) | F29: SoP | G29: =IF(SUM(H12:H24)>0,G28/G27,"na") -> na | H29: (%) | I29: SoP | J29: =IF(SUM(K12:K24)>0,J28/J27,"na") -> na | K29: (%) | L29: SoP | M29: =IF(SUM(N12:N24)>0,M28/M27,"na") -> na | N29: (%) | O29: SoP | P29: =IF(SUM(Q12:Q24)>0,P28/P27,"na") -> na | Q29: (%)
C31: No. aged | E31: (n) | F31: No. aged | H31: (n) | I31: No. aged | K31: (n) | L31: No. aged | N31: (n) | O31: No. aged | Q31: (n)

Sheet WLK F1
A1: WEIGHT-LENGTH DISTRIBUTIONS BY FLEET AND QUARTER
A2: Weight of an individual at length
A3: Member: | B3: ='START HERE'!F6 -> EU | F3: Fleet : | G3: ='LEN F1'!F3 -> Fleet 1 Northern Chile
A4: Species : | B4: ='START HERE'!F5 -> Jack mackerel
A5: Year : | B5: ='START HERE'!$K$3 -> 2007 | F5: Unit : | G5: Kg
F6: Revised (date) : | G6: ='START HERE'!$F8 -> 13/6/2022
A9: ='START HERE'!$F$13 -> fork length | B9: Quarter1 | C9: Quarter 2 | D9: Quarter 3 | E9: Quarter 4
A10: (cm) | B10: ='START HERE'!$K$3 -> 2007 | C10: ='START HERE'!$K$3 -> 2007 | D10: ='START HERE'!$K$3 -> 2007 | E10: ='START HERE'!$K$3 -> 2007
A11: 1
A12: 2
A13: 3
A14: 4
A15: 5
A16: 6
A17: 7
A18: 8
A19: 9
A20: 10
A21: 11
A22: 12
... A110: 100

Sheet WLK F2
A1: WEIGHT-LENGTH DISTRIBUTIONS BY FLEET AND QUARTER
A2: Weight of an individual at length
A3: Member: | B3: ='START HERE'!F6 -> EU | F3: Fleet : | G3: ='LEN F2'!F3 -> Fleet 2 South-Central Chile
A4: Species : | B4: ='START HERE'!F5 -> Jack mackerel
A5: Year : | B5: ='START HERE'!$K$3 -> 2007 | F5: Unit : | G5: Kg
F6: Revised (date) : | G6: ='START HERE'!$F8 -> 13/6/2022
A9: ='START HERE'!$F$13 -> fork length | B9: Quarter1 | C9: Quarter 2 | D9: Quarter 3 | E9: Quarter 4
A10: (cm) | B10: ='START HERE'!$K$3 -> 2007 | C10: ='START HERE'!$K$3 -> 2007 | D10: ='START HERE'!$K$3 -> 2007 | E10: ='START HERE'!$K$3 -> 2007
A11: 1
A12: 2
A13: 3
A14: 4
A15: 5
A16: 6
A17: 7
A18: 8
A19: 9
A20: 10
A21: 11
A22: 12
... A110: 100

Sheet WLK F3
A1: WEIGHT-LENGTH DISTRIBUTIONS BY FLEET AND QUARTER
A2: Weight of an individual at length
A3: Member: | B3: ='START HERE'!F6 -> EU | F3: Fleet : | G3: ='LEN F3'!F3 -> Fleet 3 Peru & Equador
A4: Species : | B4: ='START HERE'!F5 -> Jack mackerel
A5: Year : | B5: ='START HERE'!$K$3 -> 2007 | F5: Unit : | G5: Kg
F6: Revised (date) : | G6: ='START HERE'!$F8 -> 13/6/2022
A9: ='START HERE'!$F$13 -> fork length | B9: Quarter1 | C9: Quarter 2 | D9: Quarter 3 | E9: Quarter 4
A10: (cm) | B10: ='START HERE'!$K$3 -> 2007 | C10: ='START HERE'!$K$3 -> 2007 | D10: ='START HERE'!$K$3 -> 2007 | E10: ='START HERE'!$K$3 -> 2007
A11: 1
A12: 2
A13: 3
A14: 4
A15: 5
A16: 6
A17: 7
A18: 8
A19: 9
A20: 10
A21: 11
A22: 12
... A110: 100

Sheet WLK F4
A1: WEIGHT-LENGTH DISTRIBUTIONS BY FLEET AND QUARTER
A2: Weight of an individual at length
A3: Member: | B3: ='START HERE'!F6 -> EU | F3: Fleet : | G3: ='LEN F4'!F3 -> Fleet 4 Offshore
A4: Species : | B4: ='START HERE'!F5 -> Jack mackerel
A5: Year : | B5: ='START HERE'!$K$3 -> 2007 | F5: Unit : | G5: Kg
F6: Revised (date) : | G6: ='START HERE'!$F8 -> 13/6/2022
A9: ='START HERE'!$F$13 -> fork length | B9: Quarter1 | C9: Quarter 2 | D9: Quarter 3 | E9: Quarter 4
A10: (cm) | B10: ='START HERE'!$K$3 -> 2007 | C10: ='START HERE'!$K$3 -> 2007 | D10: ='START HERE'!$K$3 -> 2007 | E10: ='START HERE'!$K$3 -> 2007
A11: 1
A12: 2
A13: 3
A14: 4
A15: 5
A16: 6
A17: 7
A18: 8
A19: 9
A20: 10
A21: 11
A22: 12
... A110: 100

Sheet lists
A1: Units | B1: Countries | C1: Species | D1: Length measures
A2: individuals | B2: Chile | C2: Jack mackerel | D2: fork length
A3: thousands | B3: China | D3: total length
A4: millions | B4: Ecuador
B5: EU
B6: Korea
B7: Peru
B8: Russia
B9: Taiwan
B10: Vanuatu
