Workbook

Sheet LEN raised
B1: may | C1: june | D1: july | E1: august | F1: september | G1: october | I1: sum
A2: 15 | B2: 0 | C2: 0 | D2: 0 | E2: 0 | F2: 0 | G2: 0 | I2: =SUM(B2:G2) -> 0
A3: 16 | B3: 0 | C3: 0 | D3: 0 | E3: 0 | F3: 0 | G3: 0 | I3: =SUM(B3:G3) -> 0
A4: 17 | B4: 0 | C4: 0 | D4: 0 | E4: 0 | F4: 6.235 | G4: 0 | I4: =SUM(B4:G4) -> 6.235
A5: 18 | B5: 0 | C5: 0 | D5: 0 | E5: 3.6417893 | F5: 101.81006 | G5: 16.159079 | I5: =SUM(B5:G5) -> 121.61092
A6: 19 | B6: 0 | C6: 0 | D6: 0 | E6: 37.221058 | F6: 49.215499 | G6: 65.841407 | I6: =SUM(B6:G6) -> 152.27796
A7: 20 | B7: 0 | C7: 0 | D7: 0 | E7: 29.2184 | F7: 6.2067234 | G7: 30.355458 | I7: =SUM(B7:G7) -> 65.780581
A8: 21 | B8: 0 | C8: 0 | D8: 0 | E8: 37.972032 | F8: 0 | G8: 37.836497 | I8: =SUM(B8:G8) -> 75.80853
A9: 22 | B9: 0 | C9: 0 | D9: 0 | E9: 5.8454198 | F9: 2.0714286 | G9: 6.5705709 | I9: =SUM(B9:G9) -> 14.487419
A10: 23 | B10: 0 | C10: 0 | D10: 0 | E10: 0 | F10: 2.0714286 | G10: 7.3933013 | I10: =SUM(B10:G10) -> 9.4647299
A11: 24 | B11: 0 | C11: 0 | D11: 0 | E11: 23.143919 | F11: 0 | G11: 5.9196605 | I11: =SUM(B11:G11) -> 29.063579
A12: 25 | B12: 0 | C12: 0 | D12: 0 | E12: 122.16231 | F12: 58.689871 | G12: 16.84517 | I12: =SUM(B12:G12) -> 197.69736
A13: 26 | B13: 0 | C13: 0 | D13: 0 | E13: 1276.5776 | F13: 1091.3571 | G13: 89.322862 | I13: =SUM(B13:G13) -> 2457.2576
... A42: 55 | B42: 0.39354121 | C42: 0 | D42: 0 | E42: 0 | F42: 0 | G42: 0 | I42: =SUM(B42:G42) -> 0.39354121
I43: =SUM(I2:I42) -> 50595.364

Sheet ALK raised
B1: ALL MONTHS
A2: length | B2: II | C2: III | D2: IV | E2: V | F2: VI | G2: VII | H2: VIII | I2: IX | J2: X | K2: XI | L2: 12+ | N2: XII | O2: XIII | P2: XIV | Q2: XV | R2: XVI | S2: XVII | T2: XVIII | U2: XIX | V2: XX
A3: 15 | B3: 0 | C3: 0 | D3: 0 | E3: 0 | F3: 0 | G3: 0 | H3: 0 | I3: 0 | J3: 0 | K3: 0 | L3: =SUM(N3:V3) -> 0 | N3: 0 | O3: 0 | P3: 0 | Q3: 0 | R3: 0 | S3: 0 | T3: 0 | U3: 0 | V3: 0
A4: 16 | B4: 0 | C4: 0 | D4: 0 | E4: 0 | F4: 0 | G4: 0 | H4: 0 | I4: 0 | J4: 0 | K4: 0 | L4: =SUM(N4:V4) -> 0 | N4: 0 | O4: 0 | P4: 0 | Q4: 0 | R4: 0 | S4: 0 | T4: 0 | U4: 0 | V4: 0
A5: 17 | B5: =SUM(sep!D4, okt!D4) -> 2 | C5: =SUM(sep!E4, okt!E4) -> 0 | D5: =SUM(sep!F4, okt!F4) -> 0 | E5: =SUM(sep!G4, okt!G4) -> 0 | F5: =SUM(sep!H4, okt!H4) -> 0 | G5: =SUM(sep!I4, okt!I4) -> 0 | H5: =SUM(sep!J4, okt!J4) -> 0 | I5: =SUM(sep!K4, okt!K4) -> 0 | ... K5: =SUM(sep!M4, okt!M4) -> 0 | L5: =SUM(N5:V5) -> 0 | N5: =SUM(sep!N4, okt!N4) -> 0 | O5: =SUM(sep!O4, okt!O4) -> 0 | P5: =SUM(sep!P4, okt!P4) -> 0 | Q5: =SUM(sep!Q4, okt!Q4) -> 0 | R5: =SUM(sep!R4, okt!R4) -> 0 | S5: =SUM(sep!S4, okt!S4) -> 0 | T5: =SUM(sep!T4, okt!T4) -> 0 | U5: =SUM(sep!U4, okt!U4) -> 0 | V5: =SUM(sep!V4, okt!V4) -> 0
A6: 18 | B6: =SUM(aug!D5, sep!D5, okt!D5) -> 3 | C6: =SUM(aug!E5, sep!E5, okt!E5) -> 0 | D6: =SUM(aug!F5, sep!F5, okt!F5) -> 0 | E6: =SUM(aug!G5, sep!G5, okt!G5) -> 0 | F6: =SUM(aug!H5, sep!H5, okt!H5) -> 0 | G6: =SUM(aug!I5, sep!I5, okt!I5) -> 0 | H6: =SUM(aug!J5, sep!J5, okt!J5) -> 0 | I6: =SUM(aug!K5, sep!K5, okt!K5) -> 0 | ... K6: =SUM(aug!M5, sep!M5, okt!M5) -> 0 | L6: =SUM(N6:V6) -> 0 | N6: =SUM(aug!N5, sep!N5, okt!N5) -> 0 | O6: =SUM(aug!O5, sep!O5, okt!O5) -> 0 | P6: =SUM(aug!P5, sep!P5, okt!P5) -> 0 | Q6: =SUM(aug!Q5, sep!Q5, okt!Q5) -> 0 | R6: =SUM(aug!R5, sep!R5, okt!R5) -> 0 | S6: =SUM(aug!S5, sep!S5, okt!S5) -> 0 | T6: =SUM(aug!T5, sep!T5, okt!T5) -> 0 | U6: =SUM(aug!U5, sep!U5, okt!U5) -> 0 | V6: =SUM(aug!V5, sep!V5, okt!V5) -> 0
A7: 19 | B7: =SUM(aug!D6, sep!D6, okt!D6) -> 3 | C7: =SUM(aug!E6, sep!E6, okt!E6) -> 0 | D7: =SUM(aug!F6, sep!F6, okt!F6) -> 0 | E7: =SUM(aug!G6, sep!G6, okt!G6) -> 0 | F7: =SUM(aug!H6, sep!H6, okt!H6) -> 0 | G7: =SUM(aug!I6, sep!I6, okt!I6) -> 0 | H7: =SUM(aug!J6, sep!J6, okt!J6) -> 0 | I7: =SUM(aug!K6, sep!K6, okt!K6) -> 0 | ... K7: =SUM(aug!M6, sep!M6, okt!M6) -> 0 | L7: =SUM(N7:V7) -> 0 | N7: =SUM(aug!N6, sep!N6, okt!N6) -> 0 | O7: =SUM(aug!O6, sep!O6, okt!O6) -> 0 | P7: =SUM(aug!P6, sep!P6, okt!P6) -> 0 | Q7: =SUM(aug!Q6, sep!Q6, okt!Q6) -> 0 | R7: =SUM(aug!R6, sep!R6, okt!R6) -> 0 | S7: =SUM(aug!S6, sep!S6, okt!S6) -> 0 | T7: =SUM(aug!T6, sep!T6, okt!T6) -> 0 | U7: =SUM(aug!U6, sep!U6, okt!U6) -> 0 | V7: =SUM(aug!V6, sep!V6, okt!V6) -> 0
A8: 20 | B8: =SUM(aug!D7, sep!D7, okt!D7) -> 3 | C8: =SUM(aug!E7, sep!E7, okt!E7) -> 0 | D8: =SUM(aug!F7, sep!F7, okt!F7) -> 0 | E8: =SUM(aug!G7, sep!G7, okt!G7) -> 0 | F8: =SUM(aug!H7, sep!H7, okt!H7) -> 0 | G8: =SUM(aug!I7, sep!I7, okt!I7) -> 0 | H8: =SUM(aug!J7, sep!J7, okt!J7) -> 0 | I8: =SUM(aug!K7, sep!K7, okt!K7) -> 0 | ... K8: =SUM(aug!M7, sep!M7, okt!M7) -> 0 | L8: =SUM(N8:V8) -> 0 | N8: =SUM(aug!N7, sep!N7, okt!N7) -> 0 | O8: =SUM(aug!O7, sep!O7, okt!O7) -> 0 | P8: =SUM(aug!P7, sep!P7, okt!P7) -> 0 | Q8: =SUM(aug!Q7, sep!Q7, okt!Q7) -> 0 | R8: =SUM(aug!R7, sep!R7, okt!R7) -> 0 | S8: =SUM(aug!S7, sep!S7, okt!S7) -> 0 | T8: =SUM(aug!T7, sep!T7, okt!T7) -> 0 | U8: =SUM(aug!U7, sep!U7, okt!U7) -> 0 | V8: =SUM(aug!V7, sep!V7, okt!V7) -> 0
A9: 21 | B9: =SUM(aug!D8, sep!D8, okt!D8) -> 3 | C9: =SUM(aug!E8, sep!E8, okt!E8) -> 0 | D9: =SUM(aug!F8, sep!F8, okt!F8) -> 0 | E9: =SUM(aug!G8, sep!G8, okt!G8) -> 0 | F9: =SUM(aug!H8, sep!H8, okt!H8) -> 0 | G9: =SUM(aug!I8, sep!I8, okt!I8) -> 0 | H9: =SUM(aug!J8, sep!J8, okt!J8) -> 0 | I9: =SUM(aug!K8, sep!K8, okt!K8) -> 0 | ... K9: =SUM(aug!M8, sep!M8, okt!M8) -> 0 | L9: =SUM(N9:V9) -> 0 | N9: =SUM(aug!N8, sep!N8, okt!N8) -> 0 | O9: =SUM(aug!O8, sep!O8, okt!O8) -> 0 | P9: =SUM(aug!P8, sep!P8, okt!P8) -> 0 | Q9: =SUM(aug!Q8, sep!Q8, okt!Q8) -> 0 | R9: =SUM(aug!R8, sep!R8, okt!R8) -> 0 | S9: =SUM(aug!S8, sep!S8, okt!S8) -> 0 | T9: =SUM(aug!T8, sep!T8, okt!T8) -> 0 | U9: =SUM(aug!U8, sep!U8, okt!U8) -> 0 | V9: =SUM(aug!V8, sep!V8, okt!V8) -> 0
A10: 22 | B10: =SUM(aug!D9, sep!D9, okt!D9) -> 3 | C10: =SUM(aug!E9, sep!E9, okt!E9) -> 0 | D10: =SUM(aug!F9, sep!F9, okt!F9) -> 0 | E10: =SUM(aug!G9, sep!G9, okt!G9) -> 0 | F10: =SUM(aug!H9, sep!H9, okt!H9) -> 0 | G10: =SUM(aug!I9, sep!I9, okt!I9) -> 0 | H10: =SUM(aug!J9, sep!J9, okt!J9) -> 0 | I10: =SUM(aug!K9, sep!K9, okt!K9) -> 0 | ... K10: =SUM(aug!M9, sep!M9, okt!M9) -> 0 | L10: =SUM(N10:V10) -> 0 | N10: =SUM(aug!N9, sep!N9, okt!N9) -> 0 | O10: =SUM(aug!O9, sep!O9, okt!O9) -> 0 | P10: =SUM(aug!P9, sep!P9, okt!P9) -> 0 | Q10: =SUM(aug!Q9, sep!Q9, okt!Q9) -> 0 | R10: =SUM(aug!R9, sep!R9, okt!R9) -> 0 | S10: =SUM(aug!S9, sep!S9, okt!S9) -> 0 | T10: =SUM(aug!T9, sep!T9, okt!T9) -> 0 | U10: =SUM(aug!U9, sep!U9, okt!U9) -> 0 | V10: =SUM(aug!V9, sep!V9, okt!V9) -> 0
A11: 23 | B11: =SUM(aug!D10, sep!D10, okt!D10) -> 3 | C11: =SUM(aug!E10, sep!E10, okt!E10) -> 0 | D11: =SUM(aug!F10, sep!F10, okt!F10) -> 0 | E11: =SUM(aug!G10, sep!G10, okt!G10) -> 0 | F11: =SUM(aug!H10, sep!H10, okt!H10) -> 0 | G11: =SUM(aug!I10, sep!I10, okt!I10) -> 0 | H11: =SUM(aug!J10, sep!J10, okt!J10) -> 0 | I11: =SUM(aug!K10, sep!K10, okt!K10) -> 0 | ... K11: =SUM(aug!M10, sep!M10, okt!M10) -> 0 | L11: =SUM(N11:V11) -> 0 | N11: =SUM(aug!N10, sep!N10, okt!N10) -> 0 | O11: =SUM(aug!O10, sep!O10, okt!O10) -> 0 | P11: =SUM(aug!P10, sep!P10, okt!P10) -> 0 | Q11: =SUM(aug!Q10, sep!Q10, okt!Q10) -> 0 | R11: =SUM(aug!R10, sep!R10, okt!R10) -> 0 | S11: =SUM(aug!S10, sep!S10, okt!S10) -> 0 | T11: =SUM(aug!T10, sep!T10, okt!T10) -> 0 | U11: =SUM(aug!U10, sep!U10, okt!U10) -> 0 | V11: =SUM(aug!V10, sep!V10, okt!V10) -> 0
A12: 24 | B12: =SUM(aug!D11, sep!D11, okt!D11) -> 0 | C12: =SUM(aug!E11, sep!E11, okt!E11) -> 3 | D12: =SUM(aug!F11, sep!F11, okt!F11) -> 0 | E12: =SUM(aug!G11, sep!G11, okt!G11) -> 0 | F12: =SUM(aug!H11, sep!H11, okt!H11) -> 0 | G12: =SUM(aug!I11, sep!I11, okt!I11) -> 0 | H12: =SUM(aug!J11, sep!J11, okt!J11) -> 0 | I12: =SUM(aug!K11, sep!K11, okt!K11) -> 0 | ... K12: =SUM(aug!M11, sep!M11, okt!M11) -> 0 | L12: =SUM(N12:V12) -> 0 | N12: =SUM(aug!N11, sep!N11, okt!N11) -> 0 | O12: =SUM(aug!O11, sep!O11, okt!O11) -> 0 | P12: =SUM(aug!P11, sep!P11, okt!P11) -> 0 | Q12: =SUM(aug!Q11, sep!Q11, okt!Q11) -> 0 | R12: =SUM(aug!R11, sep!R11, okt!R11) -> 0 | S12: =SUM(aug!S11, sep!S11, okt!S11) -> 0 | T12: =SUM(aug!T11, sep!T11, okt!T11) -> 0 | U12: =SUM(aug!U11, sep!U11, okt!U11) -> 0 | V12: =SUM(aug!V11, sep!V11, okt!V11) -> 0
A13: 25 | B13: =SUM(aug!D12, sep!D12, okt!D12) -> 0 | C13: =SUM(aug!E12, sep!E12, okt!E12) -> 3 | D13: =SUM(aug!F12, sep!F12, okt!F12) -> 0 | E13: =SUM(aug!G12, sep!G12, okt!G12) -> 0 | F13: =SUM(aug!H12, sep!H12, okt!H12) -> 0 | G13: =SUM(aug!I12, sep!I12, okt!I12) -> 0 | H13: =SUM(aug!J12, sep!J12, okt!J12) -> 0 | I13: =SUM(aug!K12, sep!K12, okt!K12) -> 0 | ... K13: =SUM(aug!M12, sep!M12, okt!M12) -> 0 | L13: =SUM(N13:V13) -> 0 | N13: =SUM(aug!N12, sep!N12, okt!N12) -> 0 | O13: =SUM(aug!O12, sep!O12, okt!O12) -> 0 | P13: =SUM(aug!P12, sep!P12, okt!P12) -> 0 | Q13: =SUM(aug!Q12, sep!Q12, okt!Q12) -> 0 | R13: =SUM(aug!R12, sep!R12, okt!R12) -> 0 | S13: =SUM(aug!S12, sep!S12, okt!S12) -> 0 | T13: =SUM(aug!T12, sep!T12, okt!T12) -> 0 | U13: =SUM(aug!U12, sep!U12, okt!U12) -> 0 | V13: =SUM(aug!V12, sep!V12, okt!V12) -> 0
A14: 26 | B14: =SUM(aug!D13, sep!D13, okt!D13) -> 6 | C14: =SUM(aug!E13, sep!E13, okt!E13) -> 27 | D14: =SUM(aug!F13, sep!F13, okt!F13) -> 9 | E14: =SUM(aug!G13, sep!G13, okt!G13) -> 0 | F14: =SUM(aug!H13, sep!H13, okt!H13) -> 0 | G14: =SUM(aug!I13, sep!I13, okt!I13) -> 0 | H14: =SUM(aug!J13, sep!J13, okt!J13) -> 0 | I14: =SUM(aug!K13, sep!K13, okt!K13) -> 0 | ... K14: =SUM(aug!M13, sep!M13, okt!M13) -> 0 | L14: =SUM(N14:V14) -> 0 | N14: =SUM(aug!N13, sep!N13, okt!N13) -> 0 | O14: =SUM(aug!O13, sep!O13, okt!O13) -> 0 | P14: =SUM(aug!P13, sep!P13, okt!P13) -> 0 | Q14: =SUM(aug!Q13, sep!Q13, okt!Q13) -> 0 | R14: =SUM(aug!R13, sep!R13, okt!R13) -> 0 | S14: =SUM(aug!S13, sep!S13, okt!S13) -> 0 | T14: =SUM(aug!T13, sep!T13, okt!T13) -> 0 | U14: =SUM(aug!U13, sep!U13, okt!U13) -> 0 | V14: =SUM(aug!V13, sep!V13, okt!V13) -> 0
A15: 27 | B15: =SUM(aug!D14, sep!D14, okt!D14) -> 0 | C15: =SUM(aug!E14, sep!E14, okt!E14) -> 156 | D15: =SUM(aug!F14, sep!F14, okt!F14) -> 78 | E15: =SUM(aug!G14, sep!G14, okt!G14) -> 6 | F15: =SUM(aug!H14, sep!H14, okt!H14) -> 0 | G15: =SUM(aug!I14, sep!I14, okt!I14) -> 0 | H15: =SUM(aug!J14, sep!J14, okt!J14) -> 0 | I15: =SUM(aug!K14, sep!K14, okt!K14) -> 0 | ... K15: =SUM(aug!M14, sep!M14, okt!M14) -> 0 | L15: =SUM(N15:V15) -> 0 | N15: =SUM(aug!N14, sep!N14, okt!N14) -> 0 | O15: =SUM(aug!O14, sep!O14, okt!O14) -> 0 | P15: =SUM(aug!P14, sep!P14, okt!P14) -> 0 | Q15: =SUM(aug!Q14, sep!Q14, okt!Q14) -> 0 | R15: =SUM(aug!R14, sep!R14, okt!R14) -> 0 | S15: =SUM(aug!S14, sep!S14, okt!S14) -> 0 | T15: =SUM(aug!T14, sep!T14, okt!T14) -> 0 | U15: =SUM(aug!U14, sep!U14, okt!U14) -> 0 | V15: =SUM(aug!V14, sep!V14, okt!V14) -> 0
A16: 28 | B16: =SUM(mei!D15, jun!D15, jul!D15, aug!D15, sep!D15, okt!D15) -> 0 | C16: =SUM(mei!E15, jun!E15, jul!E15, aug!E15, sep!E15, okt!E15) -> 107 | D16: =SUM(mei!F15, jun!F15, jul!F15, aug!F15, sep!F15, okt!F15) -> 70 | E16: =SUM(mei!G15, jun!G15, jul!G15, aug!G15, sep!G15, okt!G15) -> 7 | F16: =SUM(mei!H15, jun!H15, jul!H15, aug!H15, sep!H15, okt!H15) -> 3 | G16: =SUM(mei!I15, jun!I15, jul!I15, aug!I15, sep!I15, okt!I15) -> 0 | H16: =SUM(mei!J15, jun!J15, jul!J15, aug!J15, sep!J15, okt!J15) -> 0 | I16: =SUM(mei!K15, jun!K15, jul!K15, aug!K15, sep!K15, okt!K15) -> 0 | ... K16: =SUM(mei!M15, jun!M15, jul!M15, aug!M15, sep!M15, okt!M15) -> 0 | L16: =SUM(N16:V16) -> 0 | N16: =SUM(mei!N15, jun!N15, jul!N15, aug!N15, sep!N15, okt!N15) -> 0 | O16: =SUM(mei!O15, jun!O15, jul!O15, aug!O15, sep!O15, okt!O15) -> 0 | P16: =SUM(mei!P15, jun!P15, jul!P15, aug!P15, sep!P15, okt!P15) -> 0 | Q16: =SUM(mei!Q15, jun!Q15, jul!Q15, aug!Q15, sep!Q15, okt!Q15) -> 0 | R16: =SUM(mei!R15, jun!R15, jul!R15, aug!R15, sep!R15, okt!R15) -> 0 | S16: =SUM(mei!S15, jun!S15, jul!S15, aug!S15, sep!S15, okt!S15) -> 0 | T16: =SUM(mei!T15, jun!T15, jul!T15, aug!T15, sep!T15, okt!T15) -> 0 | U16: =SUM(mei!U15, jun!U15, jul!U15, aug!U15, sep!U15, okt!U15) -> 0 | V16: =SUM(mei!V15, jun!V15, jul!V15, aug!V15, sep!V15, okt!V15) -> 0
A17: 29 | B17: =SUM(mei!D16, jun!D16, jul!D16, aug!D16, sep!D16, okt!D16) -> 0 | C17: =SUM(mei!E16, jun!E16, jul!E16, aug!E16, sep!E16, okt!E16) -> 30 | D17: =SUM(mei!F16, jun!F16, jul!F16, aug!F16, sep!F16, okt!F16) -> 34 | E17: =SUM(mei!G16, jun!G16, jul!G16, aug!G16, sep!G16, okt!G16) -> 3 | F17: =SUM(mei!H16, jun!H16, jul!H16, aug!H16, sep!H16, okt!H16) -> 1 | G17: =SUM(mei!I16, jun!I16, jul!I16, aug!I16, sep!I16, okt!I16) -> 0 | H17: =SUM(mei!J16, jun!J16, jul!J16, aug!J16, sep!J16, okt!J16) -> 0 | I17: =SUM(mei!K16, jun!K16, jul!K16, aug!K16, sep!K16, okt!K16) -> 0 | ... K17: =SUM(mei!M16, jun!M16, jul!M16, aug!M16, sep!M16, okt!M16) -> 0 | L17: =SUM(N17:V17) -> 0 | N17: =SUM(mei!N16, jun!N16, jul!N16, aug!N16, sep!N16, okt!N16) -> 0 | O17: =SUM(mei!O16, jun!O16, jul!O16, aug!O16, sep!O16, okt!O16) -> 0 | P17: =SUM(mei!P16, jun!P16, jul!P16, aug!P16, sep!P16, okt!P16) -> 0 | Q17: =SUM(mei!Q16, jun!Q16, jul!Q16, aug!Q16, sep!Q16, okt!Q16) -> 0 | R17: =SUM(mei!R16, jun!R16, jul!R16, aug!R16, sep!R16, okt!R16) -> 0 | S17: =SUM(mei!S16, jun!S16, jul!S16, aug!S16, sep!S16, okt!S16) -> 0 | T17: =SUM(mei!T16, jun!T16, jul!T16, aug!T16, sep!T16, okt!T16) -> 0 | U17: =SUM(mei!U16, jun!U16, jul!U16, aug!U16, sep!U16, okt!U16) -> 0 | V17: =SUM(mei!V16, jun!V16, jul!V16, aug!V16, sep!V16, okt!V16) -> 0
A18: 30 | B18: =SUM(mei!D17, jun!D17, jul!D17, aug!D17, sep!D17, okt!D17) -> 0 | C18: =SUM(mei!E17, jun!E17, jul!E17, aug!E17, sep!E17, okt!E17) -> 19 | D18: =SUM(mei!F17, jun!F17, jul!F17, aug!F17, sep!F17, okt!F17) -> 14 | E18: =SUM(mei!G17, jun!G17, jul!G17, aug!G17, sep!G17, okt!G17) -> 3 | F18: =SUM(mei!H17, jun!H17, jul!H17, aug!H17, sep!H17, okt!H17) -> 0 | G18: =SUM(mei!I17, jun!I17, jul!I17, aug!I17, sep!I17, okt!I17) -> 0 | H18: =SUM(mei!J17, jun!J17, jul!J17, aug!J17, sep!J17, okt!J17) -> 0 | I18: =SUM(mei!K17, jun!K17, jul!K17, aug!K17, sep!K17, okt!K17) -> 0 | ... K18: =SUM(mei!M17, jun!M17, jul!M17, aug!M17, sep!M17, okt!M17) -> 0 | L18: =SUM(N18:V18) -> 0 | N18: =SUM(mei!N17, jun!N17, jul!N17, aug!N17, sep!N17, okt!N17) -> 0 | O18: =SUM(mei!O17, jun!O17, jul!O17, aug!O17, sep!O17, okt!O17) -> 0 | P18: =SUM(mei!P17, jun!P17, jul!P17, aug!P17, sep!P17, okt!P17) -> 0 | Q18: =SUM(mei!Q17, jun!Q17, jul!Q17, aug!Q17, sep!Q17, okt!Q17) -> 0 | R18: =SUM(mei!R17, jun!R17, jul!R17, aug!R17, sep!R17, okt!R17) -> 0 | S18: =SUM(mei!S17, jun!S17, jul!S17, aug!S17, sep!S17, okt!S17) -> 0 | T18: =SUM(mei!T17, jun!T17, jul!T17, aug!T17, sep!T17, okt!T17) -> 0 | U18: =SUM(mei!U17, jun!U17, jul!U17, aug!U17, sep!U17, okt!U17) -> 0 | V18: =SUM(mei!V17, jun!V17, jul!V17, aug!V17, sep!V17, okt!V17) -> 0
A19: 31 | B19: =SUM(mei!D18, jun!D18, jul!D18, aug!D18, sep!D18, okt!D18) -> 0 | C19: =SUM(mei!E18, jun!E18, jul!E18, aug!E18, sep!E18, okt!E18) -> 1 | D19: =SUM(mei!F18, jun!F18, jul!F18, aug!F18, sep!F18, okt!F18) -> 20 | E19: =SUM(mei!G18, jun!G18, jul!G18, aug!G18, sep!G18, okt!G18) -> 6 | F19: =SUM(mei!H18, jun!H18, jul!H18, aug!H18, sep!H18, okt!H18) -> 0 | G19: =SUM(mei!I18, jun!I18, jul!I18, aug!I18, sep!I18, okt!I18) -> 0 | H19: =SUM(mei!J18, jun!J18, jul!J18, aug!J18, sep!J18, okt!J18) -> 0 | I19: =SUM(mei!K18, jun!K18, jul!K18, aug!K18, sep!K18, okt!K18) -> 0 | ... K19: =SUM(mei!M18, jun!M18, jul!M18, aug!M18, sep!M18, okt!M18) -> 0 | L19: =SUM(N19:V19) -> 0 | N19: =SUM(mei!N18, jun!N18, jul!N18, aug!N18, sep!N18, okt!N18) -> 0 | O19: =SUM(mei!O18, jun!O18, jul!O18, aug!O18, sep!O18, okt!O18) -> 0 | P19: =SUM(mei!P18, jun!P18, jul!P18, aug!P18, sep!P18, okt!P18) -> 0 | Q19: =SUM(mei!Q18, jun!Q18, jul!Q18, aug!Q18, sep!Q18, okt!Q18) -> 0 | R19: =SUM(mei!R18, jun!R18, jul!R18, aug!R18, sep!R18, okt!R18) -> 0 | S19: =SUM(mei!S18, jun!S18, jul!S18, aug!S18, sep!S18, okt!S18) -> 0 | T19: =SUM(mei!T18, jun!T18, jul!T18, aug!T18, sep!T18, okt!T18) -> 0 | U19: =SUM(mei!U18, jun!U18, jul!U18, aug!U18, sep!U18, okt!U18) -> 0 | V19: =SUM(mei!V18, jun!V18, jul!V18, aug!V18, sep!V18, okt!V18) -> 0
A20: 32 | B20: =SUM(mei!D19, jun!D19, jul!D19, aug!D19, sep!D19, okt!D19) -> 0 | C20: =SUM(mei!E19, jun!E19, jul!E19, aug!E19, sep!E19, okt!E19) -> 3 | D20: =SUM(mei!F19, jun!F19, jul!F19, aug!F19, sep!F19, okt!F19) -> 31 | E20: =SUM(mei!G19, jun!G19, jul!G19, aug!G19, sep!G19, okt!G19) -> 29 | F20: =SUM(mei!H19, jun!H19, jul!H19, aug!H19, sep!H19, okt!H19) -> 0 | G20: =SUM(mei!I19, jun!I19, jul!I19, aug!I19, sep!I19, okt!I19) -> 0 | H20: =SUM(mei!J19, jun!J19, jul!J19, aug!J19, sep!J19, okt!J19) -> 0 | I20: =SUM(mei!K19, jun!K19, jul!K19, aug!K19, sep!K19, okt!K19) -> 0 | ... K20: =SUM(mei!M19, jun!M19, jul!M19, aug!M19, sep!M19, okt!M19) -> 0 | L20: =SUM(N20:V20) -> 0 | N20: =SUM(mei!N19, jun!N19, jul!N19, aug!N19, sep!N19, okt!N19) -> 0 | O20: =SUM(mei!O19, jun!O19, jul!O19, aug!O19, sep!O19, okt!O19) -> 0 | P20: =SUM(mei!P19, jun!P19, jul!P19, aug!P19, sep!P19, okt!P19) -> 0 | Q20: =SUM(mei!Q19, jun!Q19, jul!Q19, aug!Q19, sep!Q19, okt!Q19) -> 0 | R20: =SUM(mei!R19, jun!R19, jul!R19, aug!R19, sep!R19, okt!R19) -> 0 | S20: =SUM(mei!S19, jun!S19, jul!S19, aug!S19, sep!S19, okt!S19) -> 0 | T20: =SUM(mei!T19, jun!T19, jul!T19, aug!T19, sep!T19, okt!T19) -> 0 | U20: =SUM(mei!U19, jun!U19, jul!U19, aug!U19, sep!U19, okt!U19) -> 0 | V20: =SUM(mei!V19, jun!V19, jul!V19, aug!V19, sep!V19, okt!V19) -> 0
A21: 33 | B21: =SUM(mei!D20, jun!D20, jul!D20, aug!D20, sep!D20, okt!D20) -> 0 | C21: =SUM(mei!E20, jun!E20, jul!E20, aug!E20, sep!E20, okt!E20) -> 1 | D21: =SUM(mei!F20, jun!F20, jul!F20, aug!F20, sep!F20, okt!F20) -> 44 | E21: =SUM(mei!G20, jun!G20, jul!G20, aug!G20, sep!G20, okt!G20) -> 78 | F21: =SUM(mei!H20, jun!H20, jul!H20, aug!H20, sep!H20, okt!H20) -> 3 | G21: =SUM(mei!I20, jun!I20, jul!I20, aug!I20, sep!I20, okt!I20) -> 2 | H21: =SUM(mei!J20, jun!J20, jul!J20, aug!J20, sep!J20, okt!J20) -> 0 | I21: =SUM(mei!K20, jun!K20, jul!K20, aug!K20, sep!K20, okt!K20) -> 0 | ... K21: =SUM(mei!M20, jun!M20, jul!M20, aug!M20, sep!M20, okt!M20) -> 0 | L21: =SUM(N21:V21) -> 0 | N21: =SUM(mei!N20, jun!N20, jul!N20, aug!N20, sep!N20, okt!N20) -> 0 | O21: =SUM(mei!O20, jun!O20, jul!O20, aug!O20, sep!O20, okt!O20) -> 0 | P21: =SUM(mei!P20, jun!P20, jul!P20, aug!P20, sep!P20, okt!P20) -> 0 | Q21: =SUM(mei!Q20, jun!Q20, jul!Q20, aug!Q20, sep!Q20, okt!Q20) -> 0 | R21: =SUM(mei!R20, jun!R20, jul!R20, aug!R20, sep!R20, okt!R20) -> 0 | S21: =SUM(mei!S20, jun!S20, jul!S20, aug!S20, sep!S20, okt!S20) -> 0 | T21: =SUM(mei!T20, jun!T20, jul!T20, aug!T20, sep!T20, okt!T20) -> 0 | U21: =SUM(mei!U20, jun!U20, jul!U20, aug!U20, sep!U20, okt!U20) -> 0 | V21: =SUM(mei!V20, jun!V20, jul!V20, aug!V20, sep!V20, okt!V20) -> 0
A22: 34 | B22: =SUM(mei!D21, jun!D21, jul!D21, aug!D21, sep!D21, okt!D21) -> 0 | C22: =SUM(mei!E21, jun!E21, jul!E21, aug!E21, sep!E21, okt!E21) -> 0 | D22: =SUM(mei!F21, jun!F21, jul!F21, aug!F21, sep!F21, okt!F21) -> 107 | E22: =SUM(mei!G21, jun!G21, jul!G21, aug!G21, sep!G21, okt!G21) -> 141 | F22: =SUM(mei!H21, jun!H21, jul!H21, aug!H21, sep!H21, okt!H21) -> 26 | G22: =SUM(mei!I21, jun!I21, jul!I21, aug!I21, sep!I21, okt!I21) -> 7 | H22: =SUM(mei!J21, jun!J21, jul!J21, aug!J21, sep!J21, okt!J21) -> 0 | I22: =SUM(mei!K21, jun!K21, jul!K21, aug!K21, sep!K21, okt!K21) -> 0 | ... K22: =SUM(mei!M21, jun!M21, jul!M21, aug!M21, sep!M21, okt!M21) -> 0 | L22: =SUM(N22:V22) -> 0 | N22: =SUM(mei!N21, jun!N21, jul!N21, aug!N21, sep!N21, okt!N21) -> 0 | O22: =SUM(mei!O21, jun!O21, jul!O21, aug!O21, sep!O21, okt!O21) -> 0 | P22: =SUM(mei!P21, jun!P21, jul!P21, aug!P21, sep!P21, okt!P21) -> 0 | Q22: =SUM(mei!Q21, jun!Q21, jul!Q21, aug!Q21, sep!Q21, okt!Q21) -> 0 | R22: =SUM(mei!R21, jun!R21, jul!R21, aug!R21, sep!R21, okt!R21) -> 0 | S22: =SUM(mei!S21, jun!S21, jul!S21, aug!S21, sep!S21, okt!S21) -> 0 | T22: =SUM(mei!T21, jun!T21, jul!T21, aug!T21, sep!T21, okt!T21) -> 0 | U22: =SUM(mei!U21, jun!U21, jul!U21, aug!U21, sep!U21, okt!U21) -> 0 | V22: =SUM(mei!V21, jun!V21, jul!V21, aug!V21, sep!V21, okt!V21) -> 0
A23: 35 | B23: =SUM(mei!D22, jun!D22, jul!D22, aug!D22, sep!D22, okt!D22) -> 0 | C23: =SUM(mei!E22, jun!E22, jul!E22, aug!E22, sep!E22, okt!E22) -> 0 | D23: =SUM(mei!F22, jun!F22, jul!F22, aug!F22, sep!F22, okt!F22) -> 0 | E23: =SUM(mei!G22, jun!G22, jul!G22, aug!G22, sep!G22, okt!G22) -> 81 | F23: =SUM(mei!H22, jun!H22, jul!H22, aug!H22, sep!H22, okt!H22) -> 101 | G23: =SUM(mei!I22, jun!I22, jul!I22, aug!I22, sep!I22, okt!I22) -> 10 | H23: =SUM(mei!J22, jun!J22, jul!J22, aug!J22, sep!J22, okt!J22) -> 0 | I23: =SUM(mei!K22, jun!K22, jul!K22, aug!K22, sep!K22, okt!K22) -> 0 | ... K23: =SUM(mei!M22, jun!M22, jul!M22, aug!M22, sep!M22, okt!M22) -> 0 | L23: =SUM(N23:V23) -> 0 | N23: =SUM(mei!N22, jun!N22, jul!N22, aug!N22, sep!N22, okt!N22) -> 0 | O23: =SUM(mei!O22, jun!O22, jul!O22, aug!O22, sep!O22, okt!O22) -> 0 | P23: =SUM(mei!P22, jun!P22, jul!P22, aug!P22, sep!P22, okt!P22) -> 0 | Q23: =SUM(mei!Q22, jun!Q22, jul!Q22, aug!Q22, sep!Q22, okt!Q22) -> 0 | R23: =SUM(mei!R22, jun!R22, jul!R22, aug!R22, sep!R22, okt!R22) -> 0 | S23: =SUM(mei!S22, jun!S22, jul!S22, aug!S22, sep!S22, okt!S22) -> 0 | T23: =SUM(mei!T22, jun!T22, jul!T22, aug!T22, sep!T22, okt!T22) -> 0 | U23: =SUM(mei!U22, jun!U22, jul!U22, aug!U22, sep!U22, okt!U22) -> 0 | V23: =SUM(mei!V22, jun!V22, jul!V22, aug!V22, sep!V22, okt!V22) -> 0
A24: 36 | B24: =SUM(mei!D23, jun!D23, jul!D23, aug!D23, sep!D23, okt!D23) -> 0 | C24: =SUM(mei!E23, jun!E23, jul!E23, aug!E23, sep!E23, okt!E23) -> 0 | D24: =SUM(mei!F23, jun!F23, jul!F23, aug!F23, sep!F23, okt!F23) -> 1 | E24: =SUM(mei!G23, jun!G23, jul!G23, aug!G23, sep!G23, okt!G23) -> 37 | F24: =SUM(mei!H23, jun!H23, jul!H23, aug!H23, sep!H23, okt!H23) -> 181 | G24: =SUM(mei!I23, jun!I23, jul!I23, aug!I23, sep!I23, okt!I23) -> 34 | H24: =SUM(mei!J23, jun!J23, jul!J23, aug!J23, sep!J23, okt!J23) -> 0 | I24: =SUM(mei!K23, jun!K23, jul!K23, aug!K23, sep!K23, okt!K23) -> 0 | ... K24: =SUM(mei!M23, jun!M23, jul!M23, aug!M23, sep!M23, okt!M23) -> 0 | L24: =SUM(N24:V24) -> 0 | N24: =SUM(mei!N23, jun!N23, jul!N23, aug!N23, sep!N23, okt!N23) -> 0 | O24: =SUM(mei!O23, jun!O23, jul!O23, aug!O23, sep!O23, okt!O23) -> 0 | P24: =SUM(mei!P23, jun!P23, jul!P23, aug!P23, sep!P23, okt!P23) -> 0 | Q24: =SUM(mei!Q23, jun!Q23, jul!Q23, aug!Q23, sep!Q23, okt!Q23) -> 0 | R24: =SUM(mei!R23, jun!R23, jul!R23, aug!R23, sep!R23, okt!R23) -> 0 | S24: =SUM(mei!S23, jun!S23, jul!S23, aug!S23, sep!S23, okt!S23) -> 0 | T24: =SUM(mei!T23, jun!T23, jul!T23, aug!T23, sep!T23, okt!T23) -> 0 | U24: =SUM(mei!U23, jun!U23, jul!U23, aug!U23, sep!U23, okt!U23) -> 0 | V24: =SUM(mei!V23, jun!V23, jul!V23, aug!V23, sep!V23, okt!V23) -> 0
A25: 37 | B25: =SUM(mei!D24, jun!D24, jul!D24, aug!D24, sep!D24, okt!D24) -> 0 | C25: =SUM(mei!E24, jun!E24, jul!E24, aug!E24, sep!E24, okt!E24) -> 0 | D25: =SUM(mei!F24, jun!F24, jul!F24, aug!F24, sep!F24, okt!F24) -> 0 | E25: =SUM(mei!G24, jun!G24, jul!G24, aug!G24, sep!G24, okt!G24) -> 6 | F25: =SUM(mei!H24, jun!H24, jul!H24, aug!H24, sep!H24, okt!H24) -> 112 | G25: =SUM(mei!I24, jun!I24, jul!I24, aug!I24, sep!I24, okt!I24) -> 105 | H25: =SUM(mei!J24, jun!J24, jul!J24, aug!J24, sep!J24, okt!J24) -> 5 | I25: =SUM(mei!K24, jun!K24, jul!K24, aug!K24, sep!K24, okt!K24) -> 1 | ... K25: =SUM(mei!M24, jun!M24, jul!M24, aug!M24, sep!M24, okt!M24) -> 0 | L25: =SUM(N25:V25) -> 0 | N25: =SUM(mei!N24, jun!N24, jul!N24, aug!N24, sep!N24, okt!N24) -> 0 | O25: =SUM(mei!O24, jun!O24, jul!O24, aug!O24, sep!O24, okt!O24) -> 0 | P25: =SUM(mei!P24, jun!P24, jul!P24, aug!P24, sep!P24, okt!P24) -> 0 | Q25: =SUM(mei!Q24, jun!Q24, jul!Q24, aug!Q24, sep!Q24, okt!Q24) -> 0 | R25: =SUM(mei!R24, jun!R24, jul!R24, aug!R24, sep!R24, okt!R24) -> 0 | S25: =SUM(mei!S24, jun!S24, jul!S24, aug!S24, sep!S24, okt!S24) -> 0 | T25: =SUM(mei!T24, jun!T24, jul!T24, aug!T24, sep!T24, okt!T24) -> 0 | U25: =SUM(mei!U24, jun!U24, jul!U24, aug!U24, sep!U24, okt!U24) -> 0 | V25: =SUM(mei!V24, jun!V24, jul!V24, aug!V24, sep!V24, okt!V24) -> 0
A26: 38 | B26: =SUM(mei!D25, jun!D25, jul!D25, aug!D25, sep!D25, okt!D25) -> 0 | C26: =SUM(mei!E25, jun!E25, jul!E25, aug!E25, sep!E25, okt!E25) -> 0 | D26: =SUM(mei!F25, jun!F25, jul!F25, aug!F25, sep!F25, okt!F25) -> 0 | E26: =SUM(mei!G25, jun!G25, jul!G25, aug!G25, sep!G25, okt!G25) -> 1 | F26: =SUM(mei!H25, jun!H25, jul!H25, aug!H25, sep!H25, okt!H25) -> 35 | G26: =SUM(mei!I25, jun!I25, jul!I25, aug!I25, sep!I25, okt!I25) -> 143 | H26: =SUM(mei!J25, jun!J25, jul!J25, aug!J25, sep!J25, okt!J25) -> 15 | I26: =SUM(mei!K25, jun!K25, jul!K25, aug!K25, sep!K25, okt!K25) -> 1 | ... K26: =SUM(mei!M25, jun!M25, jul!M25, aug!M25, sep!M25, okt!M25) -> 0 | L26: =SUM(N26:V26) -> 0 | N26: =SUM(mei!N25, jun!N25, jul!N25, aug!N25, sep!N25, okt!N25) -> 0 | O26: =SUM(mei!O25, jun!O25, jul!O25, aug!O25, sep!O25, okt!O25) -> 0 | P26: =SUM(mei!P25, jun!P25, jul!P25, aug!P25, sep!P25, okt!P25) -> 0 | Q26: =SUM(mei!Q25, jun!Q25, jul!Q25, aug!Q25, sep!Q25, okt!Q25) -> 0 | R26: =SUM(mei!R25, jun!R25, jul!R25, aug!R25, sep!R25, okt!R25) -> 0 | S26: =SUM(mei!S25, jun!S25, jul!S25, aug!S25, sep!S25, okt!S25) -> 0 | T26: =SUM(mei!T25, jun!T25, jul!T25, aug!T25, sep!T25, okt!T25) -> 0 | U26: =SUM(mei!U25, jun!U25, jul!U25, aug!U25, sep!U25, okt!U25) -> 0 | V26: =SUM(mei!V25, jun!V25, jul!V25, aug!V25, sep!V25, okt!V25) -> 0
A27: 39 | B27: =SUM(mei!D26, jun!D26, jul!D26, aug!D26, sep!D26, okt!D26) -> 0 | C27: =SUM(mei!E26, jun!E26, jul!E26, aug!E26, sep!E26, okt!E26) -> 0 | D27: =SUM(mei!F26, jun!F26, jul!F26, aug!F26, sep!F26, okt!F26) -> 0 | E27: =SUM(mei!G26, jun!G26, jul!G26, aug!G26, sep!G26, okt!G26) -> 0 | F27: =SUM(mei!H26, jun!H26, jul!H26, aug!H26, sep!H26, okt!H26) -> 4 | G27: =SUM(mei!I26, jun!I26, jul!I26, aug!I26, sep!I26, okt!I26) -> 137 | H27: =SUM(mei!J26, jun!J26, jul!J26, aug!J26, sep!J26, okt!J26) -> 89 | I27: =SUM(mei!K26, jun!K26, jul!K26, aug!K26, sep!K26, okt!K26) -> 7 | ... K27: =SUM(mei!M26, jun!M26, jul!M26, aug!M26, sep!M26, okt!M26) -> 0 | L27: =SUM(N27:V27) -> 0 | N27: =SUM(mei!N26, jun!N26, jul!N26, aug!N26, sep!N26, okt!N26) -> 0 | O27: =SUM(mei!O26, jun!O26, jul!O26, aug!O26, sep!O26, okt!O26) -> 0 | P27: =SUM(mei!P26, jun!P26, jul!P26, aug!P26, sep!P26, okt!P26) -> 0 | Q27: =SUM(mei!Q26, jun!Q26, jul!Q26, aug!Q26, sep!Q26, okt!Q26) -> 0 | R27: =SUM(mei!R26, jun!R26, jul!R26, aug!R26, sep!R26, okt!R26) -> 0 | S27: =SUM(mei!S26, jun!S26, jul!S26, aug!S26, sep!S26, okt!S26) -> 0 | T27: =SUM(mei!T26, jun!T26, jul!T26, aug!T26, sep!T26, okt!T26) -> 0 | U27: =SUM(mei!U26, jun!U26, jul!U26, aug!U26, sep!U26, okt!U26) -> 0 | V27: =SUM(mei!V26, jun!V26, jul!V26, aug!V26, sep!V26, okt!V26) -> 0
... A43: 55 | B43: =SUM(mei!D42, jun!D42, jul!D42, aug!D42, sep!D42, okt!D42) -> 0 | C43: =SUM(mei!E42, jun!E42, jul!E42, aug!E42, sep!E42, okt!E42) -> 0 | D43: =SUM(mei!F42, jun!F42, jul!F42, aug!F42, sep!F42, okt!F42) -> 0 | E43: =SUM(mei!G42, jun!G42, jul!G42, aug!G42, sep!G42, okt!G42) -> 0 | F43: =SUM(mei!H42, jun!H42, jul!H42, aug!H42, sep!H42, okt!H42) -> 0 | G43: =SUM(mei!I42, jun!I42, jul!I42, aug!I42, sep!I42, okt!I42) -> 0 | H43: =SUM(mei!J42, jun!J42, jul!J42, aug!J42, sep!J42, okt!J42) -> 0 | I43: =SUM(mei!K42, jun!K42, jul!K42, aug!K42, sep!K42, okt!K42) -> 0 | ... K43: =SUM(mei!M42, jun!M42, jul!M42, aug!M42, sep!M42, okt!M42) -> 0 | L43: =SUM(N43:V43) -> 6 | N43: =SUM(mei!N42, jun!N42, jul!N42, aug!N42, sep!N42, okt!N42) -> 0 | O43: =SUM(mei!O42, jun!O42, jul!O42, aug!O42, sep!O42, okt!O42) -> 0 | P43: =SUM(mei!P42, jun!P42, jul!P42, aug!P42, sep!P42, okt!P42) -> 0 | Q43: =SUM(mei!Q42, jun!Q42, jul!Q42, aug!Q42, sep!Q42, okt!Q42) -> 0 | R43: =SUM(mei!R42, jun!R42, jul!R42, aug!R42, sep!R42, okt!R42) -> 0 | S43: =SUM(mei!S42, jun!S42, jul!S42, aug!S42, sep!S42, okt!S42) -> 6 | T43: =SUM(mei!T42, jun!T42, jul!T42, aug!T42, sep!T42, okt!T42) -> 0 | U43: =SUM(mei!U42, jun!U42, jul!U42, aug!U42, sep!U42, okt!U42) -> 0 | V43: =SUM(mei!V42, jun!V42, jul!V42, aug!V42, sep!V42, okt!V42) -> 0
L45: =SUM(B3:L43) -> 3064

Sheet mei
A2: 15 | B2: 0
A3: 16 | B3: 0
A4: 17 | B4: 0
A5: 18 | B5: 0
A6: 19 | B6: 0
A7: 20 | B7: 0
A8: 21 | B8: 0
A9: 22 | B9: 0
A10: 23 | B10: 0
A11: 24 | B11: 0
A12: 25 | B12: 0
A13: 26 | B13: 0 | C13: MAY 2014
A14: 27 | B14: 0 | C14: cm / Age | D14: II | E14: III | F14: IV | G14: V | H14: VI | I14: VII | J14: VIII | K14: IX | L14: X | M14: XI | N14: XII | O14: XIII | P14: XIV | Q14: XV | R14: XVI | S14: XVII | T14: XVIII | U14: XIX | V14: XX | W14: total | X14: II | Y14: III | Z14: IV | AA14: V | AB14: VI | AC14: VII | AD14: VIII | AE14: IX | AF14: X | AG14: XI | AH14: XII | AI14: XIII | AJ14: XIV | AK14: XV | AL14: XVI | AM14: XVII | AN14: XVIII | AO14: XIX | AP14: XX
A15: 28 | B15: 10.881684 | C15: 28 | E15: 4 | F15: 1 | W15: =SUM(E15:V15) -> 5 | X15: =D15/$W15*$B15 -> 0 | Y15: =E15/$W15*$B15 -> 8.7053471 | Z15: =F15/$W15*$B15 -> 2.1763368 | AA15: =G15/$W15*$B15 -> 0 | AB15: =H15/$W15*$B15 -> 0 | AC15: =I15/$W15*$B15 -> 0 | AD15: =J15/$W15*$B15 -> 0 | AE15: =K15/$W15*$B15 -> 0 | ... AP15: =V15/$W15*$B15 -> 0 | AQ15: =SUM(X15:AP15) -> 10.881684
A16: 29 | B16: 19.809139 | C16: 29 | E16: 5 | F16: 1 | H16: 1 | W16: =SUM(E16:V16) -> 7 | X16: =D16/$W16*$B16 -> 0 | Y16: =E16/$W16*$B16 -> 14.149385 | Z16: =F16/$W16*$B16 -> 2.829877 | AA16: =G16/$W16*$B16 -> 0 | AB16: =H16/$W16*$B16 -> 2.829877 | AC16: =I16/$W16*$B16 -> 0 | AD16: =J16/$W16*$B16 -> 0 | AE16: =K16/$W16*$B16 -> 0 | ... AP16: =V16/$W16*$B16 -> 0 | AQ16: =SUM(X16:AP16) -> 19.809139
A17: 30 | B17: 13.730814 | C17: 30 | E17: 1 | F17: 4 | W17: =SUM(E17:V17) -> 5 | X17: =D17/$W17*$B17 -> 0 | Y17: =E17/$W17*$B17 -> 2.7461629 | Z17: =F17/$W17*$B17 -> 10.984652 | AA17: =G17/$W17*$B17 -> 0 | AB17: =H17/$W17*$B17 -> 0 | AC17: =I17/$W17*$B17 -> 0 | AD17: =J17/$W17*$B17 -> 0 | AE17: =K17/$W17*$B17 -> 0 | ... AP17: =V17/$W17*$B17 -> 0 | AQ17: =SUM(X17:AP17) -> 13.730814
A18: 31 | B18: 1.7116347 | C18: 31 | F18: 2 | W18: =SUM(E18:V18) -> 2 | X18: =D18/$W18*$B18 -> 0 | Y18: =E18/$W18*$B18 -> 0 | Z18: =F18/$W18*$B18 -> 1.7116347 | AA18: =G18/$W18*$B18 -> 0 | AB18: =H18/$W18*$B18 -> 0 | AC18: =I18/$W18*$B18 -> 0 | AD18: =J18/$W18*$B18 -> 0 | AE18: =K18/$W18*$B18 -> 0 | ... AP18: =V18/$W18*$B18 -> 0 | AQ18: =SUM(X18:AP18) -> 1.7116347
A19: 32 | B19: 34.300081 | C19: 32 | F19: 9 | W19: =SUM(E19:V19) -> 9 | X19: =D19/$W19*$B19 -> 0 | Y19: =E19/$W19*$B19 -> 0 | Z19: =F19/$W19*$B19 -> 34.300081 | AA19: =G19/$W19*$B19 -> 0 | AB19: =H19/$W19*$B19 -> 0 | AC19: =I19/$W19*$B19 -> 0 | AD19: =J19/$W19*$B19 -> 0 | AE19: =K19/$W19*$B19 -> 0 | ... AP19: =V19/$W19*$B19 -> 0 | AQ19: =SUM(X19:AP19) -> 34.300081
A20: 33 | B20: 247.10075 | C20: 33 | F20: 11 | G20: 17 | W20: =SUM(E20:V20) -> 28 | X20: =D20/$W20*$B20 -> 0 | Y20: =E20/$W20*$B20 -> 0 | Z20: =F20/$W20*$B20 -> 97.075294 | AA20: =G20/$W20*$B20 -> 150.02545 | AB20: =H20/$W20*$B20 -> 0 | AC20: =I20/$W20*$B20 -> 0 | AD20: =J20/$W20*$B20 -> 0 | AE20: =K20/$W20*$B20 -> 0 | ... AP20: =V20/$W20*$B20 -> 0 | AQ20: =SUM(X20:AP20) -> 247.10075
A21: 34 | B21: 326.29148 | C21: 34 | F21: 1 | G21: 38 | H21: 4 | W21: =SUM(E21:V21) -> 43 | X21: =D21/$W21*$B21 -> 0 | Y21: =E21/$W21*$B21 -> 0 | Z21: =F21/$W21*$B21 -> 7.588174 | AA21: =G21/$W21*$B21 -> 288.35061 | AB21: =H21/$W21*$B21 -> 30.352696 | AC21: =I21/$W21*$B21 -> 0 | AD21: =J21/$W21*$B21 -> 0 | AE21: =K21/$W21*$B21 -> 0 | ... AP21: =V21/$W21*$B21 -> 0 | AQ21: =SUM(X21:AP21) -> 326.29148
A22: 35 | B22: 475.84523 | C22: 35 | G22: 18 | H22: 31 | W22: =SUM(E22:V22) -> 49 | X22: =D22/$W22*$B22 -> 0 | Y22: =E22/$W22*$B22 -> 0 | Z22: =F22/$W22*$B22 -> 0 | AA22: =G22/$W22*$B22 -> 174.80029 | AB22: =H22/$W22*$B22 -> 301.04494 | AC22: =I22/$W22*$B22 -> 0 | AD22: =J22/$W22*$B22 -> 0 | AE22: =K22/$W22*$B22 -> 0 | ... AP22: =V22/$W22*$B22 -> 0 | AQ22: =SUM(X22:AP22) -> 475.84523
A23: 36 | B23: 648.7392 | C23: 36 | F23: 1 | G23: 11 | H23: 69 | I23: 7 | W23: =SUM(E23:V23) -> 88 | X23: =D23/$W23*$B23 -> 0 | Y23: =E23/$W23*$B23 -> 0 | Z23: =F23/$W23*$B23 -> 7.3720364 | AA23: =G23/$W23*$B23 -> 81.0924 | AB23: =H23/$W23*$B23 -> 508.67051 | AC23: =I23/$W23*$B23 -> 51.604255 | AD23: =J23/$W23*$B23 -> 0 | AE23: =K23/$W23*$B23 -> 0 | ... AP23: =V23/$W23*$B23 -> 0 | AQ23: =SUM(X23:AP23) -> 648.7392
A24: 37 | B24: 551.31619 | C24: 37 | G24: 2 | H24: 33 | I24: 43 | J24: 1 | K24: 1 | W24: =SUM(E24:V24) -> 80 | X24: =D24/$W24*$B24 -> 0 | Y24: =E24/$W24*$B24 -> 0 | Z24: =F24/$W24*$B24 -> 0 | AA24: =G24/$W24*$B24 -> 13.782905 | AB24: =H24/$W24*$B24 -> 227.41793 | AC24: =I24/$W24*$B24 -> 296.33245 | AD24: =J24/$W24*$B24 -> 6.8914523 | AE24: =K24/$W24*$B24 -> 6.8914523 | ... AP24: =V24/$W24*$B24 -> 0 | AQ24: =SUM(X24:AP24) -> 551.31619
A25: 38 | B25: 374.92617 | C25: 38 | H25: 12 | I25: 55 | J25: 9 | W25: =SUM(E25:V25) -> 76 | X25: =D25/$W25*$B25 -> 0 | Y25: =E25/$W25*$B25 -> 0 | Z25: =F25/$W25*$B25 -> 0 | AA25: =G25/$W25*$B25 -> 0 | AB25: =H25/$W25*$B25 -> 59.198869 | AC25: =I25/$W25*$B25 -> 271.32815 | AD25: =J25/$W25*$B25 -> 44.399151 | AE25: =K25/$W25*$B25 -> 0 | ... AP25: =V25/$W25*$B25 -> 0 | AQ25: =SUM(X25:AP25) -> 374.92617
A26: 39 | B26: 269.99353 | C26: 39 | I26: 30 | J26: 24 | K26: 2 | W26: =SUM(E26:V26) -> 56 | X26: =D26/$W26*$B26 -> 0 | Y26: =E26/$W26*$B26 -> 0 | Z26: =F26/$W26*$B26 -> 0 | AA26: =G26/$W26*$B26 -> 0 | AB26: =H26/$W26*$B26 -> 0 | AC26: =I26/$W26*$B26 -> 144.63939 | AD26: =J26/$W26*$B26 -> 115.71151 | AE26: =K26/$W26*$B26 -> 9.6426259 | ... AP26: =V26/$W26*$B26 -> 0 | AQ26: =SUM(X26:AP26) -> 269.99353
A27: 40 | B27: 178.28764 | C27: 40 | I27: 15 | J27: 35 | K27: 3 | W27: =SUM(E27:V27) -> 53 | X27: =D27/$W27*$B27 -> 0 | Y27: =E27/$W27*$B27 -> 0 | Z27: =F27/$W27*$B27 -> 0 | AA27: =G27/$W27*$B27 -> 0 | AB27: =H27/$W27*$B27 -> 0 | AC27: =I27/$W27*$B27 -> 50.458767 | AD27: =J27/$W27*$B27 -> 117.73712 | AE27: =K27/$W27*$B27 -> 10.091753 | ... AP27: =V27/$W27*$B27 -> 0 | AQ27: =SUM(X27:AP27) -> 178.28764
A28: 41 | B28: 145.95796 | C28: 41 | I28: 2 | J28: 11 | K28: 21 | L28: 2 | W28: =SUM(E28:V28) -> 36 | X28: =D28/$W28*$B28 -> 0 | Y28: =E28/$W28*$B28 -> 0 | Z28: =F28/$W28*$B28 -> 0 | AA28: =G28/$W28*$B28 -> 0 | AB28: =H28/$W28*$B28 -> 0 | AC28: =I28/$W28*$B28 -> 8.1087758 | AD28: =J28/$W28*$B28 -> 44.598267 | AE28: =K28/$W28*$B28 -> 85.142146 | ... AP28: =V28/$W28*$B28 -> 0 | AQ28: =SUM(X28:AP28) -> 145.95796
A29: 42 | B29: 103.45551 | C29: 42 | I29: 1 | J29: 11 | K29: 21 | L29: 4 | M29: 2 | W29: =SUM(E29:V29) -> 39 | X29: =D29/$W29*$B29 -> 0 | Y29: =E29/$W29*$B29 -> 0 | Z29: =F29/$W29*$B29 -> 0 | AA29: =G29/$W29*$B29 -> 0 | AB29: =H29/$W29*$B29 -> 0 | AC29: =I29/$W29*$B29 -> 2.6527055 | AD29: =J29/$W29*$B29 -> 29.17976 | AE29: =K29/$W29*$B29 -> 55.706815 | ... AP29: =V29/$W29*$B29 -> 0 | AQ29: =SUM(X29:AP29) -> 103.45551
A30: 43 | B30: 79.489933 | C30: 43 | J30: 3 | K30: 15 | L30: 11 | M30: 1 | N30: 1 | W30: =SUM(E30:V30) -> 31 | X30: =D30/$W30*$B30 -> 0 | Y30: =E30/$W30*$B30 -> 0 | Z30: =F30/$W30*$B30 -> 0 | AA30: =G30/$W30*$B30 -> 0 | AB30: =H30/$W30*$B30 -> 0 | AC30: =I30/$W30*$B30 -> 0 | AD30: =J30/$W30*$B30 -> 7.6925741 | AE30: =K30/$W30*$B30 -> 38.462871 | ... AP30: =V30/$W30*$B30 -> 0 | AQ30: =SUM(X30:AP30) -> 79.489933
A31: 44 | B31: 85.864761 | C31: 44 | J31: 1 | K31: 9 | L31: 13 | M31: 9 | N31: 1 | W31: =SUM(E31:V31) -> 33 | X31: =D31/$W31*$B31 -> 0 | Y31: =E31/$W31*$B31 -> 0 | Z31: =F31/$W31*$B31 -> 0 | AA31: =G31/$W31*$B31 -> 0 | AB31: =H31/$W31*$B31 -> 0 | AC31: =I31/$W31*$B31 -> 0 | AD31: =J31/$W31*$B31 -> 2.6019625 | AE31: =K31/$W31*$B31 -> 23.417662 | ... AP31: =V31/$W31*$B31 -> 0 | AQ31: =SUM(X31:AP31) -> 85.864761
A32: 45 | B32: 81.266259 | C32: 45 | L32: 4 | M32: 9 | N32: 13 | O32: 1 | P32: 1 | R32: 1 | W32: =SUM(E32:V32) -> 29 | X32: =D32/$W32*$B32 -> 0 | Y32: =E32/$W32*$B32 -> 0 | Z32: =F32/$W32*$B32 -> 0 | AA32: =G32/$W32*$B32 -> 0 | AB32: =H32/$W32*$B32 -> 0 | AC32: =I32/$W32*$B32 -> 0 | AD32: =J32/$W32*$B32 -> 0 | AE32: =K32/$W32*$B32 -> 0 | ... AP32: =V32/$W32*$B32 -> 0 | AQ32: =SUM(X32:AP32) -> 81.266259
A33: 46 | B33: 60.51909 | C33: 46 | L33: 1 | M33: 2 | N33: 2 | O33: 6 | P33: 2 | Q33: 1 | R33: 1 | W33: =SUM(E33:V33) -> 15 | X33: =D33/$W33*$B33 -> 0 | Y33: =E33/$W33*$B33 -> 0 | Z33: =F33/$W33*$B33 -> 0 | AA33: =G33/$W33*$B33 -> 0 | AB33: =H33/$W33*$B33 -> 0 | AC33: =I33/$W33*$B33 -> 0 | AD33: =J33/$W33*$B33 -> 0 | AE33: =K33/$W33*$B33 -> 0 | ... AP33: =V33/$W33*$B33 -> 0 | AQ33: =SUM(X33:AP33) -> 60.51909
A34: 47 | B34: 28.798591 | C34: 47 | N34: 3 | O34: 4 | P34: 1 | W34: =SUM(E34:V34) -> 8 | X34: =D34/$W34*$B34 -> 0 | Y34: =E34/$W34*$B34 -> 0 | Z34: =F34/$W34*$B34 -> 0 | AA34: =G34/$W34*$B34 -> 0 | AB34: =H34/$W34*$B34 -> 0 | AC34: =I34/$W34*$B34 -> 0 | AD34: =J34/$W34*$B34 -> 0 | AE34: =K34/$W34*$B34 -> 0 | ... AP34: =V34/$W34*$B34 -> 0 | AQ34: =SUM(X34:AP34) -> 28.798591
A35: 48 | B35: 32.836431 | C35: 48 | M35: 1 | O35: 2 | P35: 1 | Q35: 3 | R35: 2 | S35: 1 | W35: =SUM(E35:V35) -> 10 | X35: =D35/$W35*$B35 -> 0 | Y35: =E35/$W35*$B35 -> 0 | Z35: =F35/$W35*$B35 -> 0 | AA35: =G35/$W35*$B35 -> 0 | AB35: =H35/$W35*$B35 -> 0 | AC35: =I35/$W35*$B35 -> 0 | AD35: =J35/$W35*$B35 -> 0 | AE35: =K35/$W35*$B35 -> 0 | ... AP35: =V35/$W35*$B35 -> 0 | AQ35: =SUM(X35:AP35) -> 32.836431
A36: 49 | B36: 5.8788587 | C36: 49 | R36: 2 | S36: 2 | W36: =SUM(E36:V36) -> 4 | X36: =D36/$W36*$B36 -> 0 | Y36: =E36/$W36*$B36 -> 0 | Z36: =F36/$W36*$B36 -> 0 | AA36: =G36/$W36*$B36 -> 0 | AB36: =H36/$W36*$B36 -> 0 | AC36: =I36/$W36*$B36 -> 0 | AD36: =J36/$W36*$B36 -> 0 | AE36: =K36/$W36*$B36 -> 0 | ... AP36: =V36/$W36*$B36 -> 0 | AQ36: =SUM(X36:AP36) -> 5.8788587
A37: 50 | B37: 7.5527566 | C37: 50 | Q37: 2 | R37: 1 | W37: =SUM(E37:V37) -> 3 | X37: =D37/$W37*$B37 -> 0 | Y37: =E37/$W37*$B37 -> 0 | Z37: =F37/$W37*$B37 -> 0 | AA37: =G37/$W37*$B37 -> 0 | AB37: =H37/$W37*$B37 -> 0 | AC37: =I37/$W37*$B37 -> 0 | AD37: =J37/$W37*$B37 -> 0 | AE37: =K37/$W37*$B37 -> 0 | ... AP37: =V37/$W37*$B37 -> 0 | AQ37: =SUM(X37:AP37) -> 7.5527566
A38: 51 | B38: 4.3073894 | C38: 51 | Q38: 1 | S38: 1 | W38: =SUM(E38:V38) -> 2 | X38: =D38/$W38*$B38 -> 0 | Y38: =E38/$W38*$B38 -> 0 | Z38: =F38/$W38*$B38 -> 0 | AA38: =G38/$W38*$B38 -> 0 | AB38: =H38/$W38*$B38 -> 0 | AC38: =I38/$W38*$B38 -> 0 | AD38: =J38/$W38*$B38 -> 0 | AE38: =K38/$W38*$B38 -> 0 | ... AP38: =V38/$W38*$B38 -> 0 | AQ38: =SUM(X38:AP38) -> 4.3073894
A39: 52 | B39: 0.23181194 | C39: 52 | S39: 1 | W39: =SUM(E39:V39) -> 1 | X39: =D39/$W39*$B39 -> 0 | Y39: =E39/$W39*$B39 -> 0 | Z39: =F39/$W39*$B39 -> 0 | AA39: =G39/$W39*$B39 -> 0 | AB39: =H39/$W39*$B39 -> 0 | AC39: =I39/$W39*$B39 -> 0 | AD39: =J39/$W39*$B39 -> 0 | AE39: =K39/$W39*$B39 -> 0 | ... AP39: =V39/$W39*$B39 -> 0 | AQ39: =SUM(X39:AP39) -> 0.23181194
A40: 53 | B40: 1.6954618 | C40: 53 | Q40: 2 | W40: 2 | X40: =D40/$W40*$B40 -> 0 | Y40: =E40/$W40*$B40 -> 0 | Z40: =F40/$W40*$B40 -> 0 | AA40: =G40/$W40*$B40 -> 0 | AB40: =H40/$W40*$B40 -> 0 | AC40: =I40/$W40*$B40 -> 0 | AD40: =J40/$W40*$B40 -> 0 | AE40: =K40/$W40*$B40 -> 0 | ... AP40: =V40/$W40*$B40 -> 0 | AQ40: =SUM(X40:AP40) -> 1.6954618
A41: 54 | B41: 0.23181194 | C41: 54 | V41: 1 | W41: =SUM(E41:V41) -> 1 | X41: =D41/$W41*$B41 -> 0 | Y41: =E41/$W41*$B41 -> 0 | Z41: =F41/$W41*$B41 -> 0 | AA41: =G41/$W41*$B41 -> 0 | AB41: =H41/$W41*$B41 -> 0 | AC41: =I41/$W41*$B41 -> 0 | AD41: =J41/$W41*$B41 -> 0 | AE41: =K41/$W41*$B41 -> 0 | ... AP41: =V41/$W41*$B41 -> 0.23181194 | AQ41: =SUM(X41:AP41) -> 0.23181194
...

Sheet jun
A2: 15 | B2: 0
A3: 16 | B3: 0
A4: 17 | B4: 0
A5: 18 | B5: 0
A6: 19 | B6: 0
A7: 20 | B7: 0
A8: 21 | B8: 0
A9: 22 | B9: 0
A10: 23 | B10: 0
A11: 24 | B11: 0
A12: 25 | B12: 0
A13: 26 | B13: 0 | C13: JUNE 2014
A14: 27 | B14: 0 | C14: cm / Age | D14: II | E14: III | F14: IV | G14: V | H14: VI | I14: VII | J14: VIII | K14: IX | L14: X | M14: XI | N14: XII | O14: XIII | P14: XIV | Q14: XV | R14: XVI | S14: XVII | T14: XVIII | U14: XIX | V14: XX | W14: total | X14: II | Y14: III | Z14: IV | AA14: V | AB14: VI | AC14: VII | AD14: VIII | AE14: IX | AF14: X | AG14: XI | AH14: XII | AI14: XIII | AJ14: XIV | AK14: XV | AL14: XVI | AM14: XVII | AN14: XVIII | AO14: XIX | AP14: XX
A15: 28 | B15: 2.7137509 | C15: 28 | E15: 1 | W15: =SUM(E15:V15) -> 1 | X15: =D15/$W15*$B15 -> 0 | Y15: =E15/$W15*$B15 -> 2.7137509 | Z15: =F15/$W15*$B15 -> 0 | AA15: =G15/$W15*$B15 -> 0 | AB15: =H15/$W15*$B15 -> 0 | AC15: =I15/$W15*$B15 -> 0 | AD15: =J15/$W15*$B15 -> 0 | AE15: =K15/$W15*$B15 -> 0 | ... AP15: =V15/$W15*$B15 -> 0 | AQ15: =SUM(X15:AP15) -> 2.7137509
A16: 29 | B16: 38.879701 | C16: 29 | E16: 5 | F16: 4 | W16: =SUM(E16:V16) -> 9 | X16: =D16/$W16*$B16 -> 0 | Y16: =E16/$W16*$B16 -> 21.599834 | Z16: =F16/$W16*$B16 -> 17.279867 | AA16: =G16/$W16*$B16 -> 0 | AB16: =H16/$W16*$B16 -> 0 | AC16: =I16/$W16*$B16 -> 0 | AD16: =J16/$W16*$B16 -> 0 | AE16: =K16/$W16*$B16 -> 0 | ... AP16: =V16/$W16*$B16 -> 0 | AQ16: =SUM(X16:AP16) -> 38.879701
A17: 30 | B17: 47.102639 | C17: 30 | E17: 6 | F17: 4 | W17: =SUM(E17:V17) -> 10 | X17: =D17/$W17*$B17 -> 0 | Y17: =E17/$W17*$B17 -> 28.261583 | Z17: =F17/$W17*$B17 -> 18.841055 | AA17: =G17/$W17*$B17 -> 0 | AB17: =H17/$W17*$B17 -> 0 | AC17: =I17/$W17*$B17 -> 0 | AD17: =J17/$W17*$B17 -> 0 | AE17: =K17/$W17*$B17 -> 0 | ... AP17: =V17/$W17*$B17 -> 0 | AQ17: =SUM(X17:AP17) -> 47.102639
A18: 31 | B18: 18.900958 | C18: 31 | F18: 4 | W18: =SUM(E18:V18) -> 4 | X18: =D18/$W18*$B18 -> 0 | Y18: =E18/$W18*$B18 -> 0 | Z18: =F18/$W18*$B18 -> 18.900958 | AA18: =G18/$W18*$B18 -> 0 | AB18: =H18/$W18*$B18 -> 0 | AC18: =I18/$W18*$B18 -> 0 | AD18: =J18/$W18*$B18 -> 0 | AE18: =K18/$W18*$B18 -> 0 | ... AP18: =V18/$W18*$B18 -> 0 | AQ18: =SUM(X18:AP18) -> 18.900958
A19: 32 | B19: 31.153679 | C19: 32 | F19: 3 | G19: 2 | W19: =SUM(E19:V19) -> 5 | X19: =D19/$W19*$B19 -> 0 | Y19: =E19/$W19*$B19 -> 0 | Z19: =F19/$W19*$B19 -> 18.692208 | AA19: =G19/$W19*$B19 -> 12.461472 | AB19: =H19/$W19*$B19 -> 0 | AC19: =I19/$W19*$B19 -> 0 | AD19: =J19/$W19*$B19 -> 0 | AE19: =K19/$W19*$B19 -> 0 | ... AP19: =V19/$W19*$B19 -> 0 | AQ19: =SUM(X19:AP19) -> 31.153679
A20: 33 | B20: 394.41965 | C20: 33 | E20: 1 | F20: 4 | G20: 16 | W20: =SUM(E20:V20) -> 21 | X20: =D20/$W20*$B20 -> 0 | Y20: =E20/$W20*$B20 -> 18.781888 | Z20: =F20/$W20*$B20 -> 75.127552 | AA20: =G20/$W20*$B20 -> 300.51021 | AB20: =H20/$W20*$B20 -> 0 | AC20: =I20/$W20*$B20 -> 0 | AD20: =J20/$W20*$B20 -> 0 | AE20: =K20/$W20*$B20 -> 0 | ... AP20: =V20/$W20*$B20 -> 0 | AQ20: =SUM(X20:AP20) -> 394.41965
A21: 34 | B21: 813.34247 | C21: 34 | F21: 5 | G21: 35 | H21: 4 | I21: 1 | W21: =SUM(E21:V21) -> 45 | X21: =D21/$W21*$B21 -> 0 | Y21: =E21/$W21*$B21 -> 0 | Z21: =F21/$W21*$B21 -> 90.371386 | AA21: =G21/$W21*$B21 -> 632.5997 | AB21: =H21/$W21*$B21 -> 72.297109 | AC21: =I21/$W21*$B21 -> 18.074277 | AD21: =J21/$W21*$B21 -> 0 | AE21: =K21/$W21*$B21 -> 0 | ... AP21: =V21/$W21*$B21 -> 0 | AQ21: =SUM(X21:AP21) -> 813.34247
A22: 35 | B22: 1043.0424 | C22: 35 | G22: 23 | H22: 16 | I22: 2 | W22: =SUM(E22:V22) -> 41 | X22: =D22/$W22*$B22 -> 0 | Y22: =E22/$W22*$B22 -> 0 | Z22: =F22/$W22*$B22 -> 0 | AA22: =G22/$W22*$B22 -> 585.12136 | AB22: =H22/$W22*$B22 -> 407.04095 | AC22: =I22/$W22*$B22 -> 50.880118 | AD22: =J22/$W22*$B22 -> 0 | AE22: =K22/$W22*$B22 -> 0 | ... AP22: =V22/$W22*$B22 -> 0 | AQ22: =SUM(X22:AP22) -> 1043.0424
A23: 36 | B23: 1592.0143 | C23: 36 | G23: 8 | H23: 60 | I23: 8 | W23: =SUM(E23:V23) -> 76 | X23: =D23/$W23*$B23 -> 0 | Y23: =E23/$W23*$B23 -> 0 | Z23: =F23/$W23*$B23 -> 0 | AA23: =G23/$W23*$B23 -> 167.58045 | AB23: =H23/$W23*$B23 -> 1256.8534 | AC23: =I23/$W23*$B23 -> 167.58045 | AD23: =J23/$W23*$B23 -> 0 | AE23: =K23/$W23*$B23 -> 0 | ... AP23: =V23/$W23*$B23 -> 0 | AQ23: =SUM(X23:AP23) -> 1592.0143
A24: 37 | B24: 1583.2831 | C24: 37 | G24: 2 | H24: 35 | I24: 30 | J24: 3 | W24: =SUM(E24:V24) -> 70 | X24: =D24/$W24*$B24 -> 0 | Y24: =E24/$W24*$B24 -> 0 | Z24: =F24/$W24*$B24 -> 0 | AA24: =G24/$W24*$B24 -> 45.236659 | AB24: =H24/$W24*$B24 -> 791.64154 | AC24: =I24/$W24*$B24 -> 678.54989 | AD24: =J24/$W24*$B24 -> 67.854989 | AE24: =K24/$W24*$B24 -> 0 | ... AP24: =V24/$W24*$B24 -> 0 | AQ24: =SUM(X24:AP24) -> 1583.2831
A25: 38 | B25: 1147.8168 | C25: 38 | H25: 8 | I25: 55 | J25: 4 | K25: 1 | W25: =SUM(E25:V25) -> 68 | X25: =D25/$W25*$B25 -> 0 | Y25: =E25/$W25*$B25 -> 0 | Z25: =F25/$W25*$B25 -> 0 | AA25: =G25/$W25*$B25 -> 0 | AB25: =H25/$W25*$B25 -> 135.03727 | AC25: =I25/$W25*$B25 -> 928.38125 | AD25: =J25/$W25*$B25 -> 67.518636 | AE25: =K25/$W25*$B25 -> 16.879659 | ... AP25: =V25/$W25*$B25 -> 0 | AQ25: =SUM(X25:AP25) -> 1147.8168
A26: 39 | B26: 903.71991 | C26: 39 | H26: 4 | I26: 39 | J26: 9 | K26: 1 | W26: =SUM(E26:V26) -> 53 | X26: =D26/$W26*$B26 -> 0 | Y26: =E26/$W26*$B26 -> 0 | Z26: =F26/$W26*$B26 -> 0 | AA26: =G26/$W26*$B26 -> 0 | AB26: =H26/$W26*$B26 -> 68.205276 | AC26: =I26/$W26*$B26 -> 665.00144 | AD26: =J26/$W26*$B26 -> 153.46187 | AE26: =K26/$W26*$B26 -> 17.051319 | ... AP26: =V26/$W26*$B26 -> 0 | AQ26: =SUM(X26:AP26) -> 903.71991
A27: 40 | B27: 695.22396 | C27: 40 | H27: 1 | I27: 17 | J27: 25 | K27: 2 | W27: =SUM(E27:V27) -> 45 | X27: =D27/$W27*$B27 -> 0 | Y27: =E27/$W27*$B27 -> 0 | Z27: =F27/$W27*$B27 -> 0 | AA27: =G27/$W27*$B27 -> 0 | AB27: =H27/$W27*$B27 -> 15.449421 | AC27: =I27/$W27*$B27 -> 262.64016 | AD27: =J27/$W27*$B27 -> 386.23554 | AE27: =K27/$W27*$B27 -> 30.898843 | ... AP27: =V27/$W27*$B27 -> 0 | AQ27: =SUM(X27:AP27) -> 695.22396
A28: 41 | B28: 492.38923 | C28: 41 | I28: 6 | J28: 22 | K28: 8 | L28: 1 | W28: =SUM(E28:V28) -> 37 | X28: =D28/$W28*$B28 -> 0 | Y28: =E28/$W28*$B28 -> 0 | Z28: =F28/$W28*$B28 -> 0 | AA28: =G28/$W28*$B28 -> 0 | AB28: =H28/$W28*$B28 -> 0 | AC28: =I28/$W28*$B28 -> 79.846903 | AD28: =J28/$W28*$B28 -> 292.77198 | AE28: =K28/$W28*$B28 -> 106.46254 | ... AP28: =V28/$W28*$B28 -> 0 | AQ28: =SUM(X28:AP28) -> 492.38923
A29: 42 | B29: 344.95496 | C29: 42 | J29: 11 | K29: 6 | W29: =SUM(E29:V29) -> 17 | X29: =D29/$W29*$B29 -> 0 | Y29: =E29/$W29*$B29 -> 0 | Z29: =F29/$W29*$B29 -> 0 | AA29: =G29/$W29*$B29 -> 0 | AB29: =H29/$W29*$B29 -> 0 | AC29: =I29/$W29*$B29 -> 0 | AD29: =J29/$W29*$B29 -> 223.20615 | AE29: =K29/$W29*$B29 -> 121.74881 | ... AP29: =V29/$W29*$B29 -> 0 | AQ29: =SUM(X29:AP29) -> 344.95496
A30: 43 | B30: 291.08382 | C30: 43 | K30: 14 | L30: 8 | M30: 1 | W30: =SUM(E30:V30) -> 23 | X30: =D30/$W30*$B30 -> 0 | Y30: =E30/$W30*$B30 -> 0 | Z30: =F30/$W30*$B30 -> 0 | AA30: =G30/$W30*$B30 -> 0 | AB30: =H30/$W30*$B30 -> 0 | AC30: =I30/$W30*$B30 -> 0 | AD30: =J30/$W30*$B30 -> 0 | AE30: =K30/$W30*$B30 -> 177.18146 | ... AP30: =V30/$W30*$B30 -> 0 | AQ30: =SUM(X30:AP30) -> 291.08382
A31: 44 | B31: 264.96284 | C31: 44 | K31: 3 | L31: 8 | M31: 3 | W31: =SUM(E31:V31) -> 14 | X31: =D31/$W31*$B31 -> 0 | Y31: =E31/$W31*$B31 -> 0 | Z31: =F31/$W31*$B31 -> 0 | AA31: =G31/$W31*$B31 -> 0 | AB31: =H31/$W31*$B31 -> 0 | AC31: =I31/$W31*$B31 -> 0 | AD31: =J31/$W31*$B31 -> 0 | AE31: =K31/$W31*$B31 -> 56.777751 | ... AP31: =V31/$W31*$B31 -> 0 | AQ31: =SUM(X31:AP31) -> 264.96284
A32: 45 | B32: 205.13552 | C32: 45 | K32: 1 | L32: 5 | M32: 6 | N32: 5 | O32: 1 | R32: 1 | W32: =SUM(E32:V32) -> 19 | X32: =D32/$W32*$B32 -> 0 | Y32: =E32/$W32*$B32 -> 0 | Z32: =F32/$W32*$B32 -> 0 | AA32: =G32/$W32*$B32 -> 0 | AB32: =H32/$W32*$B32 -> 0 | AC32: =I32/$W32*$B32 -> 0 | AD32: =J32/$W32*$B32 -> 0 | AE32: =K32/$W32*$B32 -> 10.796606 | ... AP32: =V32/$W32*$B32 -> 0 | AQ32: =SUM(X32:AP32) -> 205.13552
A33: 46 | B33: 134.67556 | C33: 46 | L33: 1 | M33: 2 | N33: 2 | O33: 2 | W33: =SUM(E33:V33) -> 7 | X33: =D33/$W33*$B33 -> 0 | Y33: =E33/$W33*$B33 -> 0 | Z33: =F33/$W33*$B33 -> 0 | AA33: =G33/$W33*$B33 -> 0 | AB33: =H33/$W33*$B33 -> 0 | AC33: =I33/$W33*$B33 -> 0 | AD33: =J33/$W33*$B33 -> 0 | AE33: =K33/$W33*$B33 -> 0 | ... AP33: =V33/$W33*$B33 -> 0 | AQ33: =SUM(X33:AP33) -> 134.67556
A34: 47 | B34: 126.53204 | C34: 47 | N34: 2 | O34: 1 | R34: 1 | W34: =SUM(E34:V34) -> 4 | X34: =D34/$W34*$B34 -> 0 | Y34: =E34/$W34*$B34 -> 0 | Z34: =F34/$W34*$B34 -> 0 | AA34: =G34/$W34*$B34 -> 0 | AB34: =H34/$W34*$B34 -> 0 | AC34: =I34/$W34*$B34 -> 0 | AD34: =J34/$W34*$B34 -> 0 | AE34: =K34/$W34*$B34 -> 0 | ... AP34: =V34/$W34*$B34 -> 0 | AQ34: =SUM(X34:AP34) -> 126.53204
A35: 48 | B35: 79.277378 | C35: 48 | P35: 1 | Q35: 2 | S35: 1 | W35: =SUM(E35:V35) -> 4 | X35: =D35/$W35*$B35 -> 0 | Y35: =E35/$W35*$B35 -> 0 | Z35: =F35/$W35*$B35 -> 0 | AA35: =G35/$W35*$B35 -> 0 | AB35: =H35/$W35*$B35 -> 0 | AC35: =I35/$W35*$B35 -> 0 | AD35: =J35/$W35*$B35 -> 0 | AE35: =K35/$W35*$B35 -> 0 | ... AP35: =V35/$W35*$B35 -> 0 | AQ35: =SUM(X35:AP35) -> 79.277378
A36: 49 | B36: 22.944356 | C36: 49 | R36: 2 | S36: 2 | W36: =SUM(E36:V36) -> 4 | X36: =D36/$W36*$B36 -> 0 | Y36: =E36/$W36*$B36 -> 0 | Z36: =F36/$W36*$B36 -> 0 | AA36: =G36/$W36*$B36 -> 0 | AB36: =H36/$W36*$B36 -> 0 | AC36: =I36/$W36*$B36 -> 0 | AD36: =J36/$W36*$B36 -> 0 | AE36: =K36/$W36*$B36 -> 0 | ... AP36: =V36/$W36*$B36 -> 0 | AQ36: =SUM(X36:AP36) -> 22.944356
A37: 50 | B37: 27.795526 | C37: 50 | Q37: 2 | R37: 1 | W37: =SUM(E37:V37) -> 3 | X37: =D37/$W37*$B37 -> 0 | Y37: =E37/$W37*$B37 -> 0 | Z37: =F37/$W37*$B37 -> 0 | AA37: =G37/$W37*$B37 -> 0 | AB37: =H37/$W37*$B37 -> 0 | AC37: =I37/$W37*$B37 -> 0 | AD37: =J37/$W37*$B37 -> 0 | AE37: =K37/$W37*$B37 -> 0 | ... AP37: =V37/$W37*$B37 -> 0 | AQ37: =SUM(X37:AP37) -> 27.795526
A38: 51 | B38: 1.9513594 | C38: 51 | Q38: 1 | S38: 1 | W38: =SUM(E38:V38) -> 2 | X38: =D38/$W38*$B38 -> 0 | Y38: =E38/$W38*$B38 -> 0 | Z38: =F38/$W38*$B38 -> 0 | AA38: =G38/$W38*$B38 -> 0 | AB38: =H38/$W38*$B38 -> 0 | AC38: =I38/$W38*$B38 -> 0 | AD38: =J38/$W38*$B38 -> 0 | AE38: =K38/$W38*$B38 -> 0 | ... AP38: =V38/$W38*$B38 -> 0 | AQ38: =SUM(X38:AP38) -> 1.9513594
A39: 52 | B39: 0.24278541 | C39: 52 | S39: 1 | W39: =SUM(E39:V39) -> 1 | X39: =D39/$W39*$B39 -> 0 | Y39: =E39/$W39*$B39 -> 0 | Z39: =F39/$W39*$B39 -> 0 | AA39: =G39/$W39*$B39 -> 0 | AB39: =H39/$W39*$B39 -> 0 | AC39: =I39/$W39*$B39 -> 0 | AD39: =J39/$W39*$B39 -> 0 | AE39: =K39/$W39*$B39 -> 0 | ... AP39: =V39/$W39*$B39 -> 0 | AQ39: =SUM(X39:AP39) -> 0.24278541
A40: 53 | B40: 0 | C40: 53 | Q40: 2 | W40: 2 | X40: =D40/$W40*$B40 -> 0 | Y40: =E40/$W40*$B40 -> 0 | Z40: =F40/$W40*$B40 -> 0 | AA40: =G40/$W40*$B40 -> 0 | AB40: =H40/$W40*$B40 -> 0 | AC40: =I40/$W40*$B40 -> 0 | AD40: =J40/$W40*$B40 -> 0 | AE40: =K40/$W40*$B40 -> 0 | ... AP40: =V40/$W40*$B40 -> 0 | AQ40: =SUM(X40:AP40) -> 0
A41: 54 | B41: 0 | C41: 54 | V41: 1 | W41: =SUM(E41:V41) -> 1 | X41: =D41/$W41*$B41 -> 0 | Y41: =E41/$W41*$B41 -> 0 | Z41: =F41/$W41*$B41 -> 0 | AA41: =G41/$W41*$B41 -> 0 | AB41: =H41/$W41*$B41 -> 0 | AC41: =I41/$W41*$B41 -> 0 | AD41: =J41/$W41*$B41 -> 0 | AE41: =K41/$W41*$B41 -> 0 | ... AP41: =V41/$W41*$B41 -> 0 | AQ41: =SUM(X41:AP41) -> 0
...

Sheet jul
A2: 15 | B2: 0
A3: 16 | B3: 0
A4: 17 | B4: 0
A5: 18 | B5: 0
A6: 19 | B6: 0
A7: 20 | B7: 0
A8: 21 | B8: 0
A9: 22 | B9: 0
A10: 23 | B10: 0
A11: 24 | B11: 0
A12: 25 | B12: 0
A13: 26 | B13: 0 | C13: JULY 2014
A14: 27 | B14: 0 | C14: cm / Age | D14: II | E14: III | F14: IV | G14: V | H14: VI | I14: VII | J14: VIII | K14: IX | L14: X | M14: XI | N14: XII | O14: XIII | P14: XIV | Q14: XV | R14: XVI | S14: XVII | T14: XVIII | U14: XIX | V14: XX | W14: total | X14: II | Y14: III | Z14: IV | AA14: V | AB14: VI | AC14: VII | AD14: VIII | AE14: IX | AF14: X | AG14: XI | AH14: XII | AI14: XIII | AJ14: XIV | AK14: XV | AL14: XVI | AM14: XVII | AN14: XVIII | AO14: XIX | AP14: XX
A15: 28 | B15: 6.6120636 | C15: 28 | E15: 3 | G15: 1 | W15: =SUM(E15:V15) -> 4 | X15: =D15/$W15*$B15 -> 0 | Y15: =E15/$W15*$B15 -> 4.9590477 | Z15: =F15/$W15*$B15 -> 0 | AA15: =G15/$W15*$B15 -> 1.6530159 | AB15: =H15/$W15*$B15 -> 0 | AC15: =I15/$W15*$B15 -> 0 | AD15: =J15/$W15*$B15 -> 0 | AE15: =K15/$W15*$B15 -> 0 | ... AP15: =V15/$W15*$B15 -> 0 | AQ15: =SUM(X15:AP15) -> 6.6120636
A16: 29 | B16: 22.856283 | C16: 29 | E16: 2 | F16: 5 | W16: =SUM(E16:V16) -> 7 | X16: =D16/$W16*$B16 -> 0 | Y16: =E16/$W16*$B16 -> 6.5303665 | Z16: =F16/$W16*$B16 -> 16.325916 | AA16: =G16/$W16*$B16 -> 0 | AB16: =H16/$W16*$B16 -> 0 | AC16: =I16/$W16*$B16 -> 0 | AD16: =J16/$W16*$B16 -> 0 | AE16: =K16/$W16*$B16 -> 0 | ... AP16: =V16/$W16*$B16 -> 0 | AQ16: =SUM(X16:AP16) -> 22.856283
A17: 30 | B17: 42.758641 | C17: 30 | E17: 3 | F17: 6 | W17: =SUM(E17:V17) -> 9 | X17: =D17/$W17*$B17 -> 0 | Y17: =E17/$W17*$B17 -> 14.25288 | Z17: =F17/$W17*$B17 -> 28.505761 | AA17: =G17/$W17*$B17 -> 0 | AB17: =H17/$W17*$B17 -> 0 | AC17: =I17/$W17*$B17 -> 0 | AD17: =J17/$W17*$B17 -> 0 | AE17: =K17/$W17*$B17 -> 0 | ... AP17: =V17/$W17*$B17 -> 0 | AQ17: =SUM(X17:AP17) -> 42.758641
A18: 31 | B18: 13.994511 | C18: 31 | E18: 1 | F18: 2 | W18: =SUM(E18:V18) -> 3 | X18: =D18/$W18*$B18 -> 0 | Y18: =E18/$W18*$B18 -> 4.6648368 | Z18: =F18/$W18*$B18 -> 9.3296737 | AA18: =G18/$W18*$B18 -> 0 | AB18: =H18/$W18*$B18 -> 0 | AC18: =I18/$W18*$B18 -> 0 | AD18: =J18/$W18*$B18 -> 0 | AE18: =K18/$W18*$B18 -> 0 | ... AP18: =V18/$W18*$B18 -> 0 | AQ18: =SUM(X18:AP18) -> 13.994511
A19: 32 | B19: 17.617991 | C19: 32 | F19: 1 | W19: =SUM(E19:V19) -> 1 | X19: =D19/$W19*$B19 -> 0 | Y19: =E19/$W19*$B19 -> 0 | Z19: =F19/$W19*$B19 -> 17.617991 | AA19: =G19/$W19*$B19 -> 0 | AB19: =H19/$W19*$B19 -> 0 | AC19: =I19/$W19*$B19 -> 0 | AD19: =J19/$W19*$B19 -> 0 | AE19: =K19/$W19*$B19 -> 0 | ... AP19: =V19/$W19*$B19 -> 0 | AQ19: =SUM(X19:AP19) -> 17.617991
A20: 33 | B20: 270.93076 | C20: 33 | F20: 2 | G20: 12 | I20: 2 | W20: =SUM(E20:V20) -> 16 | X20: =D20/$W20*$B20 -> 0 | Y20: =E20/$W20*$B20 -> 0 | Z20: =F20/$W20*$B20 -> 33.866345 | AA20: =G20/$W20*$B20 -> 203.19807 | AB20: =H20/$W20*$B20 -> 0 | AC20: =I20/$W20*$B20 -> 33.866345 | AD20: =J20/$W20*$B20 -> 0 | AE20: =K20/$W20*$B20 -> 0 | ... AP20: =V20/$W20*$B20 -> 0 | AQ20: =SUM(X20:AP20) -> 270.93076
A21: 34 | B21: 678.97874 | C21: 34 | F21: 2 | G21: 35 | H21: 3 | W21: =SUM(E21:V21) -> 40 | X21: =D21/$W21*$B21 -> 0 | Y21: =E21/$W21*$B21 -> 0 | Z21: =F21/$W21*$B21 -> 33.948937 | AA21: =G21/$W21*$B21 -> 594.1064 | AB21: =H21/$W21*$B21 -> 50.923405 | AC21: =I21/$W21*$B21 -> 0 | AD21: =J21/$W21*$B21 -> 0 | AE21: =K21/$W21*$B21 -> 0 | ... AP21: =V21/$W21*$B21 -> 0 | AQ21: =SUM(X21:AP21) -> 678.97874
A22: 35 | B22: 908.3151 | C22: 35 | G22: 25 | H22: 30 | I22: 5 | W22: =SUM(E22:V22) -> 60 | X22: =D22/$W22*$B22 -> 0 | Y22: =E22/$W22*$B22 -> 0 | Z22: =F22/$W22*$B22 -> 0 | AA22: =G22/$W22*$B22 -> 378.46462 | AB22: =H22/$W22*$B22 -> 454.15755 | AC22: =I22/$W22*$B22 -> 75.692925 | AD22: =J22/$W22*$B22 -> 0 | AE22: =K22/$W22*$B22 -> 0 | ... AP22: =V22/$W22*$B22 -> 0 | AQ22: =SUM(X22:AP22) -> 908.3151
A23: 36 | B23: 1174.5133 | C23: 36 | G23: 6 | H23: 46 | I23: 10 | W23: =SUM(E23:V23) -> 62 | X23: =D23/$W23*$B23 -> 0 | Y23: =E23/$W23*$B23 -> 0 | Z23: =F23/$W23*$B23 -> 0 | AA23: =G23/$W23*$B23 -> 113.66258 | AB23: =H23/$W23*$B23 -> 871.41308 | AC23: =I23/$W23*$B23 -> 189.43763 | AD23: =J23/$W23*$B23 -> 0 | AE23: =K23/$W23*$B23 -> 0 | ... AP23: =V23/$W23*$B23 -> 0 | AQ23: =SUM(X23:AP23) -> 1174.5133
A24: 37 | B24: 1052.9581 | C24: 37 | G24: 2 | H24: 35 | I24: 23 | J24: 1 | W24: =SUM(E24:V24) -> 61 | X24: =D24/$W24*$B24 -> 0 | Y24: =E24/$W24*$B24 -> 0 | Z24: =F24/$W24*$B24 -> 0 | AA24: =G24/$W24*$B24 -> 34.523217 | AB24: =H24/$W24*$B24 -> 604.1563 | AC24: =I24/$W24*$B24 -> 397.017 | AD24: =J24/$W24*$B24 -> 17.261609 | AE24: =K24/$W24*$B24 -> 0 | ... AP24: =V24/$W24*$B24 -> 0 | AQ24: =SUM(X24:AP24) -> 1052.9581
A25: 38 | B25: 729.46327 | C25: 38 | G25: 1 | H25: 12 | I25: 27 | J25: 2 | W25: =SUM(E25:V25) -> 42 | X25: =D25/$W25*$B25 -> 0 | Y25: =E25/$W25*$B25 -> 0 | Z25: =F25/$W25*$B25 -> 0 | AA25: =G25/$W25*$B25 -> 17.368173 | AB25: =H25/$W25*$B25 -> 208.41808 | AC25: =I25/$W25*$B25 -> 468.94067 | AD25: =J25/$W25*$B25 -> 34.736346 | AE25: =K25/$W25*$B25 -> 0 | ... AP25: =V25/$W25*$B25 -> 0 | AQ25: =SUM(X25:AP25) -> 729.46327
A26: 39 | B26: 455.36433 | C26: 39 | I26: 17 | J26: 14 | K26: 1 | W26: =SUM(E26:V26) -> 32 | X26: =D26/$W26*$B26 -> 0 | Y26: =E26/$W26*$B26 -> 0 | Z26: =F26/$W26*$B26 -> 0 | AA26: =G26/$W26*$B26 -> 0 | AB26: =H26/$W26*$B26 -> 0 | AC26: =I26/$W26*$B26 -> 241.9123 | AD26: =J26/$W26*$B26 -> 199.22189 | AE26: =K26/$W26*$B26 -> 14.230135 | ... AP26: =V26/$W26*$B26 -> 0 | AQ26: =SUM(X26:AP26) -> 455.36433
A27: 40 | B27: 290.68345 | C27: 40 | H27: 1 | I27: 5 | J27: 17 | K27: 2 | W27: =SUM(E27:V27) -> 25 | X27: =D27/$W27*$B27 -> 0 | Y27: =E27/$W27*$B27 -> 0 | Z27: =F27/$W27*$B27 -> 0 | AA27: =G27/$W27*$B27 -> 0 | AB27: =H27/$W27*$B27 -> 11.627338 | AC27: =I27/$W27*$B27 -> 58.136691 | AD27: =J27/$W27*$B27 -> 197.66475 | AE27: =K27/$W27*$B27 -> 23.254676 | ... AP27: =V27/$W27*$B27 -> 0 | AQ27: =SUM(X27:AP27) -> 290.68345
A28: 41 | B28: 202.90859 | C28: 41 | I28: 1 | J28: 3 | K28: 5 | W28: =SUM(E28:V28) -> 9 | X28: =D28/$W28*$B28 -> 0 | Y28: =E28/$W28*$B28 -> 0 | Z28: =F28/$W28*$B28 -> 0 | AA28: =G28/$W28*$B28 -> 0 | AB28: =H28/$W28*$B28 -> 0 | AC28: =I28/$W28*$B28 -> 22.545399 | AD28: =J28/$W28*$B28 -> 67.636196 | AE28: =K28/$W28*$B28 -> 112.72699 | ... AP28: =V28/$W28*$B28 -> 0 | AQ28: =SUM(X28:AP28) -> 202.90859
A29: 42 | B29: 162.69268 | C29: 42 | J29: 7 | K29: 3 | L29: 5 | W29: =SUM(E29:V29) -> 15 | X29: =D29/$W29*$B29 -> 0 | Y29: =E29/$W29*$B29 -> 0 | Z29: =F29/$W29*$B29 -> 0 | AA29: =G29/$W29*$B29 -> 0 | AB29: =H29/$W29*$B29 -> 0 | AC29: =I29/$W29*$B29 -> 0 | AD29: =J29/$W29*$B29 -> 75.923252 | AE29: =K29/$W29*$B29 -> 32.538537 | ... AP29: =V29/$W29*$B29 -> 0 | AQ29: =SUM(X29:AP29) -> 162.69268
A30: 43 | B30: 130.18534 | C30: 43 | I30: 1 | J30: 6 | K30: 3 | W30: =SUM(E30:V30) -> 10 | X30: =D30/$W30*$B30 -> 0 | Y30: =E30/$W30*$B30 -> 0 | Z30: =F30/$W30*$B30 -> 0 | AA30: =G30/$W30*$B30 -> 0 | AB30: =H30/$W30*$B30 -> 0 | AC30: =I30/$W30*$B30 -> 13.018534 | AD30: =J30/$W30*$B30 -> 78.111204 | AE30: =K30/$W30*$B30 -> 39.055602 | ... AP30: =V30/$W30*$B30 -> 0 | AQ30: =SUM(X30:AP30) -> 130.18534
A31: 44 | B31: 60.226966 | C31: 44 | K31: 5 | L31: 1 | M31: 3 | W31: =SUM(E31:V31) -> 9 | X31: =D31/$W31*$B31 -> 0 | Y31: =E31/$W31*$B31 -> 0 | Z31: =F31/$W31*$B31 -> 0 | AA31: =G31/$W31*$B31 -> 0 | AB31: =H31/$W31*$B31 -> 0 | AC31: =I31/$W31*$B31 -> 0 | AD31: =J31/$W31*$B31 -> 0 | AE31: =K31/$W31*$B31 -> 33.459426 | ... AP31: =V31/$W31*$B31 -> 0 | AQ31: =SUM(X31:AP31) -> 60.226966
A32: 45 | B32: 72.935929 | C32: 45 | K32: 1 | L32: 2 | M32: 3 | N32: 3 | W32: =SUM(E32:V32) -> 9 | X32: =D32/$W32*$B32 -> 0 | Y32: =E32/$W32*$B32 -> 0 | Z32: =F32/$W32*$B32 -> 0 | AA32: =G32/$W32*$B32 -> 0 | AB32: =H32/$W32*$B32 -> 0 | AC32: =I32/$W32*$B32 -> 0 | AD32: =J32/$W32*$B32 -> 0 | AE32: =K32/$W32*$B32 -> 8.1039921 | ... AP32: =V32/$W32*$B32 -> 0 | AQ32: =SUM(X32:AP32) -> 72.935929
A33: 46 | B33: 41.463641 | C33: 46 | M33: 3 | W33: =SUM(E33:V33) -> 3 | X33: =D33/$W33*$B33 -> 0 | Y33: =E33/$W33*$B33 -> 0 | Z33: =F33/$W33*$B33 -> 0 | AA33: =G33/$W33*$B33 -> 0 | AB33: =H33/$W33*$B33 -> 0 | AC33: =I33/$W33*$B33 -> 0 | AD33: =J33/$W33*$B33 -> 0 | AE33: =K33/$W33*$B33 -> 0 | ... AP33: =V33/$W33*$B33 -> 0 | AQ33: =SUM(X33:AP33) -> 41.463641
A34: 47 | B34: 19.558916 | C34: 47 | N34: 1 | O34: 2 | Q34: 1 | W34: =SUM(E34:V34) -> 4 | X34: =D34/$W34*$B34 -> 0 | Y34: =E34/$W34*$B34 -> 0 | Z34: =F34/$W34*$B34 -> 0 | AA34: =G34/$W34*$B34 -> 0 | AB34: =H34/$W34*$B34 -> 0 | AC34: =I34/$W34*$B34 -> 0 | AD34: =J34/$W34*$B34 -> 0 | AE34: =K34/$W34*$B34 -> 0 | ... AP34: =V34/$W34*$B34 -> 0 | AQ34: =SUM(X34:AP34) -> 19.558916
A35: 48 | B35: 14.314322 | C35: 48 | P35: 1 | Q35: 2 | S35: 1 | W35: =SUM(E35:V35) -> 4 | X35: =D35/$W35*$B35 -> 0 | Y35: =E35/$W35*$B35 -> 0 | Z35: =F35/$W35*$B35 -> 0 | AA35: =G35/$W35*$B35 -> 0 | AB35: =H35/$W35*$B35 -> 0 | AC35: =I35/$W35*$B35 -> 0 | AD35: =J35/$W35*$B35 -> 0 | AE35: =K35/$W35*$B35 -> 0 | ... AP35: =V35/$W35*$B35 -> 0 | AQ35: =SUM(X35:AP35) -> 14.314322
A36: 49 | B36: 7.2705917 | C36: 49 | R36: 2 | S36: 2 | W36: =SUM(E36:V36) -> 4 | X36: =D36/$W36*$B36 -> 0 | Y36: =E36/$W36*$B36 -> 0 | Z36: =F36/$W36*$B36 -> 0 | AA36: =G36/$W36*$B36 -> 0 | AB36: =H36/$W36*$B36 -> 0 | AC36: =I36/$W36*$B36 -> 0 | AD36: =J36/$W36*$B36 -> 0 | AE36: =K36/$W36*$B36 -> 0 | ... AP36: =V36/$W36*$B36 -> 0 | AQ36: =SUM(X36:AP36) -> 7.2705917
A37: 50 | B37: 0.23001222 | C37: 50 | Q37: 2 | R37: 1 | W37: =SUM(E37:V37) -> 3 | X37: =D37/$W37*$B37 -> 0 | Y37: =E37/$W37*$B37 -> 0 | Z37: =F37/$W37*$B37 -> 0 | AA37: =G37/$W37*$B37 -> 0 | AB37: =H37/$W37*$B37 -> 0 | AC37: =I37/$W37*$B37 -> 0 | AD37: =J37/$W37*$B37 -> 0 | AE37: =K37/$W37*$B37 -> 0 | ... AP37: =V37/$W37*$B37 -> 0 | AQ37: =SUM(X37:AP37) -> 0.23001222
