Workbook

Sheet Rodolfo 2010
B5: TALLAS | C5: FREC. | D5: GRUPOS DE EDAD
B6: (cm) | C6: (Unidades) | D6: O | E6: I | F6: II | G6: III | H6: IV | I6: V | J6: VI | K6: VII | L6: VIII | M6: IX | N6: X | O6: XI | P6: XII | Q6: XIII | R6: XIV | S6: XV | T6: XVI | U6: XVII | V6: XVIII | W6: XIX | X6: XX | Y6: XXI | Z6: XXII | AA6: XXIII | AB6: XXIV
B7: 5 | C7: =SUM(D7:AA7) -> 0 | D7: ='[1]Cald Coqbo 2011'!D7+'[1]SAnt Guaitecas 2011'!D7 -> 0 | E7: ='[1]Cald Coqbo 2011'!E7+'[1]SAnt Guaitecas 2011'!E7 -> 0 | F7: ='[1]Cald Coqbo 2011'!F7+'[1]SAnt Guaitecas 2011'!F7 -> 0 | G7: ='[1]Cald Coqbo 2011'!G7+'[1]SAnt Guaitecas 2011'!G7 -> 0 | H7: ='[1]Cald Coqbo 2011'!H7+'[1]SAnt Guaitecas 2011'!H7 -> 0 | I7: ='[1]Cald Coqbo 2011'!I7+'[1]SAnt Guaitecas 2011'!I7 -> 0 | J7: ='[1]Cald Coqbo 2011'!J7+'[1]SAnt Guaitecas 2011'!J7 -> 0 | K7: ='[1]Cald Coqbo 2011'!K7+'[1]SAnt Guaitecas 2011'!K7 -> 0 | ... Y7: ='[1]Cald Coqbo 2011'!Y7+'[1]SAnt Guaitecas 2011'!Y7 -> 0 | Z7: 0 | AA7: 0 | AB7: 0
B8: 6 | C8: =SUM(D8:AA8) -> 0 | D8: ='[1]Cald Coqbo 2011'!D8+'[1]SAnt Guaitecas 2011'!D8 -> 0 | E8: ='[1]Cald Coqbo 2011'!E8+'[1]SAnt Guaitecas 2011'!E8 -> 0 | F8: ='[1]Cald Coqbo 2011'!F8+'[1]SAnt Guaitecas 2011'!F8 -> 0 | G8: ='[1]Cald Coqbo 2011'!G8+'[1]SAnt Guaitecas 2011'!G8 -> 0 | H8: ='[1]Cald Coqbo 2011'!H8+'[1]SAnt Guaitecas 2011'!H8 -> 0 | I8: ='[1]Cald Coqbo 2011'!I8+'[1]SAnt Guaitecas 2011'!I8 -> 0 | J8: ='[1]Cald Coqbo 2011'!J8+'[1]SAnt Guaitecas 2011'!J8 -> 0 | K8: ='[1]Cald Coqbo 2011'!K8+'[1]SAnt Guaitecas 2011'!K8 -> 0 | ... Y8: ='[1]Cald Coqbo 2011'!Y8+'[1]SAnt Guaitecas 2011'!Y8 -> 0 | Z8: 0 | AA8: 0 | AB8: 0
B9: 7 | C9: =SUM(D9:AA9) -> 0 | D9: ='[1]Cald Coqbo 2011'!D9+'[1]SAnt Guaitecas 2011'!D9 -> 0 | E9: ='[1]Cald Coqbo 2011'!E9+'[1]SAnt Guaitecas 2011'!E9 -> 0 | F9: ='[1]Cald Coqbo 2011'!F9+'[1]SAnt Guaitecas 2011'!F9 -> 0 | G9: ='[1]Cald Coqbo 2011'!G9+'[1]SAnt Guaitecas 2011'!G9 -> 0 | H9: ='[1]Cald Coqbo 2011'!H9+'[1]SAnt Guaitecas 2011'!H9 -> 0 | I9: ='[1]Cald Coqbo 2011'!I9+'[1]SAnt Guaitecas 2011'!I9 -> 0 | J9: ='[1]Cald Coqbo 2011'!J9+'[1]SAnt Guaitecas 2011'!J9 -> 0 | K9: ='[1]Cald Coqbo 2011'!K9+'[1]SAnt Guaitecas 2011'!K9 -> 0 | ... Y9: ='[1]Cald Coqbo 2011'!Y9+'[1]SAnt Guaitecas 2011'!Y9 -> 0 | Z9: 0 | AA9: 0 | AB9: 0
B10: 8 | C10: =SUM(D10:AA10) -> 0 | D10: ='[1]Cald Coqbo 2011'!D10+'[1]SAnt Guaitecas 2011'!D10 -> 0 | E10: ='[1]Cald Coqbo 2011'!E10+'[1]SAnt Guaitecas 2011'!E10 -> 0 | F10: ='[1]Cald Coqbo 2011'!F10+'[1]SAnt Guaitecas 2011'!F10 -> 0 | G10: ='[1]Cald Coqbo 2011'!G10+'[1]SAnt Guaitecas 2011'!G10 -> 0 | H10: ='[1]Cald Coqbo 2011'!H10+'[1]SAnt Guaitecas 2011'!H10 -> 0 | I10: ='[1]Cald Coqbo 2011'!I10+'[1]SAnt Guaitecas 2011'!I10 -> 0 | J10: ='[1]Cald Coqbo 2011'!J10+'[1]SAnt Guaitecas 2011'!J10 -> 0 | K10: ='[1]Cald Coqbo 2011'!K10+'[1]SAnt Guaitecas 2011'!K10 -> 0 | ... Y10: ='[1]Cald Coqbo 2011'!Y10+'[1]SAnt Guaitecas 2011'!Y10 -> 0 | Z10: 0 | AA10: 0 | AB10: 0
B11: 9 | C11: =SUM(D11:AA11) -> 0 | D11: ='[1]Cald Coqbo 2011'!D11+'[1]SAnt Guaitecas 2011'!D11 -> 0 | E11: ='[1]Cald Coqbo 2011'!E11+'[1]SAnt Guaitecas 2011'!E11 -> 0 | F11: ='[1]Cald Coqbo 2011'!F11+'[1]SAnt Guaitecas 2011'!F11 -> 0 | G11: ='[1]Cald Coqbo 2011'!G11+'[1]SAnt Guaitecas 2011'!G11 -> 0 | H11: ='[1]Cald Coqbo 2011'!H11+'[1]SAnt Guaitecas 2011'!H11 -> 0 | I11: ='[1]Cald Coqbo 2011'!I11+'[1]SAnt Guaitecas 2011'!I11 -> 0 | J11: ='[1]Cald Coqbo 2011'!J11+'[1]SAnt Guaitecas 2011'!J11 -> 0 | K11: ='[1]Cald Coqbo 2011'!K11+'[1]SAnt Guaitecas 2011'!K11 -> 0 | ... Y11: ='[1]Cald Coqbo 2011'!Y11+'[1]SAnt Guaitecas 2011'!Y11 -> 0 | Z11: 0 | AA11: 0 | AB11: 0
B12: 10 | C12: =SUM(D12:AA12) -> 0 | D12: ='[1]Cald Coqbo 2011'!D12+'[1]SAnt Guaitecas 2011'!D12 -> 0 | E12: ='[1]Cald Coqbo 2011'!E12+'[1]SAnt Guaitecas 2011'!E12 -> 0 | F12: ='[1]Cald Coqbo 2011'!F12+'[1]SAnt Guaitecas 2011'!F12 -> 0 | G12: ='[1]Cald Coqbo 2011'!G12+'[1]SAnt Guaitecas 2011'!G12 -> 0 | H12: ='[1]Cald Coqbo 2011'!H12+'[1]SAnt Guaitecas 2011'!H12 -> 0 | I12: ='[1]Cald Coqbo 2011'!I12+'[1]SAnt Guaitecas 2011'!I12 -> 0 | J12: ='[1]Cald Coqbo 2011'!J12+'[1]SAnt Guaitecas 2011'!J12 -> 0 | K12: ='[1]Cald Coqbo 2011'!K12+'[1]SAnt Guaitecas 2011'!K12 -> 0 | ... Y12: ='[1]Cald Coqbo 2011'!Y12+'[1]SAnt Guaitecas 2011'!Y12 -> 0 | Z12: 0 | AA12: 0 | AB12: 0
B13: 11 | C13: =SUM(D13:AA13) -> 0 | D13: ='[1]Cald Coqbo 2011'!D13+'[1]SAnt Guaitecas 2011'!D13 -> 0 | E13: ='[1]Cald Coqbo 2011'!E13+'[1]SAnt Guaitecas 2011'!E13 -> 0 | F13: ='[1]Cald Coqbo 2011'!F13+'[1]SAnt Guaitecas 2011'!F13 -> 0 | G13: ='[1]Cald Coqbo 2011'!G13+'[1]SAnt Guaitecas 2011'!G13 -> 0 | H13: ='[1]Cald Coqbo 2011'!H13+'[1]SAnt Guaitecas 2011'!H13 -> 0 | I13: ='[1]Cald Coqbo 2011'!I13+'[1]SAnt Guaitecas 2011'!I13 -> 0 | J13: ='[1]Cald Coqbo 2011'!J13+'[1]SAnt Guaitecas 2011'!J13 -> 0 | K13: ='[1]Cald Coqbo 2011'!K13+'[1]SAnt Guaitecas 2011'!K13 -> 0 | ... Y13: ='[1]Cald Coqbo 2011'!Y13+'[1]SAnt Guaitecas 2011'!Y13 -> 0 | Z13: 0 | AA13: 0 | AB13: 0
B14: 12 | C14: =SUM(D14:AA14) -> 0 | D14: ='[1]Cald Coqbo 2011'!D14+'[1]SAnt Guaitecas 2011'!D14 -> 0 | E14: ='[1]Cald Coqbo 2011'!E14+'[1]SAnt Guaitecas 2011'!E14 -> 0 | F14: ='[1]Cald Coqbo 2011'!F14+'[1]SAnt Guaitecas 2011'!F14 -> 0 | G14: ='[1]Cald Coqbo 2011'!G14+'[1]SAnt Guaitecas 2011'!G14 -> 0 | H14: ='[1]Cald Coqbo 2011'!H14+'[1]SAnt Guaitecas 2011'!H14 -> 0 | I14: ='[1]Cald Coqbo 2011'!I14+'[1]SAnt Guaitecas 2011'!I14 -> 0 | J14: ='[1]Cald Coqbo 2011'!J14+'[1]SAnt Guaitecas 2011'!J14 -> 0 | K14: ='[1]Cald Coqbo 2011'!K14+'[1]SAnt Guaitecas 2011'!K14 -> 0 | ... Y14: ='[1]Cald Coqbo 2011'!Y14+'[1]SAnt Guaitecas 2011'!Y14 -> 0 | Z14: 0 | AA14: 0 | AB14: 0
B15: 13 | C15: =SUM(D15:AA15) -> 0 | D15: ='[1]Cald Coqbo 2011'!D15+'[1]SAnt Guaitecas 2011'!D15 -> 0 | E15: ='[1]Cald Coqbo 2011'!E15+'[1]SAnt Guaitecas 2011'!E15 -> 0 | F15: ='[1]Cald Coqbo 2011'!F15+'[1]SAnt Guaitecas 2011'!F15 -> 0 | G15: ='[1]Cald Coqbo 2011'!G15+'[1]SAnt Guaitecas 2011'!G15 -> 0 | H15: ='[1]Cald Coqbo 2011'!H15+'[1]SAnt Guaitecas 2011'!H15 -> 0 | I15: ='[1]Cald Coqbo 2011'!I15+'[1]SAnt Guaitecas 2011'!I15 -> 0 | J15: ='[1]Cald Coqbo 2011'!J15+'[1]SAnt Guaitecas 2011'!J15 -> 0 | K15: ='[1]Cald Coqbo 2011'!K15+'[1]SAnt Guaitecas 2011'!K15 -> 0 | ... Y15: ='[1]Cald Coqbo 2011'!Y15+'[1]SAnt Guaitecas 2011'!Y15 -> 0 | Z15: 0 | AA15: 0 | AB15: 0
B16: 14 | C16: =SUM(D16:AA16) -> 1 | D16: ='[1]Ages 2010'!D16/'[1]Ages 2010'!$C$16 -> 0 | E16: ='[1]Ages 2010'!E16/'[1]Ages 2010'!$C$16 -> 0 | F16: ='[1]Ages 2010'!F16/'[1]Ages 2010'!$C$16 -> 1 | G16: ='[1]Ages 2010'!G16/'[1]Ages 2010'!$C$16 -> 0 | H16: ='[1]Ages 2010'!H16/'[1]Ages 2010'!$C$16 -> 0 | I16: ='[1]Ages 2010'!I16/'[1]Ages 2010'!$C$16 -> 0 | J16: ='[1]Ages 2010'!J16/'[1]Ages 2010'!$C$16 -> 0 | K16: ='[1]Ages 2010'!K16/'[1]Ages 2010'!$C$16 -> 0 | ... AA16: ='[1]Ages 2010'!AA16/'[1]Ages 2010'!$C$16 -> 0 | AB16: 0
B17: 15 | C17: =SUM(D17:AA17) -> 1 | D17: ='[1]Ages 2010'!D17/'[1]Ages 2010'!$C$17 -> 0 | E17: ='[1]Ages 2010'!E17/'[1]Ages 2010'!$C$17 -> 0 | F17: ='[1]Ages 2010'!F17/'[1]Ages 2010'!$C$17 -> 1 | G17: ='[1]Ages 2010'!G17/'[1]Ages 2010'!$C$17 -> 0 | H17: ='[1]Ages 2010'!H17/'[1]Ages 2010'!$C$17 -> 0 | I17: ='[1]Ages 2010'!I17/'[1]Ages 2010'!$C$17 -> 0 | J17: ='[1]Ages 2010'!J17/'[1]Ages 2010'!$C$17 -> 0 | K17: ='[1]Ages 2010'!K17/'[1]Ages 2010'!$C$17 -> 0 | ... AB17: ='[1]Ages 2010'!AB17/'[1]Ages 2010'!$C$17 -> 0
B18: 16 | C18: =SUM(D18:AA18) -> 1 | D18: ='[1]Ages 2010'!D18/'[1]Ages 2010'!$C$18 -> 0 | E18: ='[1]Ages 2010'!E18/'[1]Ages 2010'!$C$18 -> 0 | F18: ='[1]Ages 2010'!F18/'[1]Ages 2010'!$C$18 -> 0.5 | G18: ='[1]Ages 2010'!G18/'[1]Ages 2010'!$C$18 -> 0.5 | H18: ='[1]Ages 2010'!H18/'[1]Ages 2010'!$C$18 -> 0 | I18: ='[1]Ages 2010'!I18/'[1]Ages 2010'!$C$18 -> 0 | J18: ='[1]Ages 2010'!J18/'[1]Ages 2010'!$C$18 -> 0 | K18: ='[1]Ages 2010'!K18/'[1]Ages 2010'!$C$18 -> 0 | ... AB18: ='[1]Ages 2010'!AB18/'[1]Ages 2010'!$C$18 -> 0
B19: 17 | C19: =SUM(D19:AA19) -> 1 | D19: ='[1]Ages 2010'!D19/'[1]Ages 2010'!$C$19 -> 0 | E19: ='[1]Ages 2010'!E19/'[1]Ages 2010'!$C$19 -> 0 | F19: ='[1]Ages 2010'!F19/'[1]Ages 2010'!$C$19 -> 0.5 | G19: ='[1]Ages 2010'!G19/'[1]Ages 2010'!$C$19 -> 0.5 | H19: ='[1]Ages 2010'!H19/'[1]Ages 2010'!$C$19 -> 0 | I19: ='[1]Ages 2010'!I19/'[1]Ages 2010'!$C$19 -> 0 | J19: ='[1]Ages 2010'!J19/'[1]Ages 2010'!$C$19 -> 0 | K19: ='[1]Ages 2010'!K19/'[1]Ages 2010'!$C$19 -> 0 | ... AB19: ='[1]Ages 2010'!AB19/'[1]Ages 2010'!$C$19 -> 0
B20: 18 | C20: =SUM(D20:AA20) -> 1 | D20: ='[1]Ages 2010'!D20/'[1]Ages 2010'!$C$20 -> 0 | E20: ='[1]Ages 2010'!E20/'[1]Ages 2010'!$C$20 -> 0 | F20: ='[1]Ages 2010'!F20/'[1]Ages 2010'!$C$20 -> 1 | G20: ='[1]Ages 2010'!G20/'[1]Ages 2010'!$C$20 -> 0 | H20: ='[1]Ages 2010'!H20/'[1]Ages 2010'!$C$20 -> 0 | I20: ='[1]Ages 2010'!I20/'[1]Ages 2010'!$C$20 -> 0 | J20: ='[1]Ages 2010'!J20/'[1]Ages 2010'!$C$20 -> 0 | K20: ='[1]Ages 2010'!K20/'[1]Ages 2010'!$C$20 -> 0 | ... AB20: ='[1]Ages 2010'!AB20/'[1]Ages 2010'!$C$20 -> 0
B21: 19 | C21: =SUM(D21:AA21) -> 1 | D21: ='[1]Ages 2010'!D21/'[1]Ages 2010'!$C$21 -> 0 | E21: ='[1]Ages 2010'!E21/'[1]Ages 2010'!$C$21 -> 0 | F21: ='[1]Ages 2010'!F21/'[1]Ages 2010'!$C$21 -> 0.55880394 | G21: ='[1]Ages 2010'!G21/'[1]Ages 2010'!$C$21 -> 0.44119606 | H21: ='[1]Ages 2010'!H21/'[1]Ages 2010'!$C$21 -> 0 | I21: ='[1]Ages 2010'!I21/'[1]Ages 2010'!$C$21 -> 0 | J21: ='[1]Ages 2010'!J21/'[1]Ages 2010'!$C$21 -> 0 | K21: ='[1]Ages 2010'!K21/'[1]Ages 2010'!$C$21 -> 0 | ... AB21: ='[1]Ages 2010'!AB21/'[1]Ages 2010'!$C$21 -> 0
B22: 20 | C22: =SUM(D22:AA22) -> 1 | D22: ='[1]Ages 2010'!D22/'[1]Ages 2010'!$C$22 -> 0 | E22: ='[1]Ages 2010'!E22/'[1]Ages 2010'!$C$22 -> 0 | F22: ='[1]Ages 2010'!F22/'[1]Ages 2010'!$C$22 -> 0 | G22: ='[1]Ages 2010'!G22/'[1]Ages 2010'!$C$22 -> 1 | H22: ='[1]Ages 2010'!H22/'[1]Ages 2010'!$C$22 -> 0 | I22: ='[1]Ages 2010'!I22/'[1]Ages 2010'!$C$22 -> 0 | J22: ='[1]Ages 2010'!J22/'[1]Ages 2010'!$C$22 -> 0 | K22: ='[1]Ages 2010'!K22/'[1]Ages 2010'!$C$22 -> 0 | ... AB22: ='[1]Ages 2010'!AB22/'[1]Ages 2010'!$C$22 -> 0
B23: 21 | C23: =SUM(D23:AA23) -> 1 | D23: ='[1]Ages 2010'!D23/'[1]Ages 2010'!$C$23 -> 0 | E23: ='[1]Ages 2010'!E23/'[1]Ages 2010'!$C$23 -> 0 | F23: ='[1]Ages 2010'!F23/'[1]Ages 2010'!$C$23 -> 0.001619165 | G23: ='[1]Ages 2010'!G23/'[1]Ages 2010'!$C$23 -> 0.99838084 | H23: ='[1]Ages 2010'!H23/'[1]Ages 2010'!$C$23 -> 0 | I23: ='[1]Ages 2010'!I23/'[1]Ages 2010'!$C$23 -> 0 | J23: ='[1]Ages 2010'!J23/'[1]Ages 2010'!$C$23 -> 0 | K23: ='[1]Ages 2010'!K23/'[1]Ages 2010'!$C$23 -> 0 | ... AB23: ='[1]Ages 2010'!AB23/'[1]Ages 2010'!$C$23 -> 0
B24: 22 | C24: =SUM(D24:AA24) -> 1 | D24: ='[1]Ages 2010'!D24/'[1]Ages 2010'!$C$24 -> 0 | E24: ='[1]Ages 2010'!E24/'[1]Ages 2010'!$C$24 -> 0 | F24: ='[1]Ages 2010'!F24/'[1]Ages 2010'!$C$24 -> 0 | G24: ='[1]Ages 2010'!G24/'[1]Ages 2010'!$C$24 -> 0.72796541 | H24: ='[1]Ages 2010'!H24/'[1]Ages 2010'!$C$24 -> 0.27203459 | I24: ='[1]Ages 2010'!I24/'[1]Ages 2010'!$C$24 -> 0 | J24: ='[1]Ages 2010'!J24/'[1]Ages 2010'!$C$24 -> 0 | K24: ='[1]Ages 2010'!K24/'[1]Ages 2010'!$C$24 -> 0 | ... AB24: ='[1]Ages 2010'!AB24/'[1]Ages 2010'!$C$24 -> 0
B25: 23 | C25: =SUM(D25:AA25) -> 1 | D25: ='[1]Ages 2010'!D25/'[1]Ages 2010'!$C$25 -> 0 | E25: ='[1]Ages 2010'!E25/'[1]Ages 2010'!$C$25 -> 0 | F25: ='[1]Ages 2010'!F25/'[1]Ages 2010'!$C$25 -> 0 | G25: ='[1]Ages 2010'!G25/'[1]Ages 2010'!$C$25 -> 0.45761996 | H25: ='[1]Ages 2010'!H25/'[1]Ages 2010'!$C$25 -> 0.54238004 | I25: ='[1]Ages 2010'!I25/'[1]Ages 2010'!$C$25 -> 0 | J25: ='[1]Ages 2010'!J25/'[1]Ages 2010'!$C$25 -> 0 | K25: ='[1]Ages 2010'!K25/'[1]Ages 2010'!$C$25 -> 0 | ... AB25: ='[1]Ages 2010'!AB25/'[1]Ages 2010'!$C$25 -> 0
B26: 24 | C26: =SUM(D26:AA26) -> 1 | D26: ='[1]Ages 2010'!D26/'[1]Ages 2010'!$C$26 -> 0 | E26: ='[1]Ages 2010'!E26/'[1]Ages 2010'!$C$26 -> 0 | F26: ='[1]Ages 2010'!F26/'[1]Ages 2010'!$C$26 -> 0 | G26: ='[1]Ages 2010'!G26/'[1]Ages 2010'!$C$26 -> 0.19667015 | H26: ='[1]Ages 2010'!H26/'[1]Ages 2010'!$C$26 -> 0.80332985 | I26: ='[1]Ages 2010'!I26/'[1]Ages 2010'!$C$26 -> 0 | J26: ='[1]Ages 2010'!J26/'[1]Ages 2010'!$C$26 -> 0 | K26: ='[1]Ages 2010'!K26/'[1]Ages 2010'!$C$26 -> 0 | ... AB26: ='[1]Ages 2010'!AB26/'[1]Ages 2010'!$C$26 -> 0
B27: 25 | C27: =SUM(D27:AA27) -> 1 | D27: ='[1]Ages 2010'!D27/'[1]Ages 2010'!$C$27 -> 0 | E27: ='[1]Ages 2010'!E27/'[1]Ages 2010'!$C$27 -> 0 | F27: ='[1]Ages 2010'!F27/'[1]Ages 2010'!$C$27 -> 0 | G27: ='[1]Ages 2010'!G27/'[1]Ages 2010'!$C$27 -> 0.040981286 | H27: ='[1]Ages 2010'!H27/'[1]Ages 2010'!$C$27 -> 0.93987122 | I27: ='[1]Ages 2010'!I27/'[1]Ages 2010'!$C$27 -> 0.019147491 | J27: ='[1]Ages 2010'!J27/'[1]Ages 2010'!$C$27 -> 0 | K27: ='[1]Ages 2010'!K27/'[1]Ages 2010'!$C$27 -> 0 | ... AB27: ='[1]Ages 2010'!AB27/'[1]Ages 2010'!$C$27 -> 0
B28: 26 | C28: =SUM(D28:AA28) -> 1 | D28: ='[1]Ages 2010'!D28/'[1]Ages 2010'!$C$28 -> 0 | E28: ='[1]Ages 2010'!E28/'[1]Ages 2010'!$C$28 -> 0 | F28: ='[1]Ages 2010'!F28/'[1]Ages 2010'!$C$28 -> 0 | G28: ='[1]Ages 2010'!G28/'[1]Ages 2010'!$C$28 -> 0.0015681117 | H28: ='[1]Ages 2010'!H28/'[1]Ages 2010'!$C$28 -> 0.84280018 | I28: ='[1]Ages 2010'!I28/'[1]Ages 2010'!$C$28 -> 0.15563171 | J28: ='[1]Ages 2010'!J28/'[1]Ages 2010'!$C$28 -> 0 | K28: ='[1]Ages 2010'!K28/'[1]Ages 2010'!$C$28 -> 0 | ... AB28: ='[1]Ages 2010'!AB28/'[1]Ages 2010'!$C$28 -> 0
B29: 27 | C29: =SUM(D29:AA29) -> 1 | D29: ='[1]Ages 2010'!D29/'[1]Ages 2010'!$C$29 -> 0 | E29: ='[1]Ages 2010'!E29/'[1]Ages 2010'!$C$29 -> 0 | F29: ='[1]Ages 2010'!F29/'[1]Ages 2010'!$C$29 -> 0 | G29: ='[1]Ages 2010'!G29/'[1]Ages 2010'!$C$29 -> 0.001337296 | H29: ='[1]Ages 2010'!H29/'[1]Ages 2010'!$C$29 -> 0.6874885 | I29: ='[1]Ages 2010'!I29/'[1]Ages 2010'!$C$29 -> 0.3111742 | J29: ='[1]Ages 2010'!J29/'[1]Ages 2010'!$C$29 -> 0 | K29: ='[1]Ages 2010'!K29/'[1]Ages 2010'!$C$29 -> 0 | ... AB29: ='[1]Ages 2010'!AB29/'[1]Ages 2010'!$C$29 -> 0
B30: 28 | C30: =SUM(D30:AA30) -> 1 | D30: ='[1]Ages 2010'!D30/'[1]Ages 2010'!$C$30 -> 0 | E30: ='[1]Ages 2010'!E30/'[1]Ages 2010'!$C$30 -> 0 | F30: ='[1]Ages 2010'!F30/'[1]Ages 2010'!$C$30 -> 0 | G30: ='[1]Ages 2010'!G30/'[1]Ages 2010'!$C$30 -> 0 | H30: ='[1]Ages 2010'!H30/'[1]Ages 2010'!$C$30 -> 0.091831005 | I30: ='[1]Ages 2010'!I30/'[1]Ages 2010'!$C$30 -> 0.88758183 | J30: ='[1]Ages 2010'!J30/'[1]Ages 2010'!$C$30 -> 0.020587163 | K30: ='[1]Ages 2010'!K30/'[1]Ages 2010'!$C$30 -> 0 | ... AB30: ='[1]Ages 2010'!AB30/'[1]Ages 2010'!$C$30 -> 0
B31: 29 | C31: =SUM(D31:AA31) -> 1 | D31: ='[1]Ages 2010'!D31/'[1]Ages 2010'!$C$31 -> 0 | E31: ='[1]Ages 2010'!E31/'[1]Ages 2010'!$C$31 -> 0 | F31: ='[1]Ages 2010'!F31/'[1]Ages 2010'!$C$31 -> 0 | G31: ='[1]Ages 2010'!G31/'[1]Ages 2010'!$C$31 -> 0 | H31: ='[1]Ages 2010'!H31/'[1]Ages 2010'!$C$31 -> 0.015909614 | I31: ='[1]Ages 2010'!I31/'[1]Ages 2010'!$C$31 -> 0.60758034 | J31: ='[1]Ages 2010'!J31/'[1]Ages 2010'!$C$31 -> 0.37651004 | K31: ='[1]Ages 2010'!K31/'[1]Ages 2010'!$C$31 -> 0 | ... AB31: ='[1]Ages 2010'!AB31/'[1]Ages 2010'!$C$31 -> 0
B32: 30 | C32: =SUM(D32:AA32) -> 1 | D32: ='[1]Ages 2010'!D32/'[1]Ages 2010'!$C$32 -> 0 | E32: ='[1]Ages 2010'!E32/'[1]Ages 2010'!$C$32 -> 0 | F32: ='[1]Ages 2010'!F32/'[1]Ages 2010'!$C$32 -> 0 | G32: ='[1]Ages 2010'!G32/'[1]Ages 2010'!$C$32 -> 0 | H32: ='[1]Ages 2010'!H32/'[1]Ages 2010'!$C$32 -> 0.010147738 | I32: ='[1]Ages 2010'!I32/'[1]Ages 2010'!$C$32 -> 0.065141491 | J32: ='[1]Ages 2010'!J32/'[1]Ages 2010'!$C$32 -> 0.88800885 | K32: ='[1]Ages 2010'!K32/'[1]Ages 2010'!$C$32 -> 0.036701916 | ... AB32: ='[1]Ages 2010'!AB32/'[1]Ages 2010'!$C$32 -> 0
B33: 31 | C33: =SUM(D33:AA33) -> 1 | D33: ='[1]Ages 2010'!D33/'[1]Ages 2010'!$C$33 -> 0 | E33: ='[1]Ages 2010'!E33/'[1]Ages 2010'!$C$33 -> 0 | F33: ='[1]Ages 2010'!F33/'[1]Ages 2010'!$C$33 -> 0 | G33: ='[1]Ages 2010'!G33/'[1]Ages 2010'!$C$33 -> 0 | H33: ='[1]Ages 2010'!H33/'[1]Ages 2010'!$C$33 -> 0 | I33: ='[1]Ages 2010'!I33/'[1]Ages 2010'!$C$33 -> 0.034596452 | J33: ='[1]Ages 2010'!J33/'[1]Ages 2010'!$C$33 -> 0.83082334 | K33: ='[1]Ages 2010'!K33/'[1]Ages 2010'!$C$33 -> 0.13458021 | ... AB33: ='[1]Ages 2010'!AB33/'[1]Ages 2010'!$C$33 -> 0
B34: 32 | C34: =SUM(D34:AA34) -> 1 | D34: ='[1]Ages 2010'!D34/'[1]Ages 2010'!$C$34 -> 0 | E34: ='[1]Ages 2010'!E34/'[1]Ages 2010'!$C$34 -> 0 | F34: ='[1]Ages 2010'!F34/'[1]Ages 2010'!$C$34 -> 0 | G34: ='[1]Ages 2010'!G34/'[1]Ages 2010'!$C$34 -> 0 | H34: ='[1]Ages 2010'!H34/'[1]Ages 2010'!$C$34 -> 0 | I34: ='[1]Ages 2010'!I34/'[1]Ages 2010'!$C$34 -> 0.0017272812 | J34: ='[1]Ages 2010'!J34/'[1]Ages 2010'!$C$34 -> 0.50342441 | K34: ='[1]Ages 2010'!K34/'[1]Ages 2010'!$C$34 -> 0.49484831 | ... AB34: ='[1]Ages 2010'!AB34/'[1]Ages 2010'!$C$34 -> 0
B35: 33 | C35: =SUM(D35:AA35) -> 1 | D35: ='[1]Ages 2010'!D35/'[1]Ages 2010'!$C$35 -> 0 | E35: ='[1]Ages 2010'!E35/'[1]Ages 2010'!$C$35 -> 0 | F35: ='[1]Ages 2010'!F35/'[1]Ages 2010'!$C$35 -> 0 | G35: ='[1]Ages 2010'!G35/'[1]Ages 2010'!$C$35 -> 0 | H35: ='[1]Ages 2010'!H35/'[1]Ages 2010'!$C$35 -> 0 | I35: ='[1]Ages 2010'!I35/'[1]Ages 2010'!$C$35 -> 0.00014867202 | J35: ='[1]Ages 2010'!J35/'[1]Ages 2010'!$C$35 -> 0.20985214 | K35: ='[1]Ages 2010'!K35/'[1]Ages 2010'!$C$35 -> 0.78999919 | ... AB35: ='[1]Ages 2010'!AB35/'[1]Ages 2010'!$C$35 -> 0
B36: 34 | C36: =SUM(D36:AA36) -> 1 | D36: ='[1]Ages 2010'!D36/'[1]Ages 2010'!$C$36 -> 0 | E36: ='[1]Ages 2010'!E36/'[1]Ages 2010'!$C$36 -> 0 | F36: ='[1]Ages 2010'!F36/'[1]Ages 2010'!$C$36 -> 0 | G36: ='[1]Ages 2010'!G36/'[1]Ages 2010'!$C$36 -> 0 | H36: ='[1]Ages 2010'!H36/'[1]Ages 2010'!$C$36 -> 0 | I36: ='[1]Ages 2010'!I36/'[1]Ages 2010'!$C$36 -> 0.00054932874 | J36: ='[1]Ages 2010'!J36/'[1]Ages 2010'!$C$36 -> 0.051435092 | K36: ='[1]Ages 2010'!K36/'[1]Ages 2010'!$C$36 -> 0.83375366 | ... AB36: ='[1]Ages 2010'!AB36/'[1]Ages 2010'!$C$36 -> 0
B37: 35 | C37: =SUM(D37:AA37) -> 1 | D37: ='[1]Ages 2010'!D37/'[1]Ages 2010'!$C$37 -> 0 | E37: ='[1]Ages 2010'!E37/'[1]Ages 2010'!$C$37 -> 0 | F37: ='[1]Ages 2010'!F37/'[1]Ages 2010'!$C$37 -> 0 | G37: ='[1]Ages 2010'!G37/'[1]Ages 2010'!$C$37 -> 0 | H37: ='[1]Ages 2010'!H37/'[1]Ages 2010'!$C$37 -> 0 | I37: ='[1]Ages 2010'!I37/'[1]Ages 2010'!$C$37 -> 0 | J37: ='[1]Ages 2010'!J37/'[1]Ages 2010'!$C$37 -> 0.0039526741 | K37: ='[1]Ages 2010'!K37/'[1]Ages 2010'!$C$37 -> 0.46745347 | ... AB37: ='[1]Ages 2010'!AB37/'[1]Ages 2010'!$C$37 -> 0
B38: 36 | C38: =SUM(D38:AA38) -> 1 | D38: ='[1]Ages 2010'!D38/'[1]Ages 2010'!$C$38 -> 0 | E38: ='[1]Ages 2010'!E38/'[1]Ages 2010'!$C$38 -> 0 | F38: ='[1]Ages 2010'!F38/'[1]Ages 2010'!$C$38 -> 0 | G38: ='[1]Ages 2010'!G38/'[1]Ages 2010'!$C$38 -> 0 | H38: ='[1]Ages 2010'!H38/'[1]Ages 2010'!$C$38 -> 0 | I38: ='[1]Ages 2010'!I38/'[1]Ages 2010'!$C$38 -> 0 | J38: ='[1]Ages 2010'!J38/'[1]Ages 2010'!$C$38 -> 0.0050404076 | K38: ='[1]Ages 2010'!K38/'[1]Ages 2010'!$C$38 -> 0.2360924 | ... AB38: ='[1]Ages 2010'!AB38/'[1]Ages 2010'!$C$38 -> 0
B39: 37 | C39: =SUM(D39:AA39) -> 1 | D39: ='[1]Ages 2010'!D39/'[1]Ages 2010'!$C$39 -> 0 | E39: ='[1]Ages 2010'!E39/'[1]Ages 2010'!$C$39 -> 0 | F39: ='[1]Ages 2010'!F39/'[1]Ages 2010'!$C$39 -> 0 | G39: ='[1]Ages 2010'!G39/'[1]Ages 2010'!$C$39 -> 0 | H39: ='[1]Ages 2010'!H39/'[1]Ages 2010'!$C$39 -> 0 | I39: ='[1]Ages 2010'!I39/'[1]Ages 2010'!$C$39 -> 0 | J39: ='[1]Ages 2010'!J39/'[1]Ages 2010'!$C$39 -> 0 | K39: ='[1]Ages 2010'!K39/'[1]Ages 2010'!$C$39 -> 0.085863331 | ... AB39: ='[1]Ages 2010'!AB39/'[1]Ages 2010'!$C$39 -> 0
B40: 38 | C40: =SUM(D40:AA40) -> 1 | D40: ='[1]Ages 2010'!D40/'[1]Ages 2010'!$C$40 -> 0 | E40: ='[1]Ages 2010'!E40/'[1]Ages 2010'!$C$40 -> 0 | F40: ='[1]Ages 2010'!F40/'[1]Ages 2010'!$C$40 -> 0 | G40: ='[1]Ages 2010'!G40/'[1]Ages 2010'!$C$40 -> 0 | H40: ='[1]Ages 2010'!H40/'[1]Ages 2010'!$C$40 -> 0 | I40: ='[1]Ages 2010'!I40/'[1]Ages 2010'!$C$40 -> 0 | J40: ='[1]Ages 2010'!J40/'[1]Ages 2010'!$C$40 -> 0 | K40: ='[1]Ages 2010'!K40/'[1]Ages 2010'!$C$40 -> 0.00084553566 | ... AB40: ='[1]Ages 2010'!AB40/'[1]Ages 2010'!$C$40 -> 0
B41: 39 | C41: =SUM(D41:AA41) -> 1 | D41: ='[1]Ages 2010'!D41/'[1]Ages 2010'!$C$41 -> 0 | E41: ='[1]Ages 2010'!E41/'[1]Ages 2010'!$C$41 -> 0 | F41: ='[1]Ages 2010'!F41/'[1]Ages 2010'!$C$41 -> 0 | G41: ='[1]Ages 2010'!G41/'[1]Ages 2010'!$C$41 -> 0 | H41: ='[1]Ages 2010'!H41/'[1]Ages 2010'!$C$41 -> 0 | I41: ='[1]Ages 2010'!I41/'[1]Ages 2010'!$C$41 -> 0 | J41: ='[1]Ages 2010'!J41/'[1]Ages 2010'!$C$41 -> 0 | K41: ='[1]Ages 2010'!K41/'[1]Ages 2010'!$C$41 -> 0 | ... AB41: ='[1]Ages 2010'!AB41/'[1]Ages 2010'!$C$41 -> 0
B42: 40 | C42: =SUM(D42:AA42) -> 1 | D42: ='[1]Ages 2010'!D42/'[1]Ages 2010'!$C$42 -> 0 | E42: ='[1]Ages 2010'!E42/'[1]Ages 2010'!$C$42 -> 0 | F42: ='[1]Ages 2010'!F42/'[1]Ages 2010'!$C$42 -> 0 | G42: ='[1]Ages 2010'!G42/'[1]Ages 2010'!$C$42 -> 0 | H42: ='[1]Ages 2010'!H42/'[1]Ages 2010'!$C$42 -> 0 | I42: ='[1]Ages 2010'!I42/'[1]Ages 2010'!$C$42 -> 0 | J42: ='[1]Ages 2010'!J42/'[1]Ages 2010'!$C$42 -> 0 | K42: ='[1]Ages 2010'!K42/'[1]Ages 2010'!$C$42 -> 0 | ... AB42: ='[1]Ages 2010'!AB42/'[1]Ages 2010'!$C$42 -> 0
B43: 41 | C43: =SUM(D43:AA43) -> 1 | D43: ='[1]Ages 2010'!D43/'[1]Ages 2010'!$C$43 -> 0 | E43: ='[1]Ages 2010'!E43/'[1]Ages 2010'!$C$43 -> 0 | F43: ='[1]Ages 2010'!F43/'[1]Ages 2010'!$C$43 -> 0 | G43: ='[1]Ages 2010'!G43/'[1]Ages 2010'!$C$43 -> 0 | H43: ='[1]Ages 2010'!H43/'[1]Ages 2010'!$C$43 -> 0 | I43: ='[1]Ages 2010'!I43/'[1]Ages 2010'!$C$43 -> 0 | J43: ='[1]Ages 2010'!J43/'[1]Ages 2010'!$C$43 -> 0 | K43: ='[1]Ages 2010'!K43/'[1]Ages 2010'!$C$43 -> 0 | ... AB43: ='[1]Ages 2010'!AB43/'[1]Ages 2010'!$C$43 -> 0
B44: 42 | C44: =SUM(D44:AA44) -> 1 | D44: ='[1]Ages 2010'!D44/'[1]Ages 2010'!$C$44 -> 0 | E44: ='[1]Ages 2010'!E44/'[1]Ages 2010'!$C$44 -> 0 | F44: ='[1]Ages 2010'!F44/'[1]Ages 2010'!$C$44 -> 0 | G44: ='[1]Ages 2010'!G44/'[1]Ages 2010'!$C$44 -> 0 | H44: ='[1]Ages 2010'!H44/'[1]Ages 2010'!$C$44 -> 0 | I44: ='[1]Ages 2010'!I44/'[1]Ages 2010'!$C$44 -> 0 | J44: ='[1]Ages 2010'!J44/'[1]Ages 2010'!$C$44 -> 0 | K44: ='[1]Ages 2010'!K44/'[1]Ages 2010'!$C$44 -> 0 | ... AB44: ='[1]Ages 2010'!AB44/'[1]Ages 2010'!$C$44 -> 0
...

Sheet China Catch-at-length
B2: 2000 | C2: 2001 | D2: 2002 | E2: 2003 | F2: 2004 | G2: 2005 | H2: 2006 | I2: 2007 | J2: 2008 | K2: 2009 | L2: 2010 | N2: 1000
A3: 10 | B3: 0 | C3: 0 | D3: 0 | E3: 0 | H3: 0 | I3: 0 | J3: 0 | K3: 0 | L3: 0 | N3: 2000 | O3: {=MMULT(TRANSPOSE(B10:B53),'2000'!U5:AE48)} -> 0.12982632 | P3: 0.25653335 | Q3: 0.36748109 | R3: 0.34904976 | S3: 0.27049975 | T3: 0.18948879 | U3: 0.12887894 | V3: 0.09903367 | W3: 0.07086016 | X3: 0.044312113 | Y3: 0.028417632
A4: 11 | B4: 0 | C4: 0 | D4: 0.26475677 | E4: 0 | H4: 0 | I4: 0 | J4: 0 | K4: 0 | L4: 0 | N4: 2001 | O4: =[2]CHinaSlice!V97 -> 0.0082758621 | P4: =[2]CHinaSlice!W97 -> 0.3497931 | Q4: =[2]CHinaSlice!X97 -> 0.42565517 | R4: =[2]CHinaSlice!Y97 -> 0.12937931 | S4: =[2]CHinaSlice!Z97 -> 0.040275862 | T4: =[2]CHinaSlice!AA97 -> 0.020413793 | U4: =[2]CHinaSlice!AB97 -> 0.012689655 | V4: =[2]CHinaSlice!AC97 -> 0.0071724138 | ... Y4: =[2]CHinaSlice!AF97 -> 0.0016551724
A5: 12 | B5: 0 | C5: 0 | D5: 0.52951353 | E5: 0 | H5: 0 | I5: 0 | J5: 0 | K5: 0 | L5: 0 | N5: 2002 | O5: {=MMULT(TRANSPOSE(D10:D53),'2002'!U5:AE48)} -> 26.343298 | P5: 21.848273 | Q5: 29.357773 | R5: 28.035623 | S5: 20.059345 | T5: 8.2294265 | U5: 1.8123907 | V5: 0.61977152 | W5: 0.28376494 | X5: 0.18817423 | Y5: 0.10830959
A6: 13 | B6: 0 | C6: 0 | D6: 1.5885406 | E6: 0 | H6: 0 | I6: 0 | J6: 0 | K6: 0 | L6: 0 | N6: 2003 | O6: =[2]CHinaSlice!V99 -> 0.041237113 | P6: =[2]CHinaSlice!W99 -> 0.84879725 | Q6: =[2]CHinaSlice!X99 -> 0.10652921 | R6: =[2]CHinaSlice!Y99 -> 0.0034364261 | S6: =[2]CHinaSlice!Z99 -> 0 | T6: =[2]CHinaSlice!AA99 -> 0 | U6: =[2]CHinaSlice!AB99 -> 0 | V6: =[2]CHinaSlice!AC99 -> 0 | ... Y6: =[2]CHinaSlice!AF99 -> 0
A7: 14 | B7: 0 | C7: 0 | D7: 1.5885406 | E7: 0 | H7: 0 | I7: 0 | J7: 0 | K7: 0 | L7: 0 | N7: 2004 | O7: 0 | P7: 0 | Q7: 0 | R7: 0 | S7: 0 | T7: 0 | U7: 0 | V7: 0 | W7: 0 | X7: 0 | Y7: 0
A8: 15 | B8: 0 | C8: 0 | D8: 2.1180541 | E8: 0 | H8: 0 | I8: 0 | J8: 0 | K8: 0 | L8: 0 | N8: 2005 | O8: 0 | P8: 0 | Q8: 0 | R8: 0 | S8: 0 | T8: 0 | U8: 0 | V8: 0 | W8: 0 | X8: 0 | Y8: 0
A9: 16 | B9: 0 | C9: 0 | D9: 1.3237838 | E9: 1.5937128 | H9: 0 | I9: 0 | J9: 0 | K9: 0 | L9: 0 | N9: 2006 | O9: {=MMULT(TRANSPOSE(H10:H53),'2006'!U5:AE48)} -> 0 | P9: 0 | Q9: 16.583752 | R9: 36.825212 | S9: 39.754523 | T9: 31.59239 | U9: 17.525041 | V9: 9.1892296 | W9: 2.2362181 | X9: 1.0992269 | Y9: 0.91897619
A10: 17 | B10: 0 | C10: 0 | D10: 0 | E10: 0 | H10: 0 | I10: 0 | J10: 0 | K10: 0.094537558 | L10: 0 | N10: 2007 | O10: {=MMULT(TRANSPOSE(I10:I53),'2007'!U5:AE48)} -> 0 | P10: 0 | Q10: 0 | R10: 2.2225632 | S10: 6.6100896 | T10: 11.335767 | U10: 14.29526 | V10: 12.110348 | W10: 6.2705914 | X10: 3.7983811 | Y10: 2.0979735
A11: 18 | B11: 0 | C11: 0 | D11: 0 | E11: 0 | H11: 0 | I11: 0 | J11: 0 | K11: 0.047268779 | L11: 0 | N11: 2008 | O11: {=MMULT(TRANSPOSE(J10:J53),'2008'!U5:AE48)} -> 0 | P11: 0.11731674 | Q11: 3.2281877 | R11: 7.5110386 | S11: 14.91329 | T11: 16.402929 | U11: 13.381209 | V11: 7.6032424 | W11: 4.5983276 | X11: 2.7702475 | Y11: 2.4316562
A12: 19 | B12: 0 | C12: 0 | D12: 2.3828109 | E12: 0 | H12: 0 | I12: 0 | J12: 0 | K12: 0.047268779 | L12: 0.7401291 | N12: 2009 | O12: {=MMULT(TRANSPOSE(K10:K53),'2009'!U5:AE48)} -> 0.11817195 | P12: 0.20524601 | Q12: 0.24496524 | R12: 1.2086802 | S12: 7.0233316 | T12: 9.9355069 | U12: 12.641298 | V12: 9.7962831 | W12: 5.8471312 | X12: 2.8717279 | Y12: 1.3612131
A13: 20 | B13: 0 | C13: 0 | D13: 5.5598921 | E13: 0 | H13: 0 | I13: 0 | J13: 0 | K13: 0.14180634 | L13: 4.1235764 | N13: 2010 | O13: {=MMULT(TRANSPOSE(L10:L53),'2010'!U5:AE48)} -> 6.8461942 | P13: 5.1624424 | Q13: 1.4141126 | R13: 0.45185332 | S13: 1.5417601 | T13: 4.2013929 | U13: 6.2644382 | V13: 4.545727 | W13: 1.5591172 | X13: 0.81673784 | Y13: 0.30209351
A14: 21 | B14: 0 | C14: 0 | D14: 6.8836759 | E14: 0 | H14: 0 | I14: 0 | J14: 0 | K14: 0.047268779 | L14: 7.6127565
A15: 22 | B15: 0 | C15: 0.066554916 | D15: 4.7656218 | E15: 3.1874257 | H15: 0 | I15: 0 | J15: 0 | K15: 0 | L15: 8.2471528 | N15: =N3 -> 2000 | O15: =(O3)*1000 -> 129.82632 | P15: =(P3)*1000 -> 256.53335 | Q15: =(Q3)*1000 -> 367.48109 | R15: =(R3)*1000 -> 349.04976 | S15: =(S3)*1000 -> 270.49975 | T15: =(T3)*1000 -> 189.48879 | U15: =(U3)*1000 -> 128.87894 | V15: =(V3)*1000 -> 99.03367 | ... Y15: =(Y3)*1000 -> 28.417632
A16: 23 | B16: 0.011613398 | C16: 0.43260695 | D16: 11.384541 | E16: 15.937128 | H16: 0 | I16: 0 | J16: 0 | K16: 0.28361267 | L16: 7.7184892 | N16: =N4 -> 2001 | O16: =(O4)*1000 -> 8.2758621 | P16: =(P4)*1000 -> 349.7931 | Q16: =(Q4)*1000 -> 425.65517 | R16: =(R4)*1000 -> 129.37931 | S16: =(S4)*1000 -> 40.275862 | T16: =(T4)*1000 -> 20.413793 | U16: =(U4)*1000 -> 12.689655 | V16: =(V4)*1000 -> 7.1724138 | ... Y16: =(Y4)*1000 -> 1.6551724
A17: 24 | B17: 0.077422652 | C17: 0.49916187 | D17: 32.829839 | E17: 55.779949 | H17: 0 | I17: 0 | J17: 0 | K17: 0.33088145 | L17: 4.7579728 | N17: =N5 -> 2002 | O17: =(O5)*O321000 -> 0 | P17: =(P5)*1000 -> 21848.273 | Q17: =(Q5)*1000 -> 29357.773 | R17: =(R5)*1000 -> 28035.623 | S17: =(S5)*1000 -> 20059.345 | T17: =(T5)*1000 -> 8229.4265 | U17: =(U5)*1000 -> 1812.3907 | V17: =(V5)*1000 -> 619.77152 | W17: =(W5)*1000 -> 283.76494 | ... Y17: =(Y5)*1000 -> 108.30959
A18: 25 | B18: 0.15290974 | C18: 0.83193645 | D18: 41.566812 | E18: 94.029058 | H18: 0 | I18: 0 | J18: 0 | K18: 0.80356924 | L18: 2.2203873 | N18: =N6 -> 2003 | O18: =(O6)*1000 -> 41.237113 | P18: =(P6)*1000 -> 848.79725 | Q18: =(Q6)*1000 -> 106.52921 | R18: =(R6)*1000 -> 3.4364261 | S18: =(S6)*1000 -> 0 | T18: =(T6)*1000 -> 0 | U18: =(U6)*1000 -> 0 | V18: =(V6)*1000 -> 0 | ... Y18: =(Y6)*1000 -> 0
A19: 26 | B19: 0.34065967 | C19: 3.6106042 | D19: 69.895786 | E19: 87.654206 | H19: 0 | I19: 0 | J19: 0 | K19: 0.33088145 | L19: 1.6917237 | N19: =N7 -> 2004 | O19: =(O7)*1000 -> 0 | P19: =(P7)*1000 -> 0 | Q19: =(Q7)*1000 -> 0 | R19: =(R7)*1000 -> 0 | S19: =(S7)*1000 -> 0 | T19: =(T7)*1000 -> 0 | U19: =(U7)*1000 -> 0 | V19: =(V7)*1000 -> 0 | ... Y19: =(Y7)*1000 -> 0
A20: 27 | B20: 0.64841471 | C20: 7.9533124 | D20: 43.949623 | E20: 84.466781 | H20: 0.31148239 | I20: 0 | J20: 0 | K20: 0.094537558 | L20: 0.31719819 | N20: =N8 -> 2005 | O20: =(O8)*1000 -> 0 | P20: =(P8)*1000 -> 0 | Q20: =(Q8)*1000 -> 0 | R20: =(R8)*1000 -> 0 | S20: =(S8)*1000 -> 0 | T20: =(T8)*1000 -> 0 | U20: =(U8)*1000 -> 0 | V20: =(V8)*1000 -> 0 | ... Y20: =(Y8)*1000 -> 0
A21: 28 | B21: 0.60196112 | C21: 8.2028934 | D21: 36.271677 | E21: 71.717078 | H21: 1.2459296 | I21: 0 | J21: 0.23463349 | K21: 0.047268779 | L21: 0.52866364 | N21: =N9 -> 2006 | O21: =(O9)*1000 -> 0 | P21: =(P9)*1000 -> 0 | Q21: =(Q9)*1000 -> 16583.752 | R21: =(R9)*1000 -> 36825.212 | S21: =(S9)*1000 -> 39754.523 | T21: =(T9)*1000 -> 31592.39 | U21: =(U9)*1000 -> 17525.041 | V21: =(V9)*1000 -> 9189.2296 | ... Y21: =(Y9)*1000 -> 918.97619
A22: 29 | B22: 0.40646892 | C22: 7.9865899 | D22: 26.21092 | E22: 31.874257 | H22: 14.172449 | I22: 0 | J22: 1.8770679 | K22: 0 | L22: 0.21146546 | N22: =N10 -> 2007 | O22: =(O10)*1000 -> 0 | P22: =(P10)*1000 -> 0 | Q22: =(Q10)*1000 -> 0 | R22: =(R10)*1000 -> 2222.5632 | S22: =(S10)*1000 -> 6610.0896 | T22: =(T10)*1000 -> 11335.767 | U22: =(U10)*1000 -> 14295.26 | V22: =(V10)*1000 -> 12110.348 | ... Y22: =(Y10)*1000 -> 2097.9735
A23: 30 | B23: 0.37743543 | C23: 7.6371766 | D23: 12.708325 | E23: 11.15599 | H23: 47.656805 | I23: 0 | J23: 2.2290181 | K23: 0.047268779 | L23: 0 | N23: =N11 -> 2008 | O23: =(O11)*1000 -> 0 | P23: =(P11)*1000 -> 117.31674 | Q23: =(Q11)*1000 -> 3228.1877 | R23: =(R11)*1000 -> 7511.0386 | S23: =(S11)*1000 -> 14913.29 | T23: =(T11)*1000 -> 16402.929 | U23: =(U11)*1000 -> 13381.209 | V23: =(V11)*1000 -> 7603.2424 | ... Y23: =(Y11)*1000 -> 2431.6562
A24: 31 | B24: 0.27291485 | C24: 5.7403615 | D24: 10.855027 | E24: 1.5937128 | H24: 76.001703 | I24: 1.3379609 | J24: 5.513887 | K24: 0 | L24: 0 | N24: =N12 -> 2009 | O24: =(O12)*1000 -> 118.17195 | P24: =(P12)*1000 -> 205.24601 | Q24: =(Q12)*1000 -> 244.96524 | R24: =(R12)*1000 -> 1208.6802 | S24: =(S12)*1000 -> 7023.3316 | T24: =(T12)*1000 -> 9935.5069 | U24: =(U12)*1000 -> 12641.298 | V24: =(V12)*1000 -> 9796.2831 | ... Y24: =(Y12)*1000 -> 1361.2131
A25: 32 | B25: 0.19936333 | C25: 4.3094308 | D25: 7.1484327 | E25: 4.7811385 | H25: 77.403374 | I25: 6.6898045 | J25: 15.13386 | K25: 0 | L25: 0 | N25: =N13 -> 2010 | O25: =(O13)*1000 -> 6846.1942 | P25: =(P13)*1000 -> 5162.4424 | Q25: =(Q13)*1000 -> 1414.1126 | R25: =(R13)*1000 -> 451.85332 | S25: =(S13)*1000 -> 1541.7601 | T25: =(T13)*1000 -> 4201.3929 | U25: =(U13)*1000 -> 6264.4382 | V25: =(V13)*1000 -> 4545.727 | ... Y25: =(Y13)*1000 -> 302.09351
A26: 33 | B26: 0.22065456 | C26: 3.1114423 | D26: 6.3541624 | E26: 0 | H26: 58.71443 | I26: 11.038177 | J26: 20.999697 | K26: 0.047268779 | L26: 0
A27: 34 | B27: 0.1490386 | C27: 1.9966475 | D27: 1.8532974 | E27: 0 | H27: 35.353251 | I27: 11.707158 | J27: 19.943847 | K27: 0.70903168 | L27: 0
A28: 35 | B28: 0.15097417 | C28: 1.5806792 | D28: 1.3237838 | E28: 1.5937128 | H28: 20.713579 | I28: 14.048589 | J28: 22.290181 | K28: 8.8392616 | L28: 0
A29: 36 | B29: 0.090971616 | C29: 1.1147948 | D29: 2.1180541 | E29: 0 | H29: 18.533202 | I29: 15.721041 | J29: 19.943847 | K29: 32.473651 | L29: 1.3745255
A30: 37 | B30: 0.092907182 | C30: 0.69882661 | D30: 2.1180541 | E30: 0 | H30: 10.901884 | I30: 23.748806 | J30: 24.049933 | K30: 32.615457 | L30: 8.6700837
A31: 38 | B31: 0.12774738 | C31: 0.61563297 | D31: 0.52951353 | E31: 0 | H31: 7.0083537 | I31: 21.741865 | J31: 24.284566 | K31: 26.234172 | L31: 14.696849
A32: 39 | B32: 0.13161851 | C32: 0.68218789 | D32: 0.7942703 | E32: 0 | H32: 8.5657657 | I32: 18.731453 | J32: 14.312643 | K32: 17.300373 | L32: 12.79366
A33: 40 | B33: 0.13548964 | C33: 0.43260695 | D33: 1.3237838 | E33: 0 | H33: 3.5820475 | I33: 18.731453 | J33: 8.2121721 | K33: 13.235258 | L33: 8.2471528
A34: 41 | B34: 0.12581181 | C34: 0.46588441 | D34: 1.5885406 | E34: 0 | H34: 4.827977 | I34: 14.38308 | J34: 9.2680228 | K34: 10.682744 | L34: 5.075171
A35: 42 | B35: 0.11806954 | C35: 0.39932949 | D35: 0.7942703 | E35: 0 | H35: 3.1148239 | I35: 11.372668 | J35: 9.8546065 | K35: 8.2720363 | L35: 5.075171
A36: 43 | B36: 0.096778315 | C36: 0.36605204 | D36: 0.26475677 | E36: 0 | H36: 3.7377887 | I36: 10.034707 | J36: 7.6255884 | K36: 7.2793919 | L36: 3.2777146
A37: 44 | B37: 0.094842748 | C37: 0.36605204 | D37: 0.52951353 | E37: 0 | H37: 1.2459296 | I37: 9.7002166 | J37: 4.8099865 | K37: 5.1995657 | L37: 2.8547837
... A55: 62 | B55: 0.0019355663 | C55: 0 | D55: 0 | E55: 0 | H55: 0 | I55: 0 | J55: 0 | K55: 0 | L55: 0
B57: =SUM(B3:B55) -> 5.1040883 | C57: =SUM(C3:C55) -> 60.315392 | D57: =SUM(D3:D55) -> 340.74196 | E57: =SUM(E3:E55) -> 465.36415 | F57: =SUM(F3:F55) -> 0 | G57: =SUM(G3:G55) -> 0 | H57: =SUM(H3:H55) -> 397.14005 | I57: =SUM(I3:I55) -> 213.40476 | ... L57: =SUM(L3:L55) -> 115.56587

Sheet 2010
B2: CLAVE EDAD-TALLA JUREL 2010
B4: L.H. | C4: II | D4: III | E4: IV | F4: V | G4: VI | H4: VII | I4: VIII | J4: IX | K4: X | L4: XI | M4: XII | N4: XIII | O4: Total | U4: 2 | V4: 3 | W4: 4 | X4: 5 | Y4: 6 | Z4: 7 | AA4: 8 | AB4: 9 | AC4: 10 | AD4: 11 | AE4: 12
B5: =B6-1 -> 17 | T5: =B5 -> 17 | U5: =C5/C$49 -> 0 | V5: =D5/D$49 -> 0 | W5: =E5/E$49 -> 0 | X5: =F5/F$49 -> 0 | Y5: =G5/G$49 -> 0 | Z5: =H5/H$49 -> 0 | AA5: =I5/I$49 -> 0 | AB5: =J5/J$49 -> 0 | ... AE5: =M5/M$49 -> 0
B6: =B7-1 -> 18 | T6: =B6 -> 18 | U6: =C6/C$49 -> 0 | V6: =D6/D$49 -> 0 | W6: =E6/E$49 -> 0 | X6: =F6/F$49 -> 0 | Y6: =G6/G$49 -> 0 | Z6: =H6/H$49 -> 0 | AA6: =I6/I$49 -> 0 | AB6: =J6/J$49 -> 0 | ... AE6: =M6/M$49 -> 0
B7: =B8-1 -> 19 | T7: =B7 -> 19 | U7: =C7/C$49 -> 0 | V7: =D7/D$49 -> 0 | W7: =E7/E$49 -> 0 | X7: =F7/F$49 -> 0 | Y7: =G7/G$49 -> 0 | Z7: =H7/H$49 -> 0 | AA7: =I7/I$49 -> 0 | AB7: =J7/J$49 -> 0 | ... AE7: =M7/M$49 -> 0
B8: =B9-1 -> 20 | C8: 2 | D8: 4 | O8: =SUM(C8:N8) -> 6 | T8: =B8 -> 20 | U8: =C8/C$49 -> 0.25 | V8: =D8/D$49 -> 0.031746032 | W8: =E8/E$49 -> 0 | X8: =F8/F$49 -> 0 | Y8: =G8/G$49 -> 0 | Z8: =H8/H$49 -> 0 | AA8: =I8/I$49 -> 0 | AB8: =J8/J$49 -> 0 | ... AE8: =M8/M$49 -> 0
B9: =B10-1 -> 21 | C9: 3 | D9: 10 | E9: 1 | O9: =SUM(C9:N9) -> 14 | T9: =B9 -> 21 | U9: =C9/C$49 -> 0.375 | V9: =D9/D$49 -> 0.079365079 | W9: =E9/E$49 -> 0.0047393365 | X9: =F9/F$49 -> 0 | Y9: =G9/G$49 -> 0 | Z9: =H9/H$49 -> 0 | AA9: =I9/I$49 -> 0 | AB9: =J9/J$49 -> 0 | ... AE9: =M9/M$49 -> 0
B10: =B11-1 -> 22 | C10: 1 | D10: 20 | O10: =SUM(C10:N10) -> 21 | T10: =B10 -> 22 | U10: =C10/C$49 -> 0.125 | V10: =D10/D$49 -> 0.15873016 | W10: =E10/E$49 -> 0 | X10: =F10/F$49 -> 0 | Y10: =G10/G$49 -> 0 | Z10: =H10/H$49 -> 0 | AA10: =I10/I$49 -> 0 | AB10: =J10/J$49 -> 0 | ... AE10: =M10/M$49 -> 0
B11: =B12-1 -> 23 | C11: 2 | D11: 24 | E11: 6 | O11: =SUM(C11:N11) -> 32 | T11: =B11 -> 23 | U11: =C11/C$49 -> 0.25 | V11: =D11/D$49 -> 0.19047619 | W11: =E11/E$49 -> 0.028436019 | X11: =F11/F$49 -> 0 | Y11: =G11/G$49 -> 0 | Z11: =H11/H$49 -> 0 | AA11: =I11/I$49 -> 0 | AB11: =J11/J$49 -> 0 | ... AE11: =M11/M$49 -> 0
B12: =B13-1 -> 24 | D12: 30 | E12: 10 | F12: 2 | O12: =SUM(C12:N12) -> 42 | T12: =B12 -> 24 | U12: =C12/C$49 -> 0 | V12: =D12/D$49 -> 0.23809524 | W12: =E12/E$49 -> 0.047393365 | X12: =F12/F$49 -> 0.0089686099 | Y12: =G12/G$49 -> 0 | Z12: =H12/H$49 -> 0 | AA12: =I12/I$49 -> 0 | AB12: =J12/J$49 -> 0 | ... AE12: =M12/M$49 -> 0
B13: 25 | D13: 20 | E13: 32 | F13: 3 | O13: =SUM(C13:N13) -> 55 | T13: =B13 -> 25 | U13: =C13/C$49 -> 0 | V13: =D13/D$49 -> 0.15873016 | W13: =E13/E$49 -> 0.15165877 | X13: =F13/F$49 -> 0.013452915 | Y13: =G13/G$49 -> 0 | Z13: =H13/H$49 -> 0 | AA13: =I13/I$49 -> 0 | AB13: =J13/J$49 -> 0 | ... AE13: =M13/M$49 -> 0
B14: 26 | D14: 11 | E14: 55 | F14: 9 | O14: =SUM(C14:N14) -> 75 | T14: =B14 -> 26 | U14: =C14/C$49 -> 0 | V14: =D14/D$49 -> 0.087301587 | W14: =E14/E$49 -> 0.26066351 | X14: =F14/F$49 -> 0.040358744 | Y14: =G14/G$49 -> 0 | Z14: =H14/H$49 -> 0 | AA14: =I14/I$49 -> 0 | AB14: =J14/J$49 -> 0 | ... AE14: =M14/M$49 -> 0
B15: 27 | D15: 6 | E15: 39 | F15: 17 | G15: 1 | O15: =SUM(C15:N15) -> 63 | T15: =B15 -> 27 | U15: =C15/C$49 -> 0 | V15: =D15/D$49 -> 0.047619048 | W15: =E15/E$49 -> 0.18483412 | X15: =F15/F$49 -> 0.076233184 | Y15: =G15/G$49 -> 0.0039840637 | Z15: =H15/H$49 -> 0 | AA15: =I15/I$49 -> 0 | AB15: =J15/J$49 -> 0 | ... AE15: =M15/M$49 -> 0
B16: 28 | E16: 29 | F16: 39 | G16: 2 | O16: =SUM(C16:N16) -> 70 | T16: =B16 -> 28 | U16: =C16/C$49 -> 0 | V16: =D16/D$49 -> 0 | W16: =E16/E$49 -> 0.13744076 | X16: =F16/F$49 -> 0.17488789 | Y16: =G16/G$49 -> 0.0079681275 | Z16: =H16/H$49 -> 0 | AA16: =I16/I$49 -> 0 | AB16: =J16/J$49 -> 0 | ... AE16: =M16/M$49 -> 0
B17: 29 | E17: 24 | F17: 34 | G17: 24 | H17: 1 | O17: =SUM(C17:N17) -> 83 | T17: =B17 -> 29 | U17: =C17/C$49 -> 0 | V17: =D17/D$49 -> 0 | W17: =E17/E$49 -> 0.11374408 | X17: =F17/F$49 -> 0.15246637 | Y17: =G17/G$49 -> 0.09561753 | Z17: =H17/H$49 -> 0.00330033 | AA17: =I17/I$49 -> 0 | AB17: =J17/J$49 -> 0 | ... AE17: =M17/M$49 -> 0
B18: 30 | D18: 1 | E18: 6 | F18: 39 | G18: 41 | H18: 15 | I18: 2 | O18: =SUM(C18:N18) -> 104 | T18: =B18 -> 30 | U18: =C18/C$49 -> 0 | V18: =D18/D$49 -> 0.0079365079 | W18: =E18/E$49 -> 0.028436019 | X18: =F18/F$49 -> 0.17488789 | Y18: =G18/G$49 -> 0.16334661 | Z18: =H18/H$49 -> 0.04950495 | AA18: =I18/I$49 -> 0.0056980057 | AB18: =J18/J$49 -> 0 | ... AE18: =M18/M$49 -> 0
B19: 31 | E19: 1 | F19: 36 | G19: 37 | H19: 13 | O19: =SUM(C19:N19) -> 87 | T19: =B19 -> 31 | U19: =C19/C$49 -> 0 | V19: =D19/D$49 -> 0 | W19: =E19/E$49 -> 0.0047393365 | X19: =F19/F$49 -> 0.16143498 | Y19: =G19/G$49 -> 0.14741036 | Z19: =H19/H$49 -> 0.04290429 | AA19: =I19/I$49 -> 0 | AB19: =J19/J$49 -> 0 | ... AE19: =M19/M$49 -> 0
B20: 32 | E20: 2 | F20: 16 | G20: 30 | H20: 21 | I20: 2 | O20: =SUM(C20:N20) -> 71 | T20: =B20 -> 32 | U20: =C20/C$49 -> 0 | V20: =D20/D$49 -> 0 | W20: =E20/E$49 -> 0.009478673 | X20: =F20/F$49 -> 0.071748879 | Y20: =G20/G$49 -> 0.11952191 | Z20: =H20/H$49 -> 0.069306931 | AA20: =I20/I$49 -> 0.0056980057 | AB20: =J20/J$49 -> 0 | ... AE20: =M20/M$49 -> 0
B21: 33 | E21: 2 | F21: 8 | G21: 27 | H21: 27 | I21: 2 | O21: =SUM(C21:N21) -> 66 | T21: =B21 -> 33 | U21: =C21/C$49 -> 0 | V21: =D21/D$49 -> 0 | W21: =E21/E$49 -> 0.009478673 | X21: =F21/F$49 -> 0.035874439 | Y21: =G21/G$49 -> 0.10756972 | Z21: =H21/H$49 -> 0.089108911 | AA21: =I21/I$49 -> 0.0056980057 | AB21: =J21/J$49 -> 0 | ... AE21: =M21/M$49 -> 0
B22: 34 | E22: 4 | F22: 6 | G22: 23 | H22: 27 | I22: 4 | O22: =SUM(C22:N22) -> 64 | T22: =B22 -> 34 | U22: =C22/C$49 -> 0 | V22: =D22/D$49 -> 0 | W22: =E22/E$49 -> 0.018957346 | X22: =F22/F$49 -> 0.02690583 | Y22: =G22/G$49 -> 0.091633466 | Z22: =H22/H$49 -> 0.089108911 | AA22: =I22/I$49 -> 0.011396011 | AB22: =J22/J$49 -> 0 | ... AE22: =M22/M$49 -> 0
B23: 35 | F23: 8 | G23: 21 | H23: 34 | I23: 12 | O23: =SUM(C23:N23) -> 75 | T23: =B23 -> 35 | U23: =C23/C$49 -> 0 | V23: =D23/D$49 -> 0 | W23: =E23/E$49 -> 0 | X23: =F23/F$49 -> 0.035874439 | Y23: =G23/G$49 -> 0.083665339 | Z23: =H23/H$49 -> 0.11221122 | AA23: =I23/I$49 -> 0.034188034 | AB23: =J23/J$49 -> 0 | ... AE23: =M23/M$49 -> 0
B24: 36 | F24: 3 | G24: 13 | H24: 36 | I24: 27 | J24: 2 | O24: =SUM(C24:N24) -> 81 | T24: =B24 -> 36 | U24: =C24/C$49 -> 0 | V24: =D24/D$49 -> 0 | W24: =E24/E$49 -> 0 | X24: =F24/F$49 -> 0.013452915 | Y24: =G24/G$49 -> 0.051792829 | Z24: =H24/H$49 -> 0.11881188 | AA24: =I24/I$49 -> 0.076923077 | AB24: =J24/J$49 -> 0.0073800738 | ... AE24: =M24/M$49 -> 0
B25: 37 | F25: 2 | G25: 13 | H25: 32 | I25: 32 | J25: 7 | O25: =SUM(C25:N25) -> 86 | T25: =B25 -> 37 | U25: =C25/C$49 -> 0 | V25: =D25/D$49 -> 0 | W25: =E25/E$49 -> 0 | X25: =F25/F$49 -> 0.0089686099 | Y25: =G25/G$49 -> 0.051792829 | Z25: =H25/H$49 -> 0.10561056 | AA25: =I25/I$49 -> 0.091168091 | AB25: =J25/J$49 -> 0.025830258 | ... AE25: =M25/M$49 -> 0
B26: 38 | F26: 1 | G26: 11 | H26: 26 | I26: 32 | J26: 13 | O26: =SUM(C26:N26) -> 83 | T26: =B26 -> 38 | U26: =C26/C$49 -> 0 | V26: =D26/D$49 -> 0 | W26: =E26/E$49 -> 0 | X26: =F26/F$49 -> 0.0044843049 | Y26: =G26/G$49 -> 0.043824701 | Z26: =H26/H$49 -> 0.085808581 | AA26: =I26/I$49 -> 0.091168091 | AB26: =J26/J$49 -> 0.04797048 | ... AE26: =M26/M$49 -> 0
B27: 39 | G27: 6 | H27: 19 | I27: 41 | J27: 17 | K27: 1 | O27: =SUM(C27:N27) -> 84 | T27: =B27 -> 39 | U27: =C27/C$49 -> 0 | V27: =D27/D$49 -> 0 | W27: =E27/E$49 -> 0 | X27: =F27/F$49 -> 0 | Y27: =G27/G$49 -> 0.023904382 | Z27: =H27/H$49 -> 0.062706271 | AA27: =I27/I$49 -> 0.11680912 | AB27: =J27/J$49 -> 0.062730627 | ... AE27: =M27/M$49 -> 0
B28: 40 | G28: 1 | H28: 23 | I28: 34 | J28: 20 | K28: 5 | O28: =SUM(C28:N28) -> 83 | T28: =B28 -> 40 | U28: =C28/C$49 -> 0 | V28: =D28/D$49 -> 0 | W28: =E28/E$49 -> 0 | X28: =F28/F$49 -> 0 | Y28: =G28/G$49 -> 0.0039840637 | Z28: =H28/H$49 -> 0.075907591 | AA28: =I28/I$49 -> 0.096866097 | AB28: =J28/J$49 -> 0.073800738 | ... AE28: =M28/M$49 -> 0
B29: 41 | H29: 15 | I29: 40 | J29: 17 | K29: 4 | L29: 1 | O29: =SUM(C29:N29) -> 77 | T29: =B29 -> 41 | U29: =C29/C$49 -> 0 | V29: =D29/D$49 -> 0 | W29: =E29/E$49 -> 0 | X29: =F29/F$49 -> 0 | Y29: =G29/G$49 -> 0 | Z29: =H29/H$49 -> 0.04950495 | AA29: =I29/I$49 -> 0.11396011 | AB29: =J29/J$49 -> 0.062730627 | ... AE29: =M29/M$49 -> 0
B30: 42 | H30: 5 | I30: 24 | J30: 29 | K30: 7 | O30: =SUM(C30:N30) -> 65 | T30: =B30 -> 42 | U30: =C30/C$49 -> 0 | V30: =D30/D$49 -> 0 | W30: =E30/E$49 -> 0 | X30: =F30/F$49 -> 0 | Y30: =G30/G$49 -> 0 | Z30: =H30/H$49 -> 0.01650165 | AA30: =I30/I$49 -> 0.068376068 | AB30: =J30/J$49 -> 0.10701107 | ... AE30: =M30/M$49 -> 0
B31: 43 | G31: 1 | H31: 7 | I31: 30 | J31: 24 | K31: 9 | O31: =SUM(C31:N31) -> 71 | T31: =B31 -> 43 | U31: =C31/C$49 -> 0 | V31: =D31/D$49 -> 0 | W31: =E31/E$49 -> 0 | X31: =F31/F$49 -> 0 | Y31: =G31/G$49 -> 0.0039840637 | Z31: =H31/H$49 -> 0.02310231 | AA31: =I31/I$49 -> 0.085470085 | AB31: =J31/J$49 -> 0.088560886 | ... AE31: =M31/M$49 -> 0
B32: 44 | I32: 21 | J32: 17 | K32: 14 | L32: 3 | O32: =SUM(C32:N32) -> 55 | T32: =B32 -> 44 | U32: =C32/C$49 -> 0 | V32: =D32/D$49 -> 0 | W32: =E32/E$49 -> 0 | X32: =F32/F$49 -> 0 | Y32: =G32/G$49 -> 0 | Z32: =H32/H$49 -> 0 | AA32: =I32/I$49 -> 0.05982906 | AB32: =J32/J$49 -> 0.062730627 | ... AE32: =M32/M$49 -> 0
B33: 45 | H33: 1 | I33: 16 | J33: 20 | K33: 9 | L33: 2 | M33: 2 | O33: =SUM(C33:N33) -> 50 | T33: =B33 -> 45 | U33: =C33/C$49 -> 0 | V33: =D33/D$49 -> 0 | W33: =E33/E$49 -> 0 | X33: =F33/F$49 -> 0 | Y33: =G33/G$49 -> 0 | Z33: =H33/H$49 -> 0.00330033 | AA33: =I33/I$49 -> 0.045584046 | AB33: =J33/J$49 -> 0.073800738 | ... AE33: =M33/M$49 -> 0.028571429
B34: 46 | H34: 1 | I34: 14 | J34: 15 | K34: 15 | L34: 4 | O34: =SUM(C34:N34) -> 49 | T34: =B34 -> 46 | U34: =C34/C$49 -> 0 | V34: =D34/D$49 -> 0 | W34: =E34/E$49 -> 0 | X34: =F34/F$49 -> 0 | Y34: =G34/G$49 -> 0 | Z34: =H34/H$49 -> 0.00330033 | AA34: =I34/I$49 -> 0.03988604 | AB34: =J34/J$49 -> 0.055350554 | ... AE34: =M34/M$49 -> 0
B35: 47 | I35: 9 | J35: 15 | K35: 12 | L35: 13 | M35: 1 | O35: =SUM(C35:N35) -> 50 | T35: =B35 -> 47 | U35: =C35/C$49 -> 0 | V35: =D35/D$49 -> 0 | W35: =E35/E$49 -> 0 | X35: =F35/F$49 -> 0 | Y35: =G35/G$49 -> 0 | Z35: =H35/H$49 -> 0 | AA35: =I35/I$49 -> 0.025641026 | AB35: =J35/J$49 -> 0.055350554 | ... AE35: =M35/M$49 -> 0.014285714
B36: 48 | I36: 3 | J36: 18 | K36: 20 | L36: 7 | O36: =SUM(C36:N36) -> 48 | T36: =B36 -> 48 | U36: =C36/C$49 -> 0 | V36: =D36/D$49 -> 0 | W36: =E36/E$49 -> 0 | X36: =F36/F$49 -> 0 | Y36: =G36/G$49 -> 0 | Z36: =H36/H$49 -> 0 | AA36: =I36/I$49 -> 0.0085470085 | AB36: =J36/J$49 -> 0.066420664 | ... AE36: =M36/M$49 -> 0
B37: 49 | I37: 2 | J37: 13 | K37: 12 | L37: 15 | O37: =SUM(C37:N37) -> 42 | T37: =B37 -> 49 | U37: =C37/C$49 -> 0 | V37: =D37/D$49 -> 0 | W37: =E37/E$49 -> 0 | X37: =F37/F$49 -> 0 | Y37: =G37/G$49 -> 0 | Z37: =H37/H$49 -> 0 | AA37: =I37/I$49 -> 0.0056980057 | AB37: =J37/J$49 -> 0.04797048 | ... AE37: =M37/M$49 -> 0
B38: 50 | J38: 15 | K38: 17 | L38: 9 | O38: =SUM(C38:N38) -> 41 | T38: =B38 -> 50 | U38: =C38/C$49 -> 0 | V38: =D38/D$49 -> 0 | W38: =E38/E$49 -> 0 | X38: =F38/F$49 -> 0 | Y38: =G38/G$49 -> 0 | Z38: =H38/H$49 -> 0 | AA38: =I38/I$49 -> 0 | AB38: =J38/J$49 -> 0.055350554 | ... AE38: =M38/M$49 -> 0
B39: 51 | J39: 13 | K39: 11 | L39: 11 | M39: 3 | O39: =SUM(C39:N39) -> 38 | T39: =B39 -> 51 | U39: =C39/C$49 -> 0 | V39: =D39/D$49 -> 0 | W39: =E39/E$49 -> 0 | X39: =F39/F$49 -> 0 | Y39: =G39/G$49 -> 0 | Z39: =H39/H$49 -> 0 | AA39: =I39/I$49 -> 0 | AB39: =J39/J$49 -> 0.04797048 | ... AE39: =M39/M$49 -> 0.042857143
B40: 52 | J40: 4 | K40: 13 | L40: 14 | M40: 7 | O40: =SUM(C40:N40) -> 38 | T40: =B40 -> 52 | U40: =C40/C$49 -> 0 | V40: =D40/D$49 -> 0 | W40: =E40/E$49 -> 0 | X40: =F40/F$49 -> 0 | Y40: =G40/G$49 -> 0 | Z40: =H40/H$49 -> 0 | AA40: =I40/I$49 -> 0 | AB40: =J40/J$49 -> 0.014760148 | ... AE40: =M40/M$49 -> 0.1
B41: 53 | I41: 4 | J41: 7 | K41: 21 | L41: 8 | O41: =SUM(C41:N41) -> 40 | T41: =B41 -> 53 | U41: =C41/C$49 -> 0 | V41: =D41/D$49 -> 0 | W41: =E41/E$49 -> 0 | X41: =F41/F$49 -> 0 | Y41: =G41/G$49 -> 0 | Z41: =H41/H$49 -> 0 | AA41: =I41/I$49 -> 0.011396011 | AB41: =J41/J$49 -> 0.025830258 | ... AE41: =M41/M$49 -> 0
B42: 54 | J42: 2 | K42: 12 | L42: 12 | M42: 6 | O42: =SUM(C42:N42) -> 32 | T42: =B42 -> 54 | U42: =C42/C$49 -> 0 | V42: =D42/D$49 -> 0 | W42: =E42/E$49 -> 0 | X42: =F42/F$49 -> 0 | Y42: =G42/G$49 -> 0 | Z42: =H42/H$49 -> 0 | AA42: =I42/I$49 -> 0 | AB42: =J42/J$49 -> 0.0073800738 | ... AE42: =M42/M$49 -> 0.085714286
...

Sheet 2009
B2: CLAVE EDAD-TALLA JUREL 2009
B4: L.H. | C4: II | D4: III | E4: IV | F4: V | G4: VI | H4: VII | I4: VIII | J4: IX | K4: X | L4: XI | M4: XII | N4: XIII | O4: XIV | P4: Total | U4: 2 | V4: 3 | W4: 4 | X4: 5 | Y4: 6 | Z4: 7 | AA4: 8 | AB4: 9 | AC4: 10 | AD4: 11 | AE4: 12
B5: =B6-1 -> 17 | T5: =B5 -> 17 | U5: =C5/C$49 -> 0 | V5: =D5/D$49 -> 0 | W5: =E5/E$49 -> 0 | X5: =F5/F$49 -> 0 | Y5: =G5/G$49 -> 0 | Z5: =H5/H$49 -> 0 | AA5: =I5/I$49 -> 0 | AB5: =J5/J$49 -> 0 | ... AE5: =M5/M$49 -> 0
B6: =B7-1 -> 18 | C6: 1 | D6: 1 | P6: =SUM(C6:O6) -> 2 | T6: =B6 -> 18 | U6: =C6/C$49 -> 0.0625 | V6: =D6/D$49 -> 0.013157895 | W6: =E6/E$49 -> 0 | X6: =F6/F$49 -> 0 | Y6: =G6/G$49 -> 0 | Z6: =H6/H$49 -> 0 | AA6: =I6/I$49 -> 0 | AB6: =J6/J$49 -> 0 | ... AE6: =M6/M$49 -> 0
B7: =B8-1 -> 19 | D7: 2 | P7: =SUM(C7:O7) -> 2 | T7: =B7 -> 19 | U7: =C7/C$49 -> 0 | V7: =D7/D$49 -> 0.026315789 | W7: =E7/E$49 -> 0 | X7: =F7/F$49 -> 0 | Y7: =G7/G$49 -> 0 | Z7: =H7/H$49 -> 0 | AA7: =I7/I$49 -> 0 | AB7: =J7/J$49 -> 0 | ... AE7: =M7/M$49 -> 0
B8: =B9-1 -> 20 | C8: 4 | D8: 10 | E8: 4 | P8: =SUM(C8:O8) -> 18 | T8: =B8 -> 20 | U8: =C8/C$49 -> 0.25 | V8: =D8/D$49 -> 0.13157895 | W8: =E8/E$49 -> 0.025157233 | X8: =F8/F$49 -> 0 | Y8: =G8/G$49 -> 0 | Z8: =H8/H$49 -> 0 | AA8: =I8/I$49 -> 0 | AB8: =J8/J$49 -> 0 | ... AE8: =M8/M$49 -> 0
B9: =B10-1 -> 21 | C9: 3 | D9: 16 | E9: 17 | P9: =SUM(C9:O9) -> 36 | T9: =B9 -> 21 | U9: =C9/C$49 -> 0.1875 | V9: =D9/D$49 -> 0.21052632 | W9: =E9/E$49 -> 0.10691824 | X9: =F9/F$49 -> 0 | Y9: =G9/G$49 -> 0 | Z9: =H9/H$49 -> 0 | AA9: =I9/I$49 -> 0 | AB9: =J9/J$49 -> 0 | ... AE9: =M9/M$49 -> 0
B10: =B11-1 -> 22 | C10: 4 | D10: 11 | E10: 24 | F10: 2 | P10: =SUM(C10:O10) -> 41 | T10: =B10 -> 22 | U10: =C10/C$49 -> 0.25 | V10: =D10/D$49 -> 0.14473684 | W10: =E10/E$49 -> 0.1509434 | X10: =F10/F$49 -> 0.014814815 | Y10: =G10/G$49 -> 0 | Z10: =H10/H$49 -> 0 | AA10: =I10/I$49 -> 0 | AB10: =J10/J$49 -> 0 | ... AE10: =M10/M$49 -> 0
B11: =B12-1 -> 23 | C11: 4 | D11: 13 | E11: 35 | F11: 4 | P11: =SUM(C11:O11) -> 56 | T11: =B11 -> 23 | U11: =C11/C$49 -> 0.25 | V11: =D11/D$49 -> 0.17105263 | W11: =E11/E$49 -> 0.22012579 | X11: =F11/F$49 -> 0.02962963 | Y11: =G11/G$49 -> 0 | Z11: =H11/H$49 -> 0 | AA11: =I11/I$49 -> 0 | AB11: =J11/J$49 -> 0 | ... AE11: =M11/M$49 -> 0
B12: =B13-1 -> 24 | D12: 7 | E12: 25 | F12: 6 | P12: =SUM(C12:O12) -> 38 | T12: =B12 -> 24 | U12: =C12/C$49 -> 0 | V12: =D12/D$49 -> 0.092105263 | W12: =E12/E$49 -> 0.1572327 | X12: =F12/F$49 -> 0.044444444 | Y12: =G12/G$49 -> 0 | Z12: =H12/H$49 -> 0 | AA12: =I12/I$49 -> 0 | AB12: =J12/J$49 -> 0 | ... AE12: =M12/M$49 -> 0
B13: 25 | D13: 6 | E13: 17 | F13: 11 | P13: =SUM(C13:O13) -> 34 | T13: =B13 -> 25 | U13: =C13/C$49 -> 0 | V13: =D13/D$49 -> 0.078947368 | W13: =E13/E$49 -> 0.10691824 | X13: =F13/F$49 -> 0.081481481 | Y13: =G13/G$49 -> 0 | Z13: =H13/H$49 -> 0 | AA13: =I13/I$49 -> 0 | AB13: =J13/J$49 -> 0 | ... AE13: =M13/M$49 -> 0
B14: 26 | D14: 7 | E14: 13 | F14: 10 | P14: =SUM(C14:O14) -> 30 | T14: =B14 -> 26 | U14: =C14/C$49 -> 0 | V14: =D14/D$49 -> 0.092105263 | W14: =E14/E$49 -> 0.081761006 | X14: =F14/F$49 -> 0.074074074 | Y14: =G14/G$49 -> 0 | Z14: =H14/H$49 -> 0 | AA14: =I14/I$49 -> 0 | AB14: =J14/J$49 -> 0 | ... AE14: =M14/M$49 -> 0
B15: 27 | D15: 1 | E15: 11 | F15: 12 | P15: =SUM(C15:O15) -> 24 | T15: =B15 -> 27 | U15: =C15/C$49 -> 0 | V15: =D15/D$49 -> 0.013157895 | W15: =E15/E$49 -> 0.06918239 | X15: =F15/F$49 -> 0.088888889 | Y15: =G15/G$49 -> 0 | Z15: =H15/H$49 -> 0 | AA15: =I15/I$49 -> 0 | AB15: =J15/J$49 -> 0 | ... AE15: =M15/M$49 -> 0
B16: 28 | D16: 1 | E16: 5 | F16: 16 | G16: 14 | P16: =SUM(C16:O16) -> 36 | T16: =B16 -> 28 | U16: =C16/C$49 -> 0 | V16: =D16/D$49 -> 0.013157895 | W16: =E16/E$49 -> 0.031446541 | X16: =F16/F$49 -> 0.11851852 | Y16: =G16/G$49 -> 0.07486631 | Z16: =H16/H$49 -> 0 | AA16: =I16/I$49 -> 0 | AB16: =J16/J$49 -> 0 | ... AE16: =M16/M$49 -> 0
B17: 29 | D17: 1 | E17: 2 | F17: 17 | G17: 17 | H17: 11 | I17: 1 | P17: =SUM(C17:O17) -> 49 | T17: =B17 -> 29 | U17: =C17/C$49 -> 0 | V17: =D17/D$49 -> 0.013157895 | W17: =E17/E$49 -> 0.012578616 | X17: =F17/F$49 -> 0.12592593 | Y17: =G17/G$49 -> 0.090909091 | Z17: =H17/H$49 -> 0.032448378 | AA17: =I17/I$49 -> 0.0029154519 | AB17: =J17/J$49 -> 0 | ... AE17: =M17/M$49 -> 0
B18: 30 | E18: 2 | F18: 11 | G18: 27 | H18: 25 | I18: 1 | P18: =SUM(C18:O18) -> 66 | T18: =B18 -> 30 | U18: =C18/C$49 -> 0 | V18: =D18/D$49 -> 0 | W18: =E18/E$49 -> 0.012578616 | X18: =F18/F$49 -> 0.081481481 | Y18: =G18/G$49 -> 0.14438503 | Z18: =H18/H$49 -> 0.073746313 | AA18: =I18/I$49 -> 0.0029154519 | AB18: =J18/J$49 -> 0 | ... AE18: =M18/M$49 -> 0
B19: 31 | E19: 2 | F19: 13 | G19: 21 | H19: 25 | I19: 8 | P19: =SUM(C19:O19) -> 69 | T19: =B19 -> 31 | U19: =C19/C$49 -> 0 | V19: =D19/D$49 -> 0 | W19: =E19/E$49 -> 0.012578616 | X19: =F19/F$49 -> 0.096296296 | Y19: =G19/G$49 -> 0.11229947 | Z19: =H19/H$49 -> 0.073746313 | AA19: =I19/I$49 -> 0.023323615 | AB19: =J19/J$49 -> 0 | ... AE19: =M19/M$49 -> 0
B20: 32 | E20: 1 | F20: 13 | G20: 16 | H20: 29 | I20: 7 | P20: =SUM(C20:O20) -> 66 | T20: =B20 -> 32 | U20: =C20/C$49 -> 0 | V20: =D20/D$49 -> 0 | W20: =E20/E$49 -> 0.0062893082 | X20: =F20/F$49 -> 0.096296296 | Y20: =G20/G$49 -> 0.085561497 | Z20: =H20/H$49 -> 0.085545723 | AA20: =I20/I$49 -> 0.020408163 | AB20: =J20/J$49 -> 0 | ... AE20: =M20/M$49 -> 0
B21: 33 | E21: 1 | F21: 7 | G21: 17 | H21: 40 | I21: 17 | J21: 1 | P21: =SUM(C21:O21) -> 83 | T21: =B21 -> 33 | U21: =C21/C$49 -> 0 | V21: =D21/D$49 -> 0 | W21: =E21/E$49 -> 0.0062893082 | X21: =F21/F$49 -> 0.051851852 | Y21: =G21/G$49 -> 0.090909091 | Z21: =H21/H$49 -> 0.1179941 | AA21: =I21/I$49 -> 0.049562682 | AB21: =J21/J$49 -> 0.0028985507 | ... AE21: =M21/M$49 -> 0
B22: 34 | F22: 5 | G22: 22 | H22: 37 | I22: 22 | J22: 3 | P22: =SUM(C22:O22) -> 89 | T22: =B22 -> 34 | U22: =C22/C$49 -> 0 | V22: =D22/D$49 -> 0 | W22: =E22/E$49 -> 0 | X22: =F22/F$49 -> 0.037037037 | Y22: =G22/G$49 -> 0.11764706 | Z22: =H22/H$49 -> 0.10914454 | AA22: =I22/I$49 -> 0.064139942 | AB22: =J22/J$49 -> 0.0086956522 | ... AE22: =M22/M$49 -> 0
B23: 35 | F23: 5 | G23: 16 | H23: 37 | I23: 20 | J23: 8 | K23: 3 | P23: =SUM(C23:O23) -> 89 | T23: =B23 -> 35 | U23: =C23/C$49 -> 0 | V23: =D23/D$49 -> 0 | W23: =E23/E$49 -> 0 | X23: =F23/F$49 -> 0.037037037 | Y23: =G23/G$49 -> 0.085561497 | Z23: =H23/H$49 -> 0.10914454 | AA23: =I23/I$49 -> 0.058309038 | AB23: =J23/J$49 -> 0.023188406 | ... AE23: =M23/M$49 -> 0
B24: 36 | F24: 3 | G24: 15 | H24: 22 | I24: 26 | J24: 18 | K24: 1 | P24: =SUM(C24:O24) -> 85 | T24: =B24 -> 36 | U24: =C24/C$49 -> 0 | V24: =D24/D$49 -> 0 | W24: =E24/E$49 -> 0 | X24: =F24/F$49 -> 0.022222222 | Y24: =G24/G$49 -> 0.080213904 | Z24: =H24/H$49 -> 0.064896755 | AA24: =I24/I$49 -> 0.075801749 | AB24: =J24/J$49 -> 0.052173913 | ... AE24: =M24/M$49 -> 0
B25: 37 | G25: 14 | H25: 32 | I25: 27 | J25: 17 | K25: 6 | P25: =SUM(C25:O25) -> 96 | T25: =B25 -> 37 | U25: =C25/C$49 -> 0 | V25: =D25/D$49 -> 0 | W25: =E25/E$49 -> 0 | X25: =F25/F$49 -> 0 | Y25: =G25/G$49 -> 0.07486631 | Z25: =H25/H$49 -> 0.09439528 | AA25: =I25/I$49 -> 0.078717201 | AB25: =J25/J$49 -> 0.049275362 | ... AE25: =M25/M$49 -> 0
B26: 38 | G26: 8 | H26: 24 | I26: 29 | J26: 10 | K26: 5 | P26: =SUM(C26:O26) -> 76 | T26: =B26 -> 38 | U26: =C26/C$49 -> 0 | V26: =D26/D$49 -> 0 | W26: =E26/E$49 -> 0 | X26: =F26/F$49 -> 0 | Y26: =G26/G$49 -> 0.042780749 | Z26: =H26/H$49 -> 0.07079646 | AA26: =I26/I$49 -> 0.084548105 | AB26: =J26/J$49 -> 0.028985507 | ... AE26: =M26/M$49 -> 0
B27: 39 | H27: 16 | I27: 32 | J27: 23 | K27: 11 | P27: =SUM(C27:O27) -> 82 | T27: =B27 -> 39 | U27: =C27/C$49 -> 0 | V27: =D27/D$49 -> 0 | W27: =E27/E$49 -> 0 | X27: =F27/F$49 -> 0 | Y27: =G27/G$49 -> 0 | Z27: =H27/H$49 -> 0.04719764 | AA27: =I27/I$49 -> 0.093294461 | AB27: =J27/J$49 -> 0.066666667 | ... AE27: =M27/M$49 -> 0
B28: 40 | H28: 10 | I28: 30 | J28: 23 | K28: 12 | L28: 3 | P28: =SUM(C28:O28) -> 78 | T28: =B28 -> 40 | U28: =C28/C$49 -> 0 | V28: =D28/D$49 -> 0 | W28: =E28/E$49 -> 0 | X28: =F28/F$49 -> 0 | Y28: =G28/G$49 -> 0 | Z28: =H28/H$49 -> 0.029498525 | AA28: =I28/I$49 -> 0.087463557 | AB28: =J28/J$49 -> 0.066666667 | ... AE28: =M28/M$49 -> 0
B29: 41 | H29: 7 | I29: 22 | J29: 23 | K29: 19 | L29: 2 | P29: =SUM(C29:O29) -> 73 | T29: =B29 -> 41 | U29: =C29/C$49 -> 0 | V29: =D29/D$49 -> 0 | W29: =E29/E$49 -> 0 | X29: =F29/F$49 -> 0 | Y29: =G29/G$49 -> 0 | Z29: =H29/H$49 -> 0.020648968 | AA29: =I29/I$49 -> 0.064139942 | AB29: =J29/J$49 -> 0.066666667 | ... AE29: =M29/M$49 -> 0
B30: 42 | H30: 8 | I30: 17 | J30: 34 | K30: 14 | L30: 8 | P30: =SUM(C30:O30) -> 81 | T30: =B30 -> 42 | U30: =C30/C$49 -> 0 | V30: =D30/D$49 -> 0 | W30: =E30/E$49 -> 0 | X30: =F30/F$49 -> 0 | Y30: =G30/G$49 -> 0 | Z30: =H30/H$49 -> 0.02359882 | AA30: =I30/I$49 -> 0.049562682 | AB30: =J30/J$49 -> 0.098550725 | ... AE30: =M30/M$49 -> 0
B31: 43 | H31: 4 | I31: 15 | J31: 33 | K31: 15 | L31: 11 | P31: =SUM(C31:O31) -> 78 | T31: =B31 -> 43 | U31: =C31/C$49 -> 0 | V31: =D31/D$49 -> 0 | W31: =E31/E$49 -> 0 | X31: =F31/F$49 -> 0 | Y31: =G31/G$49 -> 0 | Z31: =H31/H$49 -> 0.01179941 | AA31: =I31/I$49 -> 0.043731778 | AB31: =J31/J$49 -> 0.095652174 | ... AE31: =M31/M$49 -> 0
B32: 44 | H32: 3 | I32: 16 | J32: 22 | K32: 23 | L32: 9 | M32: 4 | P32: =SUM(C32:O32) -> 77 | T32: =B32 -> 44 | U32: =C32/C$49 -> 0 | V32: =D32/D$49 -> 0 | W32: =E32/E$49 -> 0 | X32: =F32/F$49 -> 0 | Y32: =G32/G$49 -> 0 | Z32: =H32/H$49 -> 0.0088495575 | AA32: =I32/I$49 -> 0.04664723 | AB32: =J32/J$49 -> 0.063768116 | ... AE32: =M32/M$49 -> 0.054054054
B33: 45 | H33: 3 | I33: 10 | J33: 29 | K33: 33 | L33: 9 | M33: 1 | P33: =SUM(C33:O33) -> 85 | T33: =B33 -> 45 | U33: =C33/C$49 -> 0 | V33: =D33/D$49 -> 0 | W33: =E33/E$49 -> 0 | X33: =F33/F$49 -> 0 | Y33: =G33/G$49 -> 0 | Z33: =H33/H$49 -> 0.0088495575 | AA33: =I33/I$49 -> 0.029154519 | AB33: =J33/J$49 -> 0.084057971 | ... AE33: =M33/M$49 -> 0.013513514
B34: 46 | H34: 2 | I34: 13 | J34: 25 | K34: 20 | L34: 12 | M34: 7 | P34: =SUM(C34:O34) -> 79 | T34: =B34 -> 46 | U34: =C34/C$49 -> 0 | V34: =D34/D$49 -> 0 | W34: =E34/E$49 -> 0 | X34: =F34/F$49 -> 0 | Y34: =G34/G$49 -> 0 | Z34: =H34/H$49 -> 0.005899705 | AA34: =I34/I$49 -> 0.037900875 | AB34: =J34/J$49 -> 0.072463768 | ... AE34: =M34/M$49 -> 0.094594595
B35: 47 | H35: 4 | I35: 11 | J35: 18 | K35: 26 | L35: 14 | M35: 2 | N35: 3 | P35: =SUM(C35:O35) -> 78 | T35: =B35 -> 47 | U35: =C35/C$49 -> 0 | V35: =D35/D$49 -> 0 | W35: =E35/E$49 -> 0 | X35: =F35/F$49 -> 0 | Y35: =G35/G$49 -> 0 | Z35: =H35/H$49 -> 0.01179941 | AA35: =I35/I$49 -> 0.032069971 | AB35: =J35/J$49 -> 0.052173913 | ... AE35: =M35/M$49 -> 0.027027027
B36: 48 | I36: 5 | J36: 15 | K36: 16 | L36: 21 | M36: 5 | N36: 3 | P36: =SUM(C36:O36) -> 65 | T36: =B36 -> 48 | U36: =C36/C$49 -> 0 | V36: =D36/D$49 -> 0 | W36: =E36/E$49 -> 0 | X36: =F36/F$49 -> 0 | Y36: =G36/G$49 -> 0 | Z36: =H36/H$49 -> 0 | AA36: =I36/I$49 -> 0.014577259 | AB36: =J36/J$49 -> 0.043478261 | ... AE36: =M36/M$49 -> 0.067567568
B37: 49 | I37: 7 | J37: 12 | K37: 22 | L37: 12 | M37: 12 | N37: 1 | P37: =SUM(C37:O37) -> 66 | T37: =B37 -> 49 | U37: =C37/C$49 -> 0 | V37: =D37/D$49 -> 0 | W37: =E37/E$49 -> 0 | X37: =F37/F$49 -> 0 | Y37: =G37/G$49 -> 0 | Z37: =H37/H$49 -> 0 | AA37: =I37/I$49 -> 0.020408163 | AB37: =J37/J$49 -> 0.034782609 | ... AE37: =M37/M$49 -> 0.16216216
B38: 50 | I38: 2 | J38: 8 | K38: 20 | L38: 14 | M38: 11 | N38: 2 | P38: =SUM(C38:O38) -> 57 | T38: =B38 -> 50 | U38: =C38/C$49 -> 0 | V38: =D38/D$49 -> 0 | W38: =E38/E$49 -> 0 | X38: =F38/F$49 -> 0 | Y38: =G38/G$49 -> 0 | Z38: =H38/H$49 -> 0 | AA38: =I38/I$49 -> 0.0058309038 | AB38: =J38/J$49 -> 0.023188406 | ... AE38: =M38/M$49 -> 0.14864865
B39: 51 | I39: 4 | J39: 10 | K39: 11 | L39: 7 | M39: 10 | N39: 2 | P39: =SUM(C39:O39) -> 44 | T39: =B39 -> 51 | U39: =C39/C$49 -> 0 | V39: =D39/D$49 -> 0 | W39: =E39/E$49 -> 0 | X39: =F39/F$49 -> 0 | Y39: =G39/G$49 -> 0 | Z39: =H39/H$49 -> 0 | AA39: =I39/I$49 -> 0.011661808 | AB39: =J39/J$49 -> 0.028985507 | ... AE39: =M39/M$49 -> 0.13513514
B40: 52 | I40: 1 | J40: 4 | K40: 14 | L40: 14 | M40: 1 | N40: 3 | P40: =SUM(C40:O40) -> 37 | T40: =B40 -> 52 | U40: =C40/C$49 -> 0 | V40: =D40/D$49 -> 0 | W40: =E40/E$49 -> 0 | X40: =F40/F$49 -> 0 | Y40: =G40/G$49 -> 0 | Z40: =H40/H$49 -> 0 | AA40: =I40/I$49 -> 0.0029154519 | AB40: =J40/J$49 -> 0.011594203 | ... AE40: =M40/M$49 -> 0.013513514
B41: 53 | J41: 6 | K41: 6 | L41: 6 | M41: 9 | P41: =SUM(C41:O41) -> 27 | T41: =B41 -> 53 | U41: =C41/C$49 -> 0 | V41: =D41/D$49 -> 0 | W41: =E41/E$49 -> 0 | X41: =F41/F$49 -> 0 | Y41: =G41/G$49 -> 0 | Z41: =H41/H$49 -> 0 | AA41: =I41/I$49 -> 0 | AB41: =J41/J$49 -> 0.017391304 | ... AE41: =M41/M$49 -> 0.12162162
B42: 54 | J42: 1 | K42: 2 | L42: 3 | M42: 5 | N42: 3 | P42: =SUM(C42:O42) -> 14 | T42: =B42 -> 54 | U42: =C42/C$49 -> 0 | V42: =D42/D$49 -> 0 | W42: =E42/E$49 -> 0 | X42: =F42/F$49 -> 0 | Y42: =G42/G$49 -> 0 | Z42: =H42/H$49 -> 0 | AA42: =I42/I$49 -> 0 | AB42: =J42/J$49 -> 0.0028985507 | ... AE42: =M42/M$49 -> 0.067567568
...

Sheet 2008
B2: CLAVE EDAD-TALLA JUREL 2008
B4: L.H. | C4: II | D4: III | E4: IV | F4: V | G4: VI | H4: VII | I4: VIII | J4: IX | K4: X | L4: XI | M4: XII | N4: XIII | O4: XIV | P4: XV | Q4: Total | U4: 2 | V4: 3 | W4: 4 | X4: 5 | Y4: 6 | Z4: 7 | AA4: 8 | AB4: 9 | AC4: 10 | AD4: 11 | AE4: 12
B5: =B6-1 -> 17 | T5: =B5 -> 17 | U5: =C5/C$49 -> 0 | V5: =D5/D$49 -> 0 | W5: =E5/E$49 -> 0 | X5: =F5/F$49 -> 0 | Y5: =G5/G$49 -> 0 | Z5: =H5/H$49 -> 0 | AA5: =I5/I$49 -> 0 | AB5: =J5/J$49 -> 0 | ... AE5: =M5/M$49 -> 0
B6: =B7-1 -> 18 | D6: 1 | Q6: =SUM(C6:P6) -> 1 | T6: =B6 -> 18 | U6: =C6/C$49 -> 0 | V6: =D6/D$49 -> 0.018867925 | W6: =E6/E$49 -> 0 | X6: =F6/F$49 -> 0 | Y6: =G6/G$49 -> 0 | Z6: =H6/H$49 -> 0 | AA6: =I6/I$49 -> 0 | AB6: =J6/J$49 -> 0 | ... AE6: =M6/M$49 -> 0
B7: =B8-1 -> 19 | D7: 1 | Q7: =SUM(C7:P7) -> 1 | T7: =B7 -> 19 | U7: =C7/C$49 -> 0 | V7: =D7/D$49 -> 0.018867925 | W7: =E7/E$49 -> 0 | X7: =F7/F$49 -> 0 | Y7: =G7/G$49 -> 0 | Z7: =H7/H$49 -> 0 | AA7: =I7/I$49 -> 0 | AB7: =J7/J$49 -> 0 | ... AE7: =M7/M$49 -> 0
B8: =B9-1 -> 20 | C8: 3 | D8: 2 | Q8: =SUM(C8:P8) -> 5 | T8: =B8 -> 20 | U8: =C8/C$49 -> 0.375 | V8: =D8/D$49 -> 0.037735849 | W8: =E8/E$49 -> 0 | X8: =F8/F$49 -> 0 | Y8: =G8/G$49 -> 0 | Z8: =H8/H$49 -> 0 | AA8: =I8/I$49 -> 0 | AB8: =J8/J$49 -> 0 | ... AE8: =M8/M$49 -> 0
B9: =B10-1 -> 21 | C9: 2 | D9: 10 | E9: 3 | Q9: =SUM(C9:P9) -> 15 | T9: =B9 -> 21 | U9: =C9/C$49 -> 0.25 | V9: =D9/D$49 -> 0.18867925 | W9: =E9/E$49 -> 0.033707865 | X9: =F9/F$49 -> 0 | Y9: =G9/G$49 -> 0 | Z9: =H9/H$49 -> 0 | AA9: =I9/I$49 -> 0 | AB9: =J9/J$49 -> 0 | ... AE9: =M9/M$49 -> 0
B10: =B11-1 -> 22 | C10: 3 | D10: 17 | E10: 9 | Q10: =SUM(C10:P10) -> 29 | T10: =B10 -> 22 | U10: =C10/C$49 -> 0.375 | V10: =D10/D$49 -> 0.32075472 | W10: =E10/E$49 -> 0.1011236 | X10: =F10/F$49 -> 0 | Y10: =G10/G$49 -> 0 | Z10: =H10/H$49 -> 0 | AA10: =I10/I$49 -> 0 | AB10: =J10/J$49 -> 0 | ... AE10: =M10/M$49 -> 0
