Workbook

Sheet New CPUE
A1: 1960.7331 | B1: 1819.9704 | C1: 1201.5288 | D1: 939.6086 | E1: 594.2446 | F1: 559.7124 | G1: 502.3036 | H1: 563.0264 | I1: 474.1695 | J1: 686.8446 | K1: 596.5552
A2: =$A$5*A1 -> 392.14662 | B2: =$A$5*B1 -> 363.99408 | C2: =$A$5*C1 -> 240.30576 | D2: =$A$5*D1 -> 187.92172 | E2: =$A$5*E1 -> 118.84892 | F2: =$A$5*F1 -> 111.94248 | G2: =$A$5*G1 -> 100.46072 | H2: =$A$5*H1 -> 112.60528 | ... K2: =$A$5*K1 -> 119.31104
A5: 0.2

Sheet Mod1.0
B1: #years
B2: 1970
B3: 2017
B4: #ages
B5: 1
B6: 12
B7: #nbins
B8: 41
B9: #lengthbin
B10: 10 | C10: 11 | D10: 12 | E10: 13 | F10: 14 | G10: 15 | H10: 16 | I10: 17 | J10: 18 | K10: 19 | L10: 20 | M10: 21 | N10: 22 | O10: 23 | P10: 24 | Q10: 25 | R10: 26 | S10: 27 | T10: 28 | U10: 29 | V10: 30 | W10: 31 | X10: 32 | Y10: 33 | Z10: 34 | AA10: 35 | AB10: 36 | AC10: 37 | AD10: 38 | AE10: 39 | AF10: 40 | AG10: 41 | AH10: 42 | AI10: 43 | AJ10: 44 | AK10: 45 | AL10: 46 | AM10: 47 | AN10: 48 | AO10: 49 | AP10: 50
B11: #Fnum
B12: 4
B13: #Fnames
B14: N_Chile%SC_Chile_PS%FarNorth%Offshore_Trawl
B15: #Fcaton
B16: 101.69 | C16: 143.45 | D16: 64.46 | E16: 83.2 | F16: 164.76 | G16: 207.33 | H16: 257.7 | I16: 226.23 | J16: 398.41 | K16: 344.05 | L16: 288.81 | M16: 474.82 | N16: 789.91 | O16: 301.93 | P16: 727 | Q16: 511.15 | R16: 55.21 | S16: 313.31 | T16: 325.46 | U16: 338.6 | V16: 323.09 | W16: 346.25 | X16: 304.24 | Y16: 379.47 | Z16: 222.25 | AA16: 230.18 | AB16: 278.44 | AC16: 104.2 | AD16: 30.27 | AE16: 55.65 | AF16: 118.73 | AG16: 248.1 | AH16: 108.73 | AI16: 143.28 | AJ16: 158.66 | AK16: 165.63 | AL16: 155.26 | AM16: 172.701 | AN16: 167.258 | AO16: 134.022 | AP16: 169.012 | AQ16: 30.825 | AR16: 13.256 | AS16: 16.361 | AT16: 18.219 | AU16: 34.886 | AV16: 24.657 | AW16: 35.002
B17: 10.31 | C17: 14.99 | D17: 22.55 | E17: 38.39 | F17: 28.75 | G17: 53.88 | H17: 84.57 | I17: 114.57 | J17: 188.27 | K17: 253.46 | L17: 273.45 | M17: 586.09 | N17: 704.77 | O17: 563.34 | P17: 699.3 | Q17: 945.84 | R17: 1129.11 | S17: 1456.73 | T17: 1812.79 | U17: 2051.52 | V17: 2148.79 | W17: 2674.27 | X17: 2907.82 | Y17: 2856.78 | Z17: 3819.19 | AA17: 4174.02 | AB17: 3604.89 | AC17: 2812.87 | AD17: 1582.64 | AE17: 1164.04 | AF17: 1115.57 | AG17: 1401.84 | AH17: 1410.27 | AI17: 1278.02 | AJ17: 1292.94 | AK17: 1264.81 | AL17: 1224.69 | AM17: 1130.083 | AN17: 728.85 | AO17: 700.905 | AP17: 295.796 | AQ17: 216.47 | AR17: 214.204 | AS17: 214.999 | AT17: 254.295 | AU17: 250.327 | AV17: 295.16 | AW17: 311.863
B18: 4.71 | C18: 9.19 | D18: 18.78 | E18: 42.78 | F18: 129.21 | G18: 37.9 | H18: 54.15 | I18: 504.99 | J18: 386.79 | K18: 333.81 | L18: 414.3 | M18: 445.64 | N18: 143.72 | O18: 110.69 | P18: 200.67 | Q18: 114.62 | R18: 51.03 | S18: 46.3 | T18: 244.23 | U18: 316.25 | V18: 370.82 | W18: 213.45 | X18: 111.68 | Y18: 133.35 | Z18: 233.35 | AA18: 550.99 | AB18: 495.52 | AC18: 680.05 | AD18: 412.85 | AE18: 203.75 | AF18: 303.7 | AG18: 857.74 | AH18: 154.82 | AI18: 217.73 | AJ18: 187.37 | AK18: 80.66 | AL18: 277.57 | AM18: 255.36 | AN18: 169.537 | AO18: 76.629 | AP18: 22.172 | AQ18: 326.394 | AR18: 187.396 | AS18: 80.586 | AT18: 74.532 | AU18: 22.447 | AV18: 15.088 | AW18: 5.186
B19: 0 | C19: 0 | D19: 5.5 | E19: 0 | F19: 0 | G19: 0 | H19: 0.04 | I19: 2.27 | J19: 51.29 | K19: 370.29 | L19: 339.8 | M19: 438.12 | N19: 733.2 | O19: 894.3 | P19: 1059.93 | Q19: 799.32 | R19: 837.5 | S19: 863.42 | T19: 863.22 | U19: 875.82 | V19: 872.06 | W19: 543.66 | X19: 37.93 | Y19: 0 | Z19: 0 | AA19: 0 | AB19: 0 | AC19: 0 | AD19: 0 | AE19: 0.01 | AF19: 2.32 | AG19: 20.09 | AH19: 76.26 | AI19: 158.2 | AJ19: 295.44 | AK19: 243.58 | AL19: 362.63 | AM19: 438.8306 | AN19: 406.9864 | AO19: 371.9176 | AP19: 239.593 | AQ19: 60.89131 | AR19: 39.91786 | AS19: 41.177 | AT19: 63.652 | AU19: 86.717 | AV19: 53.671 | AW19: 50
B20: #Fcatonerr
B21: 0.05 | C21: 0.05 | D21: 0.05 | E21: 0.05 | F21: 0.05 | G21: 0.05 | H21: 0.05 | I21: 0.05 | J21: 0.05 | K21: 0.05 | L21: 0.05 | M21: 0.05 | N21: 0.05 | O21: 0.05 | P21: 0.05 | Q21: 0.05 | R21: 0.05 | S21: 0.05 | T21: 0.05 | U21: 0.05 | V21: 0.05 | W21: 0.05 | X21: 0.05 | Y21: 0.05 | Z21: 0.05 | AA21: 0.05 | AB21: 0.05 | AC21: 0.05 | AD21: 0.05 | AE21: 0.05 | AF21: 0.05 | AG21: 0.05 | AH21: 0.05 | AI21: 0.05 | AJ21: 0.05 | AK21: 0.05 | AL21: 0.05 | AM21: 0.05 | AN21: 0.05 | AO21: 0.05 | AP21: 0.05 | AQ21: 0.05 | AR21: 0.05 | AS21: 0.05 | AT21: 0.05 | AU21: 0.05 | AV21: 0.05 | AW21: 0.05
B22: 0.05 | C22: 0.05 | D22: 0.05 | E22: 0.05 | F22: 0.05 | G22: 0.05 | H22: 0.05 | I22: 0.05 | J22: 0.05 | K22: 0.05 | L22: 0.05 | M22: 0.05 | N22: 0.05 | O22: 0.05 | P22: 0.05 | Q22: 0.05 | R22: 0.05 | S22: 0.05 | T22: 0.05 | U22: 0.05 | V22: 0.05 | W22: 0.05 | X22: 0.05 | Y22: 0.05 | Z22: 0.05 | AA22: 0.05 | AB22: 0.05 | AC22: 0.05 | AD22: 0.05 | AE22: 0.05 | AF22: 0.05 | AG22: 0.05 | AH22: 0.05 | AI22: 0.05 | AJ22: 0.05 | AK22: 0.05 | AL22: 0.05 | AM22: 0.05 | AN22: 0.05 | AO22: 0.05 | AP22: 0.05 | AQ22: 0.05 | AR22: 0.05 | AS22: 0.05 | AT22: 0.05 | AU22: 0.05 | AV22: 0.05 | AW22: 0.05
B23: 0.05 | C23: 0.05 | D23: 0.05 | E23: 0.05 | F23: 0.05 | G23: 0.05 | H23: 0.05 | I23: 0.05 | J23: 0.05 | K23: 0.05 | L23: 0.05 | M23: 0.05 | N23: 0.05 | O23: 0.05 | P23: 0.05 | Q23: 0.05 | R23: 0.05 | S23: 0.05 | T23: 0.05 | U23: 0.05 | V23: 0.05 | W23: 0.05 | X23: 0.05 | Y23: 0.05 | Z23: 0.05 | AA23: 0.05 | AB23: 0.05 | AC23: 0.05 | AD23: 0.05 | AE23: 0.05 | AF23: 0.05 | AG23: 0.05 | AH23: 0.05 | AI23: 0.05 | AJ23: 0.05 | AK23: 0.05 | AL23: 0.05 | AM23: 0.05 | AN23: 0.05 | AO23: 0.05 | AP23: 0.05 | AQ23: 0.05 | AR23: 0.05 | AS23: 0.05 | AT23: 0.05 | AU23: 0.05 | AV23: 0.05 | AW23: 0.05
B24: 0.05 | C24: 0.05 | D24: 0.05 | E24: 0.05 | F24: 0.05 | G24: 0.05 | H24: 0.05 | I24: 0.05 | J24: 0.05 | K24: 0.05 | L24: 0.05 | M24: 0.05 | N24: 0.05 | O24: 0.05 | P24: 0.05 | Q24: 0.05 | R24: 0.05 | S24: 0.05 | T24: 0.05 | U24: 0.05 | V24: 0.05 | W24: 0.05 | X24: 0.05 | Y24: 0.05 | Z24: 0.05 | AA24: 0.05 | AB24: 0.05 | AC24: 0.05 | AD24: 0.05 | AE24: 0.05 | AF24: 0.05 | AG24: 0.05 | AH24: 0.05 | AI24: 0.05 | AJ24: 0.05 | AK24: 0.05 | AL24: 0.05 | AM24: 0.05 | AN24: 0.05 | AO24: 0.05 | AP24: 0.05 | AQ24: 0.05 | AR24: 0.05 | AS24: 0.05 | AT24: 0.05 | AU24: 0.05 | AV24: 0.05 | AW24: 0.05
B25: #FnumyearsA
B26: 42 # 43
B27: 43
B28: 0
B29: 28 # 29
B30: #FnumyearsL
B31: 0
B32: 0
B33: 37
B34: 0
B35: #Fageyears
B36: 1975 | C36: 1976 | D36: 1977 | E36: 1978 | F36: 1979 | G36: 1980 | H36: 1981 | I36: 1982 | J36: 1983 | K36: 1984 | L36: 1985 | M36: 1986 | N36: 1987 | O36: 1988 | P36: 1989 | Q36: 1990 | R36: 1991 | S36: 1992 | T36: 1993 | U36: 1994 | V36: 1995 | W36: 1996 | X36: 1997 | Y36: 1998 | Z36: 1999 | AA36: 2000 | AB36: 2001 | AC36: 2002 | AD36: 2003 | AE36: 2004 | AF36: 2005 | AG36: 2006 | AH36: 2007 | AI36: 2008 | AJ36: 2009 | AK36: 2010 | AL36: 2011 | AM36: 2012 | AN36: 2013 | AO36: 2014 | AP36: 2015 | AQ36: 2016 | AR36: # 2017
B37: 1975 | C37: 1976 | D37: 1977 | E37: 1978 | F37: 1979 | G37: 1980 | H37: 1981 | I37: 1982 | J37: 1983 | K37: 1984 | L37: 1985 | M37: 1986 | N37: 1987 | O37: 1988 | P37: 1989 | Q37: 1990 | R37: 1991 | S37: 1992 | T37: 1993 | U37: 1994 | V37: 1995 | W37: 1996 | X37: 1997 | Y37: 1998 | Z37: 1999 | AA37: 2000 | AB37: 2001 | AC37: 2002 | AD37: 2003 | AE37: 2004 | AF37: 2005 | AG37: 2006 | AH37: 2007 | AI37: 2008 | AJ37: 2009 | AK37: 2010 | AL37: 2011 | AM37: 2012 | AN37: 2013 | AO37: 2014 | AP37: 2015 | AQ37: 2016 | AR37: 2017
B38: 1979 | C38: 1980 | D38: 1981 | E38: 1982 | F38: 1983 | G38: 1984 | H38: 1985 | I38: 1986 | J38: 1987 | K38: 1988 | L38: 1989 | M38: 1990 | N38: 1991 | O38: 2000 | P38: 2001 | Q38: 2002 | R38: 2003 | S38: 2006 | T38: 2007 | U38: 2008 | V38: 2009 | W38: 2010 | X38: 2011 | Y38: 2012 | Z38: 2013 | AA38: 2014 | AB38: 2015 | AC38: 2016 | AD38: # 2017
B39: #Flengthyears
B40: 1980 | C40: 1981 | D40: 1982 | E40: 1983 | F40: 1984 | G40: 1985 | H40: 1986 | I40: 1987 | J40: 1988 | K40: 1989 | L40: 1990 | M40: 1991 | N40: 1992 | O40: 1993 | P40: 1994 | Q40: 1995 | R40: 1996 | S40: 1997 | T40: 1998 | U40: 1999 | V40: 2000 | W40: 2001 | X40: 2002 | Y40: 2003 | Z40: 2004 | AA40: 2005 | AB40: 2006 | AC40: 2007 | AD40: 2008 | AE40: 2009 | AF40: 2010 | AG40: 2011 | AH40: 2012 | AI40: 2013 | AJ40: 2014 | AK40: 2015 | AL40: 2016
...

Sheet Mod1.5.dat
B1: #years Data file w/ new offshore CPUE (GAM) and downweighted Russian CPUE
B2: 1970
B3: 2017
B4: #ages
B5: 1
B6: 12
B7: #nbins
B8: 41
B9: #lengthbin
B10: 10 | C10: 11 | D10: 12 | E10: 13 | F10: 14 | G10: 15 | H10: 16 | I10: 17 | J10: 18 | K10: 19 | L10: 20 | M10: 21 | N10: 22 | O10: 23 | P10: 24 | Q10: 25 | R10: 26 | S10: 27 | T10: 28 | U10: 29 | V10: 30 | W10: 31 | X10: 32 | Y10: 33 | Z10: 34 | AA10: 35 | AB10: 36 | AC10: 37 | AD10: 38 | AE10: 39 | AF10: 40 | AG10: 41 | AH10: 42 | AI10: 43 | AJ10: 44 | AK10: 45 | AL10: 46 | AM10: 47 | AN10: 48 | AO10: 49 | AP10: 50
B11: #Fnum
B12: 4
B13: #Fnames
B14: N_Chile%SC_Chile_PS%FarNorth%Offshore_Trawl
B15: #Fcaton
B16: 101.69 | C16: 143.45 | D16: 64.46 | E16: 83.2 | F16: 164.76 | G16: 207.33 | H16: 257.7 | I16: 226.23 | J16: 398.41 | K16: 344.05 | L16: 288.81 | M16: 474.82 | N16: 789.91 | O16: 301.93 | P16: 727 | Q16: 511.15 | R16: 55.21 | S16: 313.31 | T16: 325.46 | U16: 338.6 | V16: 323.09 | W16: 346.25 | X16: 304.24 | Y16: 379.47 | Z16: 222.25 | AA16: 230.18 | AB16: 278.44 | AC16: 104.2 | AD16: 30.27 | AE16: 55.65 | AF16: 118.73 | AG16: 248.1 | AH16: 108.73 | AI16: 143.28 | AJ16: 158.66 | AK16: 165.63 | AL16: 155.26 | AM16: 172.701 | AN16: 167.258 | AO16: 134.022 | AP16: 169.012 | AQ16: 30.825 | AR16: 13.256 | AS16: 16.361 | AT16: 18.219 | AU16: 34.886 | AV16: 24.657 | AW16: 35.002
B17: 10.31 | C17: 14.99 | D17: 22.55 | E17: 38.39 | F17: 28.75 | G17: 53.88 | H17: 84.57 | I17: 114.57 | J17: 188.27 | K17: 253.46 | L17: 273.45 | M17: 586.09 | N17: 704.77 | O17: 563.34 | P17: 699.3 | Q17: 945.84 | R17: 1129.11 | S17: 1456.73 | T17: 1812.79 | U17: 2051.52 | V17: 2148.79 | W17: 2674.27 | X17: 2907.82 | Y17: 2856.78 | Z17: 3819.19 | AA17: 4174.02 | AB17: 3604.89 | AC17: 2812.87 | AD17: 1582.64 | AE17: 1164.04 | AF17: 1115.57 | AG17: 1401.84 | AH17: 1410.27 | AI17: 1278.02 | AJ17: 1292.94 | AK17: 1264.81 | AL17: 1224.69 | AM17: 1130.083 | AN17: 728.85 | AO17: 700.905 | AP17: 295.796 | AQ17: 216.47 | AR17: 214.204 | AS17: 214.999 | AT17: 254.295 | AU17: 250.327 | AV17: 295.16 | AW17: 311.863
B18: 4.71 | C18: 9.19 | D18: 18.78 | E18: 42.78 | F18: 129.21 | G18: 37.9 | H18: 54.15 | I18: 504.99 | J18: 386.79 | K18: 333.81 | L18: 414.3 | M18: 445.64 | N18: 143.72 | O18: 110.69 | P18: 200.67 | Q18: 114.62 | R18: 51.03 | S18: 46.3 | T18: 244.23 | U18: 316.25 | V18: 370.82 | W18: 213.45 | X18: 111.68 | Y18: 133.35 | Z18: 233.35 | AA18: 550.99 | AB18: 495.52 | AC18: 680.05 | AD18: 412.85 | AE18: 203.75 | AF18: 303.7 | AG18: 857.74 | AH18: 154.82 | AI18: 217.73 | AJ18: 187.37 | AK18: 80.66 | AL18: 277.57 | AM18: 255.36 | AN18: 169.537 | AO18: 76.629 | AP18: 22.172 | AQ18: 326.394 | AR18: 187.396 | AS18: 80.586 | AT18: 74.532 | AU18: 22.447 | AV18: 15.088 | AW18: 5.186
B19: 0 | C19: 0 | D19: 5.5 | E19: 0 | F19: 0 | G19: 0 | H19: 0.04 | I19: 2.27 | J19: 51.29 | K19: 370.29 | L19: 339.8 | M19: 438.12 | N19: 733.2 | O19: 894.3 | P19: 1059.93 | Q19: 799.32 | R19: 837.5 | S19: 863.42 | T19: 863.22 | U19: 875.82 | V19: 872.06 | W19: 543.66 | X19: 37.93 | Y19: 0 | Z19: 0 | AA19: 0 | AB19: 0 | AC19: 0 | AD19: 0 | AE19: 0.01 | AF19: 2.32 | AG19: 20.09 | AH19: 76.26 | AI19: 158.2 | AJ19: 295.44 | AK19: 243.58 | AL19: 362.63 | AM19: 438.8306 | AN19: 406.9864 | AO19: 371.9176 | AP19: 239.593 | AQ19: 60.89131 | AR19: 39.91786 | AS19: 41.177 | AT19: 63.652 | AU19: 86.717 | AV19: 53.671 | AW19: 50
B20: #Fcatonerr
B21: 0.05 | C21: 0.05 | D21: 0.05 | E21: 0.05 | F21: 0.05 | G21: 0.05 | H21: 0.05 | I21: 0.05 | J21: 0.05 | K21: 0.05 | L21: 0.05 | M21: 0.05 | N21: 0.05 | O21: 0.05 | P21: 0.05 | Q21: 0.05 | R21: 0.05 | S21: 0.05 | T21: 0.05 | U21: 0.05 | V21: 0.05 | W21: 0.05 | X21: 0.05 | Y21: 0.05 | Z21: 0.05 | AA21: 0.05 | AB21: 0.05 | AC21: 0.05 | AD21: 0.05 | AE21: 0.05 | AF21: 0.05 | AG21: 0.05 | AH21: 0.05 | AI21: 0.05 | AJ21: 0.05 | AK21: 0.05 | AL21: 0.05 | AM21: 0.05 | AN21: 0.05 | AO21: 0.05 | AP21: 0.05 | AQ21: 0.05 | AR21: 0.05 | AS21: 0.05 | AT21: 0.05 | AU21: 0.05 | AV21: 0.05 | AW21: 0.05
B22: 0.05 | C22: 0.05 | D22: 0.05 | E22: 0.05 | F22: 0.05 | G22: 0.05 | H22: 0.05 | I22: 0.05 | J22: 0.05 | K22: 0.05 | L22: 0.05 | M22: 0.05 | N22: 0.05 | O22: 0.05 | P22: 0.05 | Q22: 0.05 | R22: 0.05 | S22: 0.05 | T22: 0.05 | U22: 0.05 | V22: 0.05 | W22: 0.05 | X22: 0.05 | Y22: 0.05 | Z22: 0.05 | AA22: 0.05 | AB22: 0.05 | AC22: 0.05 | AD22: 0.05 | AE22: 0.05 | AF22: 0.05 | AG22: 0.05 | AH22: 0.05 | AI22: 0.05 | AJ22: 0.05 | AK22: 0.05 | AL22: 0.05 | AM22: 0.05 | AN22: 0.05 | AO22: 0.05 | AP22: 0.05 | AQ22: 0.05 | AR22: 0.05 | AS22: 0.05 | AT22: 0.05 | AU22: 0.05 | AV22: 0.05 | AW22: 0.05
B23: 0.05 | C23: 0.05 | D23: 0.05 | E23: 0.05 | F23: 0.05 | G23: 0.05 | H23: 0.05 | I23: 0.05 | J23: 0.05 | K23: 0.05 | L23: 0.05 | M23: 0.05 | N23: 0.05 | O23: 0.05 | P23: 0.05 | Q23: 0.05 | R23: 0.05 | S23: 0.05 | T23: 0.05 | U23: 0.05 | V23: 0.05 | W23: 0.05 | X23: 0.05 | Y23: 0.05 | Z23: 0.05 | AA23: 0.05 | AB23: 0.05 | AC23: 0.05 | AD23: 0.05 | AE23: 0.05 | AF23: 0.05 | AG23: 0.05 | AH23: 0.05 | AI23: 0.05 | AJ23: 0.05 | AK23: 0.05 | AL23: 0.05 | AM23: 0.05 | AN23: 0.05 | AO23: 0.05 | AP23: 0.05 | AQ23: 0.05 | AR23: 0.05 | AS23: 0.05 | AT23: 0.05 | AU23: 0.05 | AV23: 0.05 | AW23: 0.05
B24: 0.05 | C24: 0.05 | D24: 0.05 | E24: 0.05 | F24: 0.05 | G24: 0.05 | H24: 0.05 | I24: 0.05 | J24: 0.05 | K24: 0.05 | L24: 0.05 | M24: 0.05 | N24: 0.05 | O24: 0.05 | P24: 0.05 | Q24: 0.05 | R24: 0.05 | S24: 0.05 | T24: 0.05 | U24: 0.05 | V24: 0.05 | W24: 0.05 | X24: 0.05 | Y24: 0.05 | Z24: 0.05 | AA24: 0.05 | AB24: 0.05 | AC24: 0.05 | AD24: 0.05 | AE24: 0.05 | AF24: 0.05 | AG24: 0.05 | AH24: 0.05 | AI24: 0.05 | AJ24: 0.05 | AK24: 0.05 | AL24: 0.05 | AM24: 0.05 | AN24: 0.05 | AO24: 0.05 | AP24: 0.05 | AQ24: 0.05 | AR24: 0.05 | AS24: 0.05 | AT24: 0.05 | AU24: 0.05 | AV24: 0.05 | AW24: 0.05
B25: #FnumyearsA
B26: 42 # 43
B27: 43
B28: 0
B29: 28 # 29
B30: #FnumyearsL
B31: 0
B32: 0
B33: 37
B34: 0
B35: #Fageyears
B36: 1975 | C36: 1976 | D36: 1977 | E36: 1978 | F36: 1979 | G36: 1980 | H36: 1981 | I36: 1982 | J36: 1983 | K36: 1984 | L36: 1985 | M36: 1986 | N36: 1987 | O36: 1988 | P36: 1989 | Q36: 1990 | R36: 1991 | S36: 1992 | T36: 1993 | U36: 1994 | V36: 1995 | W36: 1996 | X36: 1997 | Y36: 1998 | Z36: 1999 | AA36: 2000 | AB36: 2001 | AC36: 2002 | AD36: 2003 | AE36: 2004 | AF36: 2005 | AG36: 2006 | AH36: 2007 | AI36: 2008 | AJ36: 2009 | AK36: 2010 | AL36: 2011 | AM36: 2012 | AN36: 2013 | AO36: 2014 | AP36: 2015 | AQ36: 2016 | AR36: # 2017
B37: 1975 | C37: 1976 | D37: 1977 | E37: 1978 | F37: 1979 | G37: 1980 | H37: 1981 | I37: 1982 | J37: 1983 | K37: 1984 | L37: 1985 | M37: 1986 | N37: 1987 | O37: 1988 | P37: 1989 | Q37: 1990 | R37: 1991 | S37: 1992 | T37: 1993 | U37: 1994 | V37: 1995 | W37: 1996 | X37: 1997 | Y37: 1998 | Z37: 1999 | AA37: 2000 | AB37: 2001 | AC37: 2002 | AD37: 2003 | AE37: 2004 | AF37: 2005 | AG37: 2006 | AH37: 2007 | AI37: 2008 | AJ37: 2009 | AK37: 2010 | AL37: 2011 | AM37: 2012 | AN37: 2013 | AO37: 2014 | AP37: 2015 | AQ37: 2016 | AR37: 2017
B38: 1979 | C38: 1980 | D38: 1981 | E38: 1982 | F38: 1983 | G38: 1984 | H38: 1985 | I38: 1986 | J38: 1987 | K38: 1988 | L38: 1989 | M38: 1990 | N38: 1991 | O38: 2000 | P38: 2001 | Q38: 2002 | R38: 2003 | S38: 2006 | T38: 2007 | U38: 2008 | V38: 2009 | W38: 2010 | X38: 2011 | Y38: 2012 | Z38: 2013 | AA38: 2014 | AB38: 2015 | AC38: 2016 | AD38: # 2017
B39: #Flengthyears
B40: 1980 | C40: 1981 | D40: 1982 | E40: 1983 | F40: 1984 | G40: 1985 | H40: 1986 | I40: 1987 | J40: 1988 | K40: 1989 | L40: 1990 | M40: 1991 | N40: 1992 | O40: 1993 | P40: 1994 | Q40: 1995 | R40: 1996 | S40: 1997 | T40: 1998 | U40: 1999 | V40: 2000 | W40: 2001 | X40: 2002 | Y40: 2003 | Z40: 2004 | AA40: 2005 | AB40: 2006 | AC40: 2007 | AD40: 2008 | AE40: 2009 | AF40: 2010 | AG40: 2011 | AH40: 2012 | AI40: 2013 | AJ40: 2014 | AK40: 2015 | AL40: 2016
...

Sheet Mod1.6.dat
B1: #years Data file w/ new offshore CPUE (GAM) and downweighted Russian CPUE
B2: 1970
B3: 2017
B4: #ages
B5: 1
B6: 12
B7: #nbins
B8: 41
B9: #lengthbin
B10: 10 | C10: 11 | D10: 12 | E10: 13 | F10: 14 | G10: 15 | H10: 16 | I10: 17 | J10: 18 | K10: 19 | L10: 20 | M10: 21 | N10: 22 | O10: 23 | P10: 24 | Q10: 25 | R10: 26 | S10: 27 | T10: 28 | U10: 29 | V10: 30 | W10: 31 | X10: 32 | Y10: 33 | Z10: 34 | AA10: 35 | AB10: 36 | AC10: 37 | AD10: 38 | AE10: 39 | AF10: 40 | AG10: 41 | AH10: 42 | AI10: 43 | AJ10: 44 | AK10: 45 | AL10: 46 | AM10: 47 | AN10: 48 | AO10: 49 | AP10: 50
B11: #Fnum
B12: 4
B13: #Fnames
B14: N_Chile%SC_Chile_PS%FarNorth%Offshore_Trawl
B15: #Fcaton
B16: 101.69 | C16: 143.45 | D16: 64.46 | E16: 83.2 | F16: 164.76 | G16: 207.33 | H16: 257.7 | I16: 226.23 | J16: 398.41 | K16: 344.05 | L16: 288.81 | M16: 474.82 | N16: 789.91 | O16: 301.93 | P16: 727 | Q16: 511.15 | R16: 55.21 | S16: 313.31 | T16: 325.46 | U16: 338.6 | V16: 323.09 | W16: 346.25 | X16: 304.24 | Y16: 379.47 | Z16: 222.25 | AA16: 230.18 | AB16: 278.44 | AC16: 104.2 | AD16: 30.27 | AE16: 55.65 | AF16: 118.73 | AG16: 248.1 | AH16: 108.73 | AI16: 143.28 | AJ16: 158.66 | AK16: 165.63 | AL16: 155.26 | AM16: 172.701 | AN16: 167.258 | AO16: 134.022 | AP16: 169.012 | AQ16: 30.825 | AR16: 13.256 | AS16: 16.361 | AT16: 18.219 | AU16: 34.886 | AV16: 24.657 | AW16: 35.002
B17: 10.31 | C17: 14.99 | D17: 22.55 | E17: 38.39 | F17: 28.75 | G17: 53.88 | H17: 84.57 | I17: 114.57 | J17: 188.27 | K17: 253.46 | L17: 273.45 | M17: 586.09 | N17: 704.77 | O17: 563.34 | P17: 699.3 | Q17: 945.84 | R17: 1129.11 | S17: 1456.73 | T17: 1812.79 | U17: 2051.52 | V17: 2148.79 | W17: 2674.27 | X17: 2907.82 | Y17: 2856.78 | Z17: 3819.19 | AA17: 4174.02 | AB17: 3604.89 | AC17: 2812.87 | AD17: 1582.64 | AE17: 1164.04 | AF17: 1115.57 | AG17: 1401.84 | AH17: 1410.27 | AI17: 1278.02 | AJ17: 1292.94 | AK17: 1264.81 | AL17: 1224.69 | AM17: 1130.083 | AN17: 728.85 | AO17: 700.905 | AP17: 295.796 | AQ17: 216.47 | AR17: 214.204 | AS17: 214.999 | AT17: 254.295 | AU17: 250.327 | AV17: 295.16 | AW17: 311.863
B18: 4.71 | C18: 9.19 | D18: 18.78 | E18: 42.78 | F18: 129.21 | G18: 37.9 | H18: 54.15 | I18: 504.99 | J18: 386.79 | K18: 333.81 | L18: 414.3 | M18: 445.64 | N18: 143.72 | O18: 110.69 | P18: 200.67 | Q18: 114.62 | R18: 51.03 | S18: 46.3 | T18: 244.23 | U18: 316.25 | V18: 370.82 | W18: 213.45 | X18: 111.68 | Y18: 133.35 | Z18: 233.35 | AA18: 550.99 | AB18: 495.52 | AC18: 680.05 | AD18: 412.85 | AE18: 203.75 | AF18: 303.7 | AG18: 857.74 | AH18: 154.82 | AI18: 217.73 | AJ18: 187.37 | AK18: 80.66 | AL18: 277.57 | AM18: 255.36 | AN18: 169.537 | AO18: 76.629 | AP18: 22.172 | AQ18: 326.394 | AR18: 187.396 | AS18: 80.586 | AT18: 74.532 | AU18: 22.447 | AV18: 15.088 | AW18: 5.186
B19: 0 | C19: 0 | D19: 5.5 | E19: 0 | F19: 0 | G19: 0 | H19: 0.04 | I19: 2.27 | J19: 51.29 | K19: 370.29 | L19: 339.8 | M19: 438.12 | N19: 733.2 | O19: 894.3 | P19: 1059.93 | Q19: 799.32 | R19: 837.5 | S19: 863.42 | T19: 863.22 | U19: 875.82 | V19: 872.06 | W19: 543.66 | X19: 37.93 | Y19: 0 | Z19: 0 | AA19: 0 | AB19: 0 | AC19: 0 | AD19: 0 | AE19: 0.01 | AF19: 2.32 | AG19: 20.09 | AH19: 76.26 | AI19: 158.2 | AJ19: 295.44 | AK19: 243.58 | AL19: 362.63 | AM19: 438.8306 | AN19: 406.9864 | AO19: 371.9176 | AP19: 239.593 | AQ19: 60.89131 | AR19: 39.91786 | AS19: 41.177 | AT19: 63.652 | AU19: 86.717 | AV19: 53.671 | AW19: 50
B20: #Fcatonerr
B21: 0.05 | C21: 0.05 | D21: 0.05 | E21: 0.05 | F21: 0.05 | G21: 0.05 | H21: 0.05 | I21: 0.05 | J21: 0.05 | K21: 0.05 | L21: 0.05 | M21: 0.05 | N21: 0.05 | O21: 0.05 | P21: 0.05 | Q21: 0.05 | R21: 0.05 | S21: 0.05 | T21: 0.05 | U21: 0.05 | V21: 0.05 | W21: 0.05 | X21: 0.05 | Y21: 0.05 | Z21: 0.05 | AA21: 0.05 | AB21: 0.05 | AC21: 0.05 | AD21: 0.05 | AE21: 0.05 | AF21: 0.05 | AG21: 0.05 | AH21: 0.05 | AI21: 0.05 | AJ21: 0.05 | AK21: 0.05 | AL21: 0.05 | AM21: 0.05 | AN21: 0.05 | AO21: 0.05 | AP21: 0.05 | AQ21: 0.05 | AR21: 0.05 | AS21: 0.05 | AT21: 0.05 | AU21: 0.05 | AV21: 0.05 | AW21: 0.05
B22: 0.05 | C22: 0.05 | D22: 0.05 | E22: 0.05 | F22: 0.05 | G22: 0.05 | H22: 0.05 | I22: 0.05 | J22: 0.05 | K22: 0.05 | L22: 0.05 | M22: 0.05 | N22: 0.05 | O22: 0.05 | P22: 0.05 | Q22: 0.05 | R22: 0.05 | S22: 0.05 | T22: 0.05 | U22: 0.05 | V22: 0.05 | W22: 0.05 | X22: 0.05 | Y22: 0.05 | Z22: 0.05 | AA22: 0.05 | AB22: 0.05 | AC22: 0.05 | AD22: 0.05 | AE22: 0.05 | AF22: 0.05 | AG22: 0.05 | AH22: 0.05 | AI22: 0.05 | AJ22: 0.05 | AK22: 0.05 | AL22: 0.05 | AM22: 0.05 | AN22: 0.05 | AO22: 0.05 | AP22: 0.05 | AQ22: 0.05 | AR22: 0.05 | AS22: 0.05 | AT22: 0.05 | AU22: 0.05 | AV22: 0.05 | AW22: 0.05
B23: 0.05 | C23: 0.05 | D23: 0.05 | E23: 0.05 | F23: 0.05 | G23: 0.05 | H23: 0.05 | I23: 0.05 | J23: 0.05 | K23: 0.05 | L23: 0.05 | M23: 0.05 | N23: 0.05 | O23: 0.05 | P23: 0.05 | Q23: 0.05 | R23: 0.05 | S23: 0.05 | T23: 0.05 | U23: 0.05 | V23: 0.05 | W23: 0.05 | X23: 0.05 | Y23: 0.05 | Z23: 0.05 | AA23: 0.05 | AB23: 0.05 | AC23: 0.05 | AD23: 0.05 | AE23: 0.05 | AF23: 0.05 | AG23: 0.05 | AH23: 0.05 | AI23: 0.05 | AJ23: 0.05 | AK23: 0.05 | AL23: 0.05 | AM23: 0.05 | AN23: 0.05 | AO23: 0.05 | AP23: 0.05 | AQ23: 0.05 | AR23: 0.05 | AS23: 0.05 | AT23: 0.05 | AU23: 0.05 | AV23: 0.05 | AW23: 0.05
B24: 0.05 | C24: 0.05 | D24: 0.05 | E24: 0.05 | F24: 0.05 | G24: 0.05 | H24: 0.05 | I24: 0.05 | J24: 0.05 | K24: 0.05 | L24: 0.05 | M24: 0.05 | N24: 0.05 | O24: 0.05 | P24: 0.05 | Q24: 0.05 | R24: 0.05 | S24: 0.05 | T24: 0.05 | U24: 0.05 | V24: 0.05 | W24: 0.05 | X24: 0.05 | Y24: 0.05 | Z24: 0.05 | AA24: 0.05 | AB24: 0.05 | AC24: 0.05 | AD24: 0.05 | AE24: 0.05 | AF24: 0.05 | AG24: 0.05 | AH24: 0.05 | AI24: 0.05 | AJ24: 0.05 | AK24: 0.05 | AL24: 0.05 | AM24: 0.05 | AN24: 0.05 | AO24: 0.05 | AP24: 0.05 | AQ24: 0.05 | AR24: 0.05 | AS24: 0.05 | AT24: 0.05 | AU24: 0.05 | AV24: 0.05 | AW24: 0.05
B25: #FnumyearsA
B26: 42 # 43
B27: 43
B28: 0
B29: 28 # 29
B30: #FnumyearsL
B31: 0
B32: 0
B33: 37
B34: 0
B35: #Fageyears
B36: 1975 | C36: 1976 | D36: 1977 | E36: 1978 | F36: 1979 | G36: 1980 | H36: 1981 | I36: 1982 | J36: 1983 | K36: 1984 | L36: 1985 | M36: 1986 | N36: 1987 | O36: 1988 | P36: 1989 | Q36: 1990 | R36: 1991 | S36: 1992 | T36: 1993 | U36: 1994 | V36: 1995 | W36: 1996 | X36: 1997 | Y36: 1998 | Z36: 1999 | AA36: 2000 | AB36: 2001 | AC36: 2002 | AD36: 2003 | AE36: 2004 | AF36: 2005 | AG36: 2006 | AH36: 2007 | AI36: 2008 | AJ36: 2009 | AK36: 2010 | AL36: 2011 | AM36: 2012 | AN36: 2013 | AO36: 2014 | AP36: 2015 | AQ36: 2016 | AR36: # 2017
B37: 1975 | C37: 1976 | D37: 1977 | E37: 1978 | F37: 1979 | G37: 1980 | H37: 1981 | I37: 1982 | J37: 1983 | K37: 1984 | L37: 1985 | M37: 1986 | N37: 1987 | O37: 1988 | P37: 1989 | Q37: 1990 | R37: 1991 | S37: 1992 | T37: 1993 | U37: 1994 | V37: 1995 | W37: 1996 | X37: 1997 | Y37: 1998 | Z37: 1999 | AA37: 2000 | AB37: 2001 | AC37: 2002 | AD37: 2003 | AE37: 2004 | AF37: 2005 | AG37: 2006 | AH37: 2007 | AI37: 2008 | AJ37: 2009 | AK37: 2010 | AL37: 2011 | AM37: 2012 | AN37: 2013 | AO37: 2014 | AP37: 2015 | AQ37: 2016 | AR37: 2017
B38: 1979 | C38: 1980 | D38: 1981 | E38: 1982 | F38: 1983 | G38: 1984 | H38: 1985 | I38: 1986 | J38: 1987 | K38: 1988 | L38: 1989 | M38: 1990 | N38: 1991 | O38: 2000 | P38: 2001 | Q38: 2002 | R38: 2003 | S38: 2006 | T38: 2007 | U38: 2008 | V38: 2009 | W38: 2010 | X38: 2011 | Y38: 2012 | Z38: 2013 | AA38: 2014 | AB38: 2015 | AC38: 2016 | AD38: # 2017
B39: #Flengthyears
B40: 1980 | C40: 1981 | D40: 1982 | E40: 1983 | F40: 1984 | G40: 1985 | H40: 1986 | I40: 1987 | J40: 1988 | K40: 1989 | L40: 1990 | M40: 1991 | N40: 1992 | O40: 1993 | P40: 1994 | Q40: 1995 | R40: 1996 | S40: 1997 | T40: 1998 | U40: 1999 | V40: 2000 | W40: 2001 | X40: 2002 | Y40: 2003 | Z40: 2004 | AA40: 2005 | AB40: 2006 | AC40: 2007 | AD40: 2008 | AE40: 2009 | AF40: 2010 | AG40: 2011 | AH40: 2012 | AI40: 2013 | AJ40: 2014 | AK40: 2015 | AL40: 2016
...

Sheet Mod1.7.dat
B1: #years Data file w/ new offshore CPUE (GAM) and downweighted Russian CPUE
B2: 1970
B3: 2017
B4: #ages
B5: 1
B6: 12
B7: #nbins
B8: 41
B9: #lengthbin
B10: 10 | C10: 11 | D10: 12 | E10: 13 | F10: 14 | G10: 15 | H10: 16 | I10: 17 | J10: 18 | K10: 19 | L10: 20 | M10: 21 | N10: 22 | O10: 23 | P10: 24 | Q10: 25 | R10: 26 | S10: 27 | T10: 28 | U10: 29 | V10: 30 | W10: 31 | X10: 32 | Y10: 33 | Z10: 34 | AA10: 35 | AB10: 36 | AC10: 37 | AD10: 38 | AE10: 39 | AF10: 40 | AG10: 41 | AH10: 42 | AI10: 43 | AJ10: 44 | AK10: 45 | AL10: 46 | AM10: 47 | AN10: 48 | AO10: 49 | AP10: 50
B11: #Fnum
B12: 4
B13: #Fnames
B14: N_Chile%SC_Chile_PS%FarNorth%Offshore_Trawl
B15: #Fcaton
B16: 101.69 | C16: 143.45 | D16: 64.46 | E16: 83.2 | F16: 164.76 | G16: 207.33 | H16: 257.7 | I16: 226.23 | J16: 398.41 | K16: 344.05 | L16: 288.81 | M16: 474.82 | N16: 789.91 | O16: 301.93 | P16: 727 | Q16: 511.15 | R16: 55.21 | S16: 313.31 | T16: 325.46 | U16: 338.6 | V16: 323.09 | W16: 346.25 | X16: 304.24 | Y16: 379.47 | Z16: 222.25 | AA16: 230.18 | AB16: 278.44 | AC16: 104.2 | AD16: 30.27 | AE16: 55.65 | AF16: 118.73 | AG16: 248.1 | AH16: 108.73 | AI16: 143.28 | AJ16: 158.66 | AK16: 165.63 | AL16: 155.26 | AM16: 172.701 | AN16: 167.258 | AO16: 134.022 | AP16: 169.012 | AQ16: 30.825 | AR16: 13.256 | AS16: 16.361 | AT16: 18.219 | AU16: 34.886 | AV16: 24.657 | AW16: 35.002
B17: 10.31 | C17: 14.99 | D17: 22.55 | E17: 38.39 | F17: 28.75 | G17: 53.88 | H17: 84.57 | I17: 114.57 | J17: 188.27 | K17: 253.46 | L17: 273.45 | M17: 586.09 | N17: 704.77 | O17: 563.34 | P17: 699.3 | Q17: 945.84 | R17: 1129.11 | S17: 1456.73 | T17: 1812.79 | U17: 2051.52 | V17: 2148.79 | W17: 2674.27 | X17: 2907.82 | Y17: 2856.78 | Z17: 3819.19 | AA17: 4174.02 | AB17: 3604.89 | AC17: 2812.87 | AD17: 1582.64 | AE17: 1164.04 | AF17: 1115.57 | AG17: 1401.84 | AH17: 1410.27 | AI17: 1278.02 | AJ17: 1292.94 | AK17: 1264.81 | AL17: 1224.69 | AM17: 1130.083 | AN17: 728.85 | AO17: 700.905 | AP17: 295.796 | AQ17: 216.47 | AR17: 214.204 | AS17: 214.999 | AT17: 254.295 | AU17: 250.327 | AV17: 295.16 | AW17: 311.863
B18: 4.71 | C18: 9.19 | D18: 18.78 | E18: 42.78 | F18: 129.21 | G18: 37.9 | H18: 54.15 | I18: 504.99 | J18: 386.79 | K18: 333.81 | L18: 414.3 | M18: 445.64 | N18: 143.72 | O18: 110.69 | P18: 200.67 | Q18: 114.62 | R18: 51.03 | S18: 46.3 | T18: 244.23 | U18: 316.25 | V18: 370.82 | W18: 213.45 | X18: 111.68 | Y18: 133.35 | Z18: 233.35 | AA18: 550.99 | AB18: 495.52 | AC18: 680.05 | AD18: 412.85 | AE18: 203.75 | AF18: 303.7 | AG18: 857.74 | AH18: 154.82 | AI18: 217.73 | AJ18: 187.37 | AK18: 80.66 | AL18: 277.57 | AM18: 255.36 | AN18: 169.537 | AO18: 76.629 | AP18: 22.172 | AQ18: 326.394 | AR18: 187.396 | AS18: 80.586 | AT18: 74.532 | AU18: 22.447 | AV18: 15.088 | AW18: 5.186
B19: 0 | C19: 0 | D19: 5.5 | E19: 0 | F19: 0 | G19: 0 | H19: 0.04 | I19: 2.27 | J19: 51.29 | K19: 370.29 | L19: 339.8 | M19: 438.12 | N19: 733.2 | O19: 894.3 | P19: 1059.93 | Q19: 799.32 | R19: 837.5 | S19: 863.42 | T19: 863.22 | U19: 875.82 | V19: 872.06 | W19: 543.66 | X19: 37.93 | Y19: 0 | Z19: 0 | AA19: 0 | AB19: 0 | AC19: 0 | AD19: 0 | AE19: 0.01 | AF19: 2.32 | AG19: 20.09 | AH19: 76.26 | AI19: 158.2 | AJ19: 295.44 | AK19: 243.58 | AL19: 362.63 | AM19: 438.8306 | AN19: 406.9864 | AO19: 371.9176 | AP19: 239.593 | AQ19: 60.89131 | AR19: 39.91786 | AS19: 41.177 | AT19: 63.652 | AU19: 86.717 | AV19: 53.671 | AW19: 50
B20: #Fcatonerr
B21: 0.05 | C21: 0.05 | D21: 0.05 | E21: 0.05 | F21: 0.05 | G21: 0.05 | H21: 0.05 | I21: 0.05 | J21: 0.05 | K21: 0.05 | L21: 0.05 | M21: 0.05 | N21: 0.05 | O21: 0.05 | P21: 0.05 | Q21: 0.05 | R21: 0.05 | S21: 0.05 | T21: 0.05 | U21: 0.05 | V21: 0.05 | W21: 0.05 | X21: 0.05 | Y21: 0.05 | Z21: 0.05 | AA21: 0.05 | AB21: 0.05 | AC21: 0.05 | AD21: 0.05 | AE21: 0.05 | AF21: 0.05 | AG21: 0.05 | AH21: 0.05 | AI21: 0.05 | AJ21: 0.05 | AK21: 0.05 | AL21: 0.05 | AM21: 0.05 | AN21: 0.05 | AO21: 0.05 | AP21: 0.05 | AQ21: 0.05 | AR21: 0.05 | AS21: 0.05 | AT21: 0.05 | AU21: 0.05 | AV21: 0.05 | AW21: 0.05
B22: 0.05 | C22: 0.05 | D22: 0.05 | E22: 0.05 | F22: 0.05 | G22: 0.05 | H22: 0.05 | I22: 0.05 | J22: 0.05 | K22: 0.05 | L22: 0.05 | M22: 0.05 | N22: 0.05 | O22: 0.05 | P22: 0.05 | Q22: 0.05 | R22: 0.05 | S22: 0.05 | T22: 0.05 | U22: 0.05 | V22: 0.05 | W22: 0.05 | X22: 0.05 | Y22: 0.05 | Z22: 0.05 | AA22: 0.05 | AB22: 0.05 | AC22: 0.05 | AD22: 0.05 | AE22: 0.05 | AF22: 0.05 | AG22: 0.05 | AH22: 0.05 | AI22: 0.05 | AJ22: 0.05 | AK22: 0.05 | AL22: 0.05 | AM22: 0.05 | AN22: 0.05 | AO22: 0.05 | AP22: 0.05 | AQ22: 0.05 | AR22: 0.05 | AS22: 0.05 | AT22: 0.05 | AU22: 0.05 | AV22: 0.05 | AW22: 0.05
B23: 0.05 | C23: 0.05 | D23: 0.05 | E23: 0.05 | F23: 0.05 | G23: 0.05 | H23: 0.05 | I23: 0.05 | J23: 0.05 | K23: 0.05 | L23: 0.05 | M23: 0.05 | N23: 0.05 | O23: 0.05 | P23: 0.05 | Q23: 0.05 | R23: 0.05 | S23: 0.05 | T23: 0.05 | U23: 0.05 | V23: 0.05 | W23: 0.05 | X23: 0.05 | Y23: 0.05 | Z23: 0.05 | AA23: 0.05 | AB23: 0.05 | AC23: 0.05 | AD23: 0.05 | AE23: 0.05 | AF23: 0.05 | AG23: 0.05 | AH23: 0.05 | AI23: 0.05 | AJ23: 0.05 | AK23: 0.05 | AL23: 0.05 | AM23: 0.05 | AN23: 0.05 | AO23: 0.05 | AP23: 0.05 | AQ23: 0.05 | AR23: 0.05 | AS23: 0.05 | AT23: 0.05 | AU23: 0.05 | AV23: 0.05 | AW23: 0.05
B24: 0.05 | C24: 0.05 | D24: 0.05 | E24: 0.05 | F24: 0.05 | G24: 0.05 | H24: 0.05 | I24: 0.05 | J24: 0.05 | K24: 0.05 | L24: 0.05 | M24: 0.05 | N24: 0.05 | O24: 0.05 | P24: 0.05 | Q24: 0.05 | R24: 0.05 | S24: 0.05 | T24: 0.05 | U24: 0.05 | V24: 0.05 | W24: 0.05 | X24: 0.05 | Y24: 0.05 | Z24: 0.05 | AA24: 0.05 | AB24: 0.05 | AC24: 0.05 | AD24: 0.05 | AE24: 0.05 | AF24: 0.05 | AG24: 0.05 | AH24: 0.05 | AI24: 0.05 | AJ24: 0.05 | AK24: 0.05 | AL24: 0.05 | AM24: 0.05 | AN24: 0.05 | AO24: 0.05 | AP24: 0.05 | AQ24: 0.05 | AR24: 0.05 | AS24: 0.05 | AT24: 0.05 | AU24: 0.05 | AV24: 0.05 | AW24: 0.05
B25: #FnumyearsA
B26: 42 # 43
B27: 43
B28: 0
B29: 28 # 29
B30: #FnumyearsL
B31: 0
B32: 0
B33: 37
B34: 0
B35: #Fageyears
B36: 1975 | C36: 1976 | D36: 1977 | E36: 1978 | F36: 1979 | G36: 1980 | H36: 1981 | I36: 1982 | J36: 1983 | K36: 1984 | L36: 1985 | M36: 1986 | N36: 1987 | O36: 1988 | P36: 1989 | Q36: 1990 | R36: 1991 | S36: 1992 | T36: 1993 | U36: 1994 | V36: 1995 | W36: 1996 | X36: 1997 | Y36: 1998 | Z36: 1999 | AA36: 2000 | AB36: 2001 | AC36: 2002 | AD36: 2003 | AE36: 2004 | AF36: 2005 | AG36: 2006 | AH36: 2007 | AI36: 2008 | AJ36: 2009 | AK36: 2010 | AL36: 2011 | AM36: 2012 | AN36: 2013 | AO36: 2014 | AP36: 2015 | AQ36: 2016 | AR36: # 2017
B37: 1975 | C37: 1976 | D37: 1977 | E37: 1978 | F37: 1979 | G37: 1980 | H37: 1981 | I37: 1982 | J37: 1983 | K37: 1984 | L37: 1985 | M37: 1986 | N37: 1987 | O37: 1988 | P37: 1989 | Q37: 1990 | R37: 1991 | S37: 1992 | T37: 1993 | U37: 1994 | V37: 1995 | W37: 1996 | X37: 1997 | Y37: 1998 | Z37: 1999 | AA37: 2000 | AB37: 2001 | AC37: 2002 | AD37: 2003 | AE37: 2004 | AF37: 2005 | AG37: 2006 | AH37: 2007 | AI37: 2008 | AJ37: 2009 | AK37: 2010 | AL37: 2011 | AM37: 2012 | AN37: 2013 | AO37: 2014 | AP37: 2015 | AQ37: 2016 | AR37: 2017
B38: 1979 | C38: 1980 | D38: 1981 | E38: 1982 | F38: 1983 | G38: 1984 | H38: 1985 | I38: 1986 | J38: 1987 | K38: 1988 | L38: 1989 | M38: 1990 | N38: 1991 | O38: 2000 | P38: 2001 | Q38: 2002 | R38: 2003 | S38: 2006 | T38: 2007 | U38: 2008 | V38: 2009 | W38: 2010 | X38: 2011 | Y38: 2012 | Z38: 2013 | AA38: 2014 | AB38: 2015 | AC38: 2016 | AD38: # 2017
B39: #Flengthyears
B40: 1980 | C40: 1981 | D40: 1982 | E40: 1983 | F40: 1984 | G40: 1985 | H40: 1986 | I40: 1987 | J40: 1988 | K40: 1989 | L40: 1990 | M40: 1991 | N40: 1992 | O40: 1993 | P40: 1994 | Q40: 1995 | R40: 1996 | S40: 1997 | T40: 1998 | U40: 1999 | V40: 2000 | W40: 2001 | X40: 2002 | Y40: 2003 | Z40: 2004 | AA40: 2005 | AB40: 2006 | AC40: 2007 | AD40: 2008 | AE40: 2009 | AF40: 2010 | AG40: 2011 | AH40: 2012 | AI40: 2013 | AJ40: 2014 | AK40: 2015 | AL40: 2016
...

Sheet Mod1.8.dat
B1: #years Data file w/ only new offshore CPUE (GAM) given weight as an index
B2: 1970
B3: 2017
B4: #ages
B5: 1
B6: 12
B7: #nbins
B8: 41
B9: #lengthbin
B10: 10 | C10: 11 | D10: 12 | E10: 13 | F10: 14 | G10: 15 | H10: 16 | I10: 17 | J10: 18 | K10: 19 | L10: 20 | M10: 21 | N10: 22 | O10: 23 | P10: 24 | Q10: 25 | R10: 26 | S10: 27 | T10: 28 | U10: 29 | V10: 30 | W10: 31 | X10: 32 | Y10: 33 | Z10: 34 | AA10: 35 | AB10: 36 | AC10: 37 | AD10: 38 | AE10: 39 | AF10: 40 | AG10: 41 | AH10: 42 | AI10: 43 | AJ10: 44 | AK10: 45 | AL10: 46 | AM10: 47 | AN10: 48 | AO10: 49 | AP10: 50
B11: #Fnum
B12: 4
B13: #Fnames
B14: N_Chile%SC_Chile_PS%FarNorth%Offshore_Trawl
B15: #Fcaton
B16: 101.69 | C16: 143.45 | D16: 64.46 | E16: 83.2 | F16: 164.76 | G16: 207.33 | H16: 257.7 | I16: 226.23 | J16: 398.41 | K16: 344.05 | L16: 288.81 | M16: 474.82 | N16: 789.91 | O16: 301.93 | P16: 727 | Q16: 511.15 | R16: 55.21 | S16: 313.31 | T16: 325.46 | U16: 338.6 | V16: 323.09 | W16: 346.25 | X16: 304.24 | Y16: 379.47 | Z16: 222.25 | AA16: 230.18 | AB16: 278.44 | AC16: 104.2 | AD16: 30.27 | AE16: 55.65 | AF16: 118.73 | AG16: 248.1 | AH16: 108.73 | AI16: 143.28 | AJ16: 158.66 | AK16: 165.63 | AL16: 155.26 | AM16: 172.701 | AN16: 167.258 | AO16: 134.022 | AP16: 169.012 | AQ16: 30.825 | AR16: 13.256 | AS16: 16.361 | AT16: 18.219 | AU16: 34.886 | AV16: 24.657 | AW16: 35.002
B17: 10.31 | C17: 14.99 | D17: 22.55 | E17: 38.39 | F17: 28.75 | G17: 53.88 | H17: 84.57 | I17: 114.57 | J17: 188.27 | K17: 253.46 | L17: 273.45 | M17: 586.09 | N17: 704.77 | O17: 563.34 | P17: 699.3 | Q17: 945.84 | R17: 1129.11 | S17: 1456.73 | T17: 1812.79 | U17: 2051.52 | V17: 2148.79 | W17: 2674.27 | X17: 2907.82 | Y17: 2856.78 | Z17: 3819.19 | AA17: 4174.02 | AB17: 3604.89 | AC17: 2812.87 | AD17: 1582.64 | AE17: 1164.04 | AF17: 1115.57 | AG17: 1401.84 | AH17: 1410.27 | AI17: 1278.02 | AJ17: 1292.94 | AK17: 1264.81 | AL17: 1224.69 | AM17: 1130.083 | AN17: 728.85 | AO17: 700.905 | AP17: 295.796 | AQ17: 216.47 | AR17: 214.204 | AS17: 214.999 | AT17: 254.295 | AU17: 250.327 | AV17: 295.16 | AW17: 311.863
B18: 4.71 | C18: 9.19 | D18: 18.78 | E18: 42.78 | F18: 129.21 | G18: 37.9 | H18: 54.15 | I18: 504.99 | J18: 386.79 | K18: 333.81 | L18: 414.3 | M18: 445.64 | N18: 143.72 | O18: 110.69 | P18: 200.67 | Q18: 114.62 | R18: 51.03 | S18: 46.3 | T18: 244.23 | U18: 316.25 | V18: 370.82 | W18: 213.45 | X18: 111.68 | Y18: 133.35 | Z18: 233.35 | AA18: 550.99 | AB18: 495.52 | AC18: 680.05 | AD18: 412.85 | AE18: 203.75 | AF18: 303.7 | AG18: 857.74 | AH18: 154.82 | AI18: 217.73 | AJ18: 187.37 | AK18: 80.66 | AL18: 277.57 | AM18: 255.36 | AN18: 169.537 | AO18: 76.629 | AP18: 22.172 | AQ18: 326.394 | AR18: 187.396 | AS18: 80.586 | AT18: 74.532 | AU18: 22.447 | AV18: 15.088 | AW18: 5.186
B19: 0 | C19: 0 | D19: 5.5 | E19: 0 | F19: 0 | G19: 0 | H19: 0.04 | I19: 2.27 | J19: 51.29 | K19: 370.29 | L19: 339.8 | M19: 438.12 | N19: 733.2 | O19: 894.3 | P19: 1059.93 | Q19: 799.32 | R19: 837.5 | S19: 863.42 | T19: 863.22 | U19: 875.82 | V19: 872.06 | W19: 543.66 | X19: 37.93 | Y19: 0 | Z19: 0 | AA19: 0 | AB19: 0 | AC19: 0 | AD19: 0 | AE19: 0.01 | AF19: 2.32 | AG19: 20.09 | AH19: 76.26 | AI19: 158.2 | AJ19: 295.44 | AK19: 243.58 | AL19: 362.63 | AM19: 438.8306 | AN19: 406.9864 | AO19: 371.9176 | AP19: 239.593 | AQ19: 60.89131 | AR19: 39.91786 | AS19: 41.177 | AT19: 63.652 | AU19: 86.717 | AV19: 53.671 | AW19: 50
B20: #Fcatonerr
B21: 0.05 | C21: 0.05 | D21: 0.05 | E21: 0.05 | F21: 0.05 | G21: 0.05 | H21: 0.05 | I21: 0.05 | J21: 0.05 | K21: 0.05 | L21: 0.05 | M21: 0.05 | N21: 0.05 | O21: 0.05 | P21: 0.05 | Q21: 0.05 | R21: 0.05 | S21: 0.05 | T21: 0.05 | U21: 0.05 | V21: 0.05 | W21: 0.05 | X21: 0.05 | Y21: 0.05 | Z21: 0.05 | AA21: 0.05 | AB21: 0.05 | AC21: 0.05 | AD21: 0.05 | AE21: 0.05 | AF21: 0.05 | AG21: 0.05 | AH21: 0.05 | AI21: 0.05 | AJ21: 0.05 | AK21: 0.05 | AL21: 0.05 | AM21: 0.05 | AN21: 0.05 | AO21: 0.05 | AP21: 0.05 | AQ21: 0.05 | AR21: 0.05 | AS21: 0.05 | AT21: 0.05 | AU21: 0.05 | AV21: 0.05 | AW21: 0.05
B22: 0.05 | C22: 0.05 | D22: 0.05 | E22: 0.05 | F22: 0.05 | G22: 0.05 | H22: 0.05 | I22: 0.05 | J22: 0.05 | K22: 0.05 | L22: 0.05 | M22: 0.05 | N22: 0.05 | O22: 0.05 | P22: 0.05 | Q22: 0.05 | R22: 0.05 | S22: 0.05 | T22: 0.05 | U22: 0.05 | V22: 0.05 | W22: 0.05 | X22: 0.05 | Y22: 0.05 | Z22: 0.05 | AA22: 0.05 | AB22: 0.05 | AC22: 0.05 | AD22: 0.05 | AE22: 0.05 | AF22: 0.05 | AG22: 0.05 | AH22: 0.05 | AI22: 0.05 | AJ22: 0.05 | AK22: 0.05 | AL22: 0.05 | AM22: 0.05 | AN22: 0.05 | AO22: 0.05 | AP22: 0.05 | AQ22: 0.05 | AR22: 0.05 | AS22: 0.05 | AT22: 0.05 | AU22: 0.05 | AV22: 0.05 | AW22: 0.05
B23: 0.05 | C23: 0.05 | D23: 0.05 | E23: 0.05 | F23: 0.05 | G23: 0.05 | H23: 0.05 | I23: 0.05 | J23: 0.05 | K23: 0.05 | L23: 0.05 | M23: 0.05 | N23: 0.05 | O23: 0.05 | P23: 0.05 | Q23: 0.05 | R23: 0.05 | S23: 0.05 | T23: 0.05 | U23: 0.05 | V23: 0.05 | W23: 0.05 | X23: 0.05 | Y23: 0.05 | Z23: 0.05 | AA23: 0.05 | AB23: 0.05 | AC23: 0.05 | AD23: 0.05 | AE23: 0.05 | AF23: 0.05 | AG23: 0.05 | AH23: 0.05 | AI23: 0.05 | AJ23: 0.05 | AK23: 0.05 | AL23: 0.05 | AM23: 0.05 | AN23: 0.05 | AO23: 0.05 | AP23: 0.05 | AQ23: 0.05 | AR23: 0.05 | AS23: 0.05 | AT23: 0.05 | AU23: 0.05 | AV23: 0.05 | AW23: 0.05
B24: 0.05 | C24: 0.05 | D24: 0.05 | E24: 0.05 | F24: 0.05 | G24: 0.05 | H24: 0.05 | I24: 0.05 | J24: 0.05 | K24: 0.05 | L24: 0.05 | M24: 0.05 | N24: 0.05 | O24: 0.05 | P24: 0.05 | Q24: 0.05 | R24: 0.05 | S24: 0.05 | T24: 0.05 | U24: 0.05 | V24: 0.05 | W24: 0.05 | X24: 0.05 | Y24: 0.05 | Z24: 0.05 | AA24: 0.05 | AB24: 0.05 | AC24: 0.05 | AD24: 0.05 | AE24: 0.05 | AF24: 0.05 | AG24: 0.05 | AH24: 0.05 | AI24: 0.05 | AJ24: 0.05 | AK24: 0.05 | AL24: 0.05 | AM24: 0.05 | AN24: 0.05 | AO24: 0.05 | AP24: 0.05 | AQ24: 0.05 | AR24: 0.05 | AS24: 0.05 | AT24: 0.05 | AU24: 0.05 | AV24: 0.05 | AW24: 0.05
B25: #FnumyearsA
B26: 42 # 43
B27: 43
B28: 0
B29: 28 # 29
B30: #FnumyearsL
B31: 0
B32: 0
B33: 37
B34: 0
B35: #Fageyears
B36: 1975 | C36: 1976 | D36: 1977 | E36: 1978 | F36: 1979 | G36: 1980 | H36: 1981 | I36: 1982 | J36: 1983 | K36: 1984 | L36: 1985 | M36: 1986 | N36: 1987 | O36: 1988 | P36: 1989 | Q36: 1990 | R36: 1991 | S36: 1992 | T36: 1993 | U36: 1994 | V36: 1995 | W36: 1996 | X36: 1997 | Y36: 1998 | Z36: 1999 | AA36: 2000 | AB36: 2001 | AC36: 2002 | AD36: 2003 | AE36: 2004 | AF36: 2005 | AG36: 2006 | AH36: 2007 | AI36: 2008 | AJ36: 2009 | AK36: 2010 | AL36: 2011 | AM36: 2012 | AN36: 2013 | AO36: 2014 | AP36: 2015 | AQ36: 2016 | AR36: # 2017
B37: 1975 | C37: 1976 | D37: 1977 | E37: 1978 | F37: 1979 | G37: 1980 | H37: 1981 | I37: 1982 | J37: 1983 | K37: 1984 | L37: 1985 | M37: 1986 | N37: 1987 | O37: 1988 | P37: 1989 | Q37: 1990 | R37: 1991 | S37: 1992 | T37: 1993 | U37: 1994 | V37: 1995 | W37: 1996 | X37: 1997 | Y37: 1998 | Z37: 1999 | AA37: 2000 | AB37: 2001 | AC37: 2002 | AD37: 2003 | AE37: 2004 | AF37: 2005 | AG37: 2006 | AH37: 2007 | AI37: 2008 | AJ37: 2009 | AK37: 2010 | AL37: 2011 | AM37: 2012 | AN37: 2013 | AO37: 2014 | AP37: 2015 | AQ37: 2016 | AR37: 2017
B38: 1979 | C38: 1980 | D38: 1981 | E38: 1982 | F38: 1983 | G38: 1984 | H38: 1985 | I38: 1986 | J38: 1987 | K38: 1988 | L38: 1989 | M38: 1990 | N38: 1991 | O38: 2000 | P38: 2001 | Q38: 2002 | R38: 2003 | S38: 2006 | T38: 2007 | U38: 2008 | V38: 2009 | W38: 2010 | X38: 2011 | Y38: 2012 | Z38: 2013 | AA38: 2014 | AB38: 2015 | AC38: 2016 | AD38: # 2017
B39: #Flengthyears
B40: 1980 | C40: 1981 | D40: 1982 | E40: 1983 | F40: 1984 | G40: 1985 | H40: 1986 | I40: 1987 | J40: 1988 | K40: 1989 | L40: 1990 | M40: 1991 | N40: 1992 | O40: 1993 | P40: 1994 | Q40: 1995 | R40: 1996 | S40: 1997 | T40: 1998 | U40: 1999 | V40: 2000 | W40: 2001 | X40: 2002 | Y40: 2003 | Z40: 2004 | AA40: 2005 | AB40: 2006 | AC40: 2007 | AD40: 2008 | AE40: 2009 | AF40: 2010 | AG40: 2011 | AH40: 2012 | AI40: 2013 | AJ40: 2014 | AK40: 2015 | AL40: 2016
...

Sheet Mod1.9.dat
B1: #years Data file w/ only new offshore CPUE (GAM) given weight as an index
B2: 1970
B3: 2017
B4: #ages
B5: 1
B6: 12
B7: #nbins
B8: 41
B9: #lengthbin
B10: 10 | C10: 11 | D10: 12 | E10: 13 | F10: 14 | G10: 15 | H10: 16 | I10: 17 | J10: 18 | K10: 19 | L10: 20 | M10: 21 | N10: 22 | O10: 23 | P10: 24 | Q10: 25 | R10: 26 | S10: 27 | T10: 28 | U10: 29 | V10: 30 | W10: 31 | X10: 32 | Y10: 33 | Z10: 34 | AA10: 35 | AB10: 36 | AC10: 37 | AD10: 38 | AE10: 39 | AF10: 40 | AG10: 41 | AH10: 42 | AI10: 43 | AJ10: 44 | AK10: 45 | AL10: 46 | AM10: 47 | AN10: 48 | AO10: 49 | AP10: 50
B11: #Fnum
B12: 4
B13: #Fnames
B14: N_Chile%SC_Chile_PS%FarNorth%Offshore_Trawl
B15: #Fcaton
B16: 101.69 | C16: 143.45 | D16: 64.46 | E16: 83.2 | F16: 164.76 | G16: 207.33 | H16: 257.7 | I16: 226.23 | J16: 398.41 | K16: 344.05 | L16: 288.81 | M16: 474.82 | N16: 789.91 | O16: 301.93 | P16: 727 | Q16: 511.15 | R16: 55.21 | S16: 313.31 | T16: 325.46 | U16: 338.6 | V16: 323.09 | W16: 346.25 | X16: 304.24 | Y16: 379.47 | Z16: 222.25 | AA16: 230.18 | AB16: 278.44 | AC16: 104.2 | AD16: 30.27 | AE16: 55.65 | AF16: 118.73 | AG16: 248.1 | AH16: 108.73 | AI16: 143.28 | AJ16: 158.66 | AK16: 165.63 | AL16: 155.26 | AM16: 172.701 | AN16: 167.258 | AO16: 134.022 | AP16: 169.012 | AQ16: 30.825 | AR16: 13.256 | AS16: 16.361 | AT16: 18.219 | AU16: 34.886 | AV16: 24.657 | AW16: 35.002
B17: 10.31 | C17: 14.99 | D17: 22.55 | E17: 38.39 | F17: 28.75 | G17: 53.88 | H17: 84.57 | I17: 114.57 | J17: 188.27 | K17: 253.46 | L17: 273.45 | M17: 586.09 | N17: 704.77 | O17: 563.34 | P17: 699.3 | Q17: 945.84 | R17: 1129.11 | S17: 1456.73 | T17: 1812.79 | U17: 2051.52 | V17: 2148.79 | W17: 2674.27 | X17: 2907.82 | Y17: 2856.78 | Z17: 3819.19 | AA17: 4174.02 | AB17: 3604.89 | AC17: 2812.87 | AD17: 1582.64 | AE17: 1164.04 | AF17: 1115.57 | AG17: 1401.84 | AH17: 1410.27 | AI17: 1278.02 | AJ17: 1292.94 | AK17: 1264.81 | AL17: 1224.69 | AM17: 1130.083 | AN17: 728.85 | AO17: 700.905 | AP17: 295.796 | AQ17: 216.47 | AR17: 214.204 | AS17: 214.999 | AT17: 254.295 | AU17: 250.327 | AV17: 295.16 | AW17: 311.863
B18: 4.71 | C18: 9.19 | D18: 18.78 | E18: 42.78 | F18: 129.21 | G18: 37.9 | H18: 54.15 | I18: 504.99 | J18: 386.79 | K18: 333.81 | L18: 414.3 | M18: 445.64 | N18: 143.72 | O18: 110.69 | P18: 200.67 | Q18: 114.62 | R18: 51.03 | S18: 46.3 | T18: 244.23 | U18: 316.25 | V18: 370.82 | W18: 213.45 | X18: 111.68 | Y18: 133.35 | Z18: 233.35 | AA18: 550.99 | AB18: 495.52 | AC18: 680.05 | AD18: 412.85 | AE18: 203.75 | AF18: 303.7 | AG18: 857.74 | AH18: 154.82 | AI18: 217.73 | AJ18: 187.37 | AK18: 80.66 | AL18: 277.57 | AM18: 255.36 | AN18: 169.537 | AO18: 76.629 | AP18: 22.172 | AQ18: 326.394 | AR18: 187.396 | AS18: 80.586 | AT18: 74.532 | AU18: 22.447 | AV18: 15.088 | AW18: 5.186
B19: 0 | C19: 0 | D19: 5.5 | E19: 0 | F19: 0 | G19: 0 | H19: 0.04 | I19: 2.27 | J19: 51.29 | K19: 370.29 | L19: 339.8 | M19: 438.12 | N19: 733.2 | O19: 894.3 | P19: 1059.93 | Q19: 799.32 | R19: 837.5 | S19: 863.42 | T19: 863.22 | U19: 875.82 | V19: 872.06 | W19: 543.66 | X19: 37.93 | Y19: 0 | Z19: 0 | AA19: 0 | AB19: 0 | AC19: 0 | AD19: 0 | AE19: 0.01 | AF19: 2.32 | AG19: 20.09 | AH19: 76.26 | AI19: 158.2 | AJ19: 295.44 | AK19: 243.58 | AL19: 362.63 | AM19: 438.8306 | AN19: 406.9864 | AO19: 371.9176 | AP19: 239.593 | AQ19: 60.89131 | AR19: 39.91786 | AS19: 41.177 | AT19: 63.652 | AU19: 86.717 | AV19: 53.671 | AW19: 50
B20: #Fcatonerr
B21: 0.05 | C21: 0.05 | D21: 0.05 | E21: 0.05 | F21: 0.05 | G21: 0.05 | H21: 0.05 | I21: 0.05 | J21: 0.05 | K21: 0.05 | L21: 0.05 | M21: 0.05 | N21: 0.05 | O21: 0.05 | P21: 0.05 | Q21: 0.05 | R21: 0.05 | S21: 0.05 | T21: 0.05 | U21: 0.05 | V21: 0.05 | W21: 0.05 | X21: 0.05 | Y21: 0.05 | Z21: 0.05 | AA21: 0.05 | AB21: 0.05 | AC21: 0.05 | AD21: 0.05 | AE21: 0.05 | AF21: 0.05 | AG21: 0.05 | AH21: 0.05 | AI21: 0.05 | AJ21: 0.05 | AK21: 0.05 | AL21: 0.05 | AM21: 0.05 | AN21: 0.05 | AO21: 0.05 | AP21: 0.05 | AQ21: 0.05 | AR21: 0.05 | AS21: 0.05 | AT21: 0.05 | AU21: 0.05 | AV21: 0.05 | AW21: 0.05
B22: 0.05 | C22: 0.05 | D22: 0.05 | E22: 0.05 | F22: 0.05 | G22: 0.05 | H22: 0.05 | I22: 0.05 | J22: 0.05 | K22: 0.05 | L22: 0.05 | M22: 0.05 | N22: 0.05 | O22: 0.05 | P22: 0.05 | Q22: 0.05 | R22: 0.05 | S22: 0.05 | T22: 0.05 | U22: 0.05 | V22: 0.05 | W22: 0.05 | X22: 0.05 | Y22: 0.05 | Z22: 0.05 | AA22: 0.05 | AB22: 0.05 | AC22: 0.05 | AD22: 0.05 | AE22: 0.05 | AF22: 0.05 | AG22: 0.05 | AH22: 0.05 | AI22: 0.05 | AJ22: 0.05 | AK22: 0.05 | AL22: 0.05 | AM22: 0.05 | AN22: 0.05 | AO22: 0.05 | AP22: 0.05 | AQ22: 0.05 | AR22: 0.05 | AS22: 0.05 | AT22: 0.05 | AU22: 0.05 | AV22: 0.05 | AW22: 0.05
B23: 0.05 | C23: 0.05 | D23: 0.05 | E23: 0.05 | F23: 0.05 | G23: 0.05 | H23: 0.05 | I23: 0.05 | J23: 0.05 | K23: 0.05 | L23: 0.05 | M23: 0.05 | N23: 0.05 | O23: 0.05 | P23: 0.05 | Q23: 0.05 | R23: 0.05 | S23: 0.05 | T23: 0.05 | U23: 0.05 | V23: 0.05 | W23: 0.05 | X23: 0.05 | Y23: 0.05 | Z23: 0.05 | AA23: 0.05 | AB23: 0.05 | AC23: 0.05 | AD23: 0.05 | AE23: 0.05 | AF23: 0.05 | AG23: 0.05 | AH23: 0.05 | AI23: 0.05 | AJ23: 0.05 | AK23: 0.05 | AL23: 0.05 | AM23: 0.05 | AN23: 0.05 | AO23: 0.05 | AP23: 0.05 | AQ23: 0.05 | AR23: 0.05 | AS23: 0.05 | AT23: 0.05 | AU23: 0.05 | AV23: 0.05 | AW23: 0.05
B24: 0.05 | C24: 0.05 | D24: 0.05 | E24: 0.05 | F24: 0.05 | G24: 0.05 | H24: 0.05 | I24: 0.05 | J24: 0.05 | K24: 0.05 | L24: 0.05 | M24: 0.05 | N24: 0.05 | O24: 0.05 | P24: 0.05 | Q24: 0.05 | R24: 0.05 | S24: 0.05 | T24: 0.05 | U24: 0.05 | V24: 0.05 | W24: 0.05 | X24: 0.05 | Y24: 0.05 | Z24: 0.05 | AA24: 0.05 | AB24: 0.05 | AC24: 0.05 | AD24: 0.05 | AE24: 0.05 | AF24: 0.05 | AG24: 0.05 | AH24: 0.05 | AI24: 0.05 | AJ24: 0.05 | AK24: 0.05 | AL24: 0.05 | AM24: 0.05 | AN24: 0.05 | AO24: 0.05 | AP24: 0.05 | AQ24: 0.05 | AR24: 0.05 | AS24: 0.05 | AT24: 0.05 | AU24: 0.05 | AV24: 0.05 | AW24: 0.05
B25: #FnumyearsA
B26: 42 # 43
B27: 43
B28: 0
B29: 28 # 29
B30: #FnumyearsL
B31: 0
B32: 0
B33: 37
B34: 0
B35: #Fageyears
B36: 1975 | C36: 1976 | D36: 1977 | E36: 1978 | F36: 1979 | G36: 1980 | H36: 1981 | I36: 1982 | J36: 1983 | K36: 1984 | L36: 1985 | M36: 1986 | N36: 1987 | O36: 1988 | P36: 1989 | Q36: 1990 | R36: 1991 | S36: 1992 | T36: 1993 | U36: 1994 | V36: 1995 | W36: 1996 | X36: 1997 | Y36: 1998 | Z36: 1999 | AA36: 2000 | AB36: 2001 | AC36: 2002 | AD36: 2003 | AE36: 2004 | AF36: 2005 | AG36: 2006 | AH36: 2007 | AI36: 2008 | AJ36: 2009 | AK36: 2010 | AL36: 2011 | AM36: 2012 | AN36: 2013 | AO36: 2014 | AP36: 2015 | AQ36: 2016 | AR36: # 2017
B37: 1975 | C37: 1976 | D37: 1977 | E37: 1978 | F37: 1979 | G37: 1980 | H37: 1981 | I37: 1982 | J37: 1983 | K37: 1984 | L37: 1985 | M37: 1986 | N37: 1987 | O37: 1988 | P37: 1989 | Q37: 1990 | R37: 1991 | S37: 1992 | T37: 1993 | U37: 1994 | V37: 1995 | W37: 1996 | X37: 1997 | Y37: 1998 | Z37: 1999 | AA37: 2000 | AB37: 2001 | AC37: 2002 | AD37: 2003 | AE37: 2004 | AF37: 2005 | AG37: 2006 | AH37: 2007 | AI37: 2008 | AJ37: 2009 | AK37: 2010 | AL37: 2011 | AM37: 2012 | AN37: 2013 | AO37: 2014 | AP37: 2015 | AQ37: 2016 | AR37: 2017
B38: 1979 | C38: 1980 | D38: 1981 | E38: 1982 | F38: 1983 | G38: 1984 | H38: 1985 | I38: 1986 | J38: 1987 | K38: 1988 | L38: 1989 | M38: 1990 | N38: 1991 | O38: 2000 | P38: 2001 | Q38: 2002 | R38: 2003 | S38: 2006 | T38: 2007 | U38: 2008 | V38: 2009 | W38: 2010 | X38: 2011 | Y38: 2012 | Z38: 2013 | AA38: 2014 | AB38: 2015 | AC38: 2016 | AD38: # 2017
B39: #Flengthyears
B40: 1980 | C40: 1981 | D40: 1982 | E40: 1983 | F40: 1984 | G40: 1985 | H40: 1986 | I40: 1987 | J40: 1988 | K40: 1989 | L40: 1990 | M40: 1991 | N40: 1992 | O40: 1993 | P40: 1994 | Q40: 1995 | R40: 1996 | S40: 1997 | T40: 1998 | U40: 1999 | V40: 2000 | W40: 2001 | X40: 2002 | Y40: 2003 | Z40: 2004 | AA40: 2005 | AB40: 2006 | AC40: 2007 | AD40: 2008 | AE40: 2009 | AF40: 2010 | AG40: 2011 | AH40: 2012 | AI40: 2013 | AJ40: 2014 | AK40: 2015 | AL40: 2016
...

Sheet Mod1.12.dat
B1: #years Data file as 1.5 but constant average somatic weights by gear
B2: 1970
B3: 2017
B4: #ages
B5: 1
B6: 12
B7: #nbins
B8: 41
B9: #lengthbin
B10: 10 | C10: 11 | D10: 12 | E10: 13 | F10: 14 | G10: 15 | H10: 16 | I10: 17 | J10: 18 | K10: 19 | L10: 20 | M10: 21 | N10: 22 | O10: 23 | P10: 24 | Q10: 25 | R10: 26 | S10: 27 | T10: 28 | U10: 29 | V10: 30 | W10: 31 | X10: 32 | Y10: 33 | Z10: 34 | AA10: 35 | AB10: 36 | AC10: 37 | AD10: 38 | AE10: 39 | AF10: 40 | AG10: 41 | AH10: 42 | AI10: 43 | AJ10: 44 | AK10: 45 | AL10: 46 | AM10: 47 | AN10: 48 | AO10: 49 | AP10: 50
B11: #Fnum
B12: 4
B13: #Fnames
B14: N_Chile%SC_Chile_PS%FarNorth%Offshore_Trawl
B15: #Fcaton
B16: 101.69 | C16: 143.45 | D16: 64.46 | E16: 83.2 | F16: 164.76 | G16: 207.33 | H16: 257.7 | I16: 226.23 | J16: 398.41 | K16: 344.05 | L16: 288.81 | M16: 474.82 | N16: 789.91 | O16: 301.93 | P16: 727 | Q16: 511.15 | R16: 55.21 | S16: 313.31 | T16: 325.46 | U16: 338.6 | V16: 323.09 | W16: 346.25 | X16: 304.24 | Y16: 379.47 | Z16: 222.25 | AA16: 230.18 | AB16: 278.44 | AC16: 104.2 | AD16: 30.27 | AE16: 55.65 | AF16: 118.73 | AG16: 248.1 | AH16: 108.73 | AI16: 143.28 | AJ16: 158.66 | AK16: 165.63 | AL16: 155.26 | AM16: 172.701 | AN16: 167.258 | AO16: 134.022 | AP16: 169.012 | AQ16: 30.825 | AR16: 13.256 | AS16: 16.361 | AT16: 18.219 | AU16: 34.886 | AV16: 24.657 | AW16: 35.002
B17: 10.31 | C17: 14.99 | D17: 22.55 | E17: 38.39 | F17: 28.75 | G17: 53.88 | H17: 84.57 | I17: 114.57 | J17: 188.27 | K17: 253.46 | L17: 273.45 | M17: 586.09 | N17: 704.77 | O17: 563.34 | P17: 699.3 | Q17: 945.84 | R17: 1129.11 | S17: 1456.73 | T17: 1812.79 | U17: 2051.52 | V17: 2148.79 | W17: 2674.27 | X17: 2907.82 | Y17: 2856.78 | Z17: 3819.19 | AA17: 4174.02 | AB17: 3604.89 | AC17: 2812.87 | AD17: 1582.64 | AE17: 1164.04 | AF17: 1115.57 | AG17: 1401.84 | AH17: 1410.27 | AI17: 1278.02 | AJ17: 1292.94 | AK17: 1264.81 | AL17: 1224.69 | AM17: 1130.083 | AN17: 728.85 | AO17: 700.905 | AP17: 295.796 | AQ17: 216.47 | AR17: 214.204 | AS17: 214.999 | AT17: 254.295 | AU17: 250.327 | AV17: 295.16 | AW17: 311.863
B18: 4.71 | C18: 9.19 | D18: 18.78 | E18: 42.78 | F18: 129.21 | G18: 37.9 | H18: 54.15 | I18: 504.99 | J18: 386.79 | K18: 333.81 | L18: 414.3 | M18: 445.64 | N18: 143.72 | O18: 110.69 | P18: 200.67 | Q18: 114.62 | R18: 51.03 | S18: 46.3 | T18: 244.23 | U18: 316.25 | V18: 370.82 | W18: 213.45 | X18: 111.68 | Y18: 133.35 | Z18: 233.35 | AA18: 550.99 | AB18: 495.52 | AC18: 680.05 | AD18: 412.85 | AE18: 203.75 | AF18: 303.7 | AG18: 857.74 | AH18: 154.82 | AI18: 217.73 | AJ18: 187.37 | AK18: 80.66 | AL18: 277.57 | AM18: 255.36 | AN18: 169.537 | AO18: 76.629 | AP18: 22.172 | AQ18: 326.394 | AR18: 187.396 | AS18: 80.586 | AT18: 74.532 | AU18: 22.447 | AV18: 15.088 | AW18: 5.186
B19: 0 | C19: 0 | D19: 5.5 | E19: 0 | F19: 0 | G19: 0 | H19: 0.04 | I19: 2.27 | J19: 51.29 | K19: 370.29 | L19: 339.8 | M19: 438.12 | N19: 733.2 | O19: 894.3 | P19: 1059.93 | Q19: 799.32 | R19: 837.5 | S19: 863.42 | T19: 863.22 | U19: 875.82 | V19: 872.06 | W19: 543.66 | X19: 37.93 | Y19: 0 | Z19: 0 | AA19: 0 | AB19: 0 | AC19: 0 | AD19: 0 | AE19: 0.01 | AF19: 2.32 | AG19: 20.09 | AH19: 76.26 | AI19: 158.2 | AJ19: 295.44 | AK19: 243.58 | AL19: 362.63 | AM19: 438.8306 | AN19: 406.9864 | AO19: 371.9176 | AP19: 239.593 | AQ19: 60.89131 | AR19: 39.91786 | AS19: 41.177 | AT19: 63.652 | AU19: 86.717 | AV19: 53.671 | AW19: 50
B20: #Fcatonerr
B21: 0.05 | C21: 0.05 | D21: 0.05 | E21: 0.05 | F21: 0.05 | G21: 0.05 | H21: 0.05 | I21: 0.05 | J21: 0.05 | K21: 0.05 | L21: 0.05 | M21: 0.05 | N21: 0.05 | O21: 0.05 | P21: 0.05 | Q21: 0.05 | R21: 0.05 | S21: 0.05 | T21: 0.05 | U21: 0.05 | V21: 0.05 | W21: 0.05 | X21: 0.05 | Y21: 0.05 | Z21: 0.05 | AA21: 0.05 | AB21: 0.05 | AC21: 0.05 | AD21: 0.05 | AE21: 0.05 | AF21: 0.05 | AG21: 0.05 | AH21: 0.05 | AI21: 0.05 | AJ21: 0.05 | AK21: 0.05 | AL21: 0.05 | AM21: 0.05 | AN21: 0.05 | AO21: 0.05 | AP21: 0.05 | AQ21: 0.05 | AR21: 0.05 | AS21: 0.05 | AT21: 0.05 | AU21: 0.05 | AV21: 0.05 | AW21: 0.05
B22: 0.05 | C22: 0.05 | D22: 0.05 | E22: 0.05 | F22: 0.05 | G22: 0.05 | H22: 0.05 | I22: 0.05 | J22: 0.05 | K22: 0.05 | L22: 0.05 | M22: 0.05 | N22: 0.05 | O22: 0.05 | P22: 0.05 | Q22: 0.05 | R22: 0.05 | S22: 0.05 | T22: 0.05 | U22: 0.05 | V22: 0.05 | W22: 0.05 | X22: 0.05 | Y22: 0.05 | Z22: 0.05 | AA22: 0.05 | AB22: 0.05 | AC22: 0.05 | AD22: 0.05 | AE22: 0.05 | AF22: 0.05 | AG22: 0.05 | AH22: 0.05 | AI22: 0.05 | AJ22: 0.05 | AK22: 0.05 | AL22: 0.05 | AM22: 0.05 | AN22: 0.05 | AO22: 0.05 | AP22: 0.05 | AQ22: 0.05 | AR22: 0.05 | AS22: 0.05 | AT22: 0.05 | AU22: 0.05 | AV22: 0.05 | AW22: 0.05
B23: 0.05 | C23: 0.05 | D23: 0.05 | E23: 0.05 | F23: 0.05 | G23: 0.05 | H23: 0.05 | I23: 0.05 | J23: 0.05 | K23: 0.05 | L23: 0.05 | M23: 0.05 | N23: 0.05 | O23: 0.05 | P23: 0.05 | Q23: 0.05 | R23: 0.05 | S23: 0.05 | T23: 0.05 | U23: 0.05 | V23: 0.05 | W23: 0.05 | X23: 0.05 | Y23: 0.05 | Z23: 0.05 | AA23: 0.05 | AB23: 0.05 | AC23: 0.05 | AD23: 0.05 | AE23: 0.05 | AF23: 0.05 | AG23: 0.05 | AH23: 0.05 | AI23: 0.05 | AJ23: 0.05 | AK23: 0.05 | AL23: 0.05 | AM23: 0.05 | AN23: 0.05 | AO23: 0.05 | AP23: 0.05 | AQ23: 0.05 | AR23: 0.05 | AS23: 0.05 | AT23: 0.05 | AU23: 0.05 | AV23: 0.05 | AW23: 0.05
B24: 0.05 | C24: 0.05 | D24: 0.05 | E24: 0.05 | F24: 0.05 | G24: 0.05 | H24: 0.05 | I24: 0.05 | J24: 0.05 | K24: 0.05 | L24: 0.05 | M24: 0.05 | N24: 0.05 | O24: 0.05 | P24: 0.05 | Q24: 0.05 | R24: 0.05 | S24: 0.05 | T24: 0.05 | U24: 0.05 | V24: 0.05 | W24: 0.05 | X24: 0.05 | Y24: 0.05 | Z24: 0.05 | AA24: 0.05 | AB24: 0.05 | AC24: 0.05 | AD24: 0.05 | AE24: 0.05 | AF24: 0.05 | AG24: 0.05 | AH24: 0.05 | AI24: 0.05 | AJ24: 0.05 | AK24: 0.05 | AL24: 0.05 | AM24: 0.05 | AN24: 0.05 | AO24: 0.05 | AP24: 0.05 | AQ24: 0.05 | AR24: 0.05 | AS24: 0.05 | AT24: 0.05 | AU24: 0.05 | AV24: 0.05 | AW24: 0.05
B25: #FnumyearsA
B26: 42 # 43
B27: 43
B28: 0
B29: 28 # 29
B30: #FnumyearsL
B31: 0
B32: 0
B33: 37
B34: 0
B35: #Fageyears
B36: 1975 | C36: 1976 | D36: 1977 | E36: 1978 | F36: 1979 | G36: 1980 | H36: 1981 | I36: 1982 | J36: 1983 | K36: 1984 | L36: 1985 | M36: 1986 | N36: 1987 | O36: 1988 | P36: 1989 | Q36: 1990 | R36: 1991 | S36: 1992 | T36: 1993 | U36: 1994 | V36: 1995 | W36: 1996 | X36: 1997 | Y36: 1998 | Z36: 1999 | AA36: 2000 | AB36: 2001 | AC36: 2002 | AD36: 2003 | AE36: 2004 | AF36: 2005 | AG36: 2006 | AH36: 2007 | AI36: 2008 | AJ36: 2009 | AK36: 2010 | AL36: 2011 | AM36: 2012 | AN36: 2013 | AO36: 2014 | AP36: 2015 | AQ36: 2016 | AR36: # 2017
B37: 1975 | C37: 1976 | D37: 1977 | E37: 1978 | F37: 1979 | G37: 1980 | H37: 1981 | I37: 1982 | J37: 1983 | K37: 1984 | L37: 1985 | M37: 1986 | N37: 1987 | O37: 1988 | P37: 1989 | Q37: 1990 | R37: 1991 | S37: 1992 | T37: 1993 | U37: 1994 | V37: 1995 | W37: 1996 | X37: 1997 | Y37: 1998 | Z37: 1999 | AA37: 2000 | AB37: 2001 | AC37: 2002 | AD37: 2003 | AE37: 2004 | AF37: 2005 | AG37: 2006 | AH37: 2007 | AI37: 2008 | AJ37: 2009 | AK37: 2010 | AL37: 2011 | AM37: 2012 | AN37: 2013 | AO37: 2014 | AP37: 2015 | AQ37: 2016 | AR37: 2017
B38: 1979 | C38: 1980 | D38: 1981 | E38: 1982 | F38: 1983 | G38: 1984 | H38: 1985 | I38: 1986 | J38: 1987 | K38: 1988 | L38: 1989 | M38: 1990 | N38: 1991 | O38: 2000 | P38: 2001 | Q38: 2002 | R38: 2003 | S38: 2006 | T38: 2007 | U38: 2008 | V38: 2009 | W38: 2010 | X38: 2011 | Y38: 2012 | Z38: 2013 | AA38: 2014 | AB38: 2015 | AC38: 2016 | AD38: # 2017
B39: #Flengthyears
B40: 1980 | C40: 1981 | D40: 1982 | E40: 1983 | F40: 1984 | G40: 1985 | H40: 1986 | I40: 1987 | J40: 1988 | K40: 1989 | L40: 1990 | M40: 1991 | N40: 1992 | O40: 1993 | P40: 1994 | Q40: 1995 | R40: 1996 | S40: 1997 | T40: 1998 | U40: 1999 | V40: 2000 | W40: 2001 | X40: 2002 | Y40: 2003 | Z40: 2004 | AA40: 2005 | AB40: 2006 | AC40: 2007 | AD40: 2008 | AE40: 2009 | AF40: 2010 | AG40: 2011 | AH40: 2012 | AI40: 2013 | AJ40: 2014 | AK40: 2015 | AL40: 2016
...

Sheet Sheet4
